Workbook

Sheet PowerHouse Data
B1: Date Equipments | C1: 46203 | D1: 46204 | E1: 46205 | F1: 46206 | G1: 46207 | H1: 46208 | I1: 46209 | J1: 46210 | K1: 46211 | L1: 46212 | M1: 46213 | N1: 46214 | O1: 46215 | P1: 46216 | Q1: 46217 | R1: 46218 | S1: 46219 | T1: 46220 | U1: 46221 | V1: 46222 | W1: 46223 | X1: 46224 | Y1: 46225 | Z1: 46226 | AA1: 46227 | AB1: 46228 | AC1: 46229 | AD1: 46230 | AE1: 46231 | AF1: 46232 | AG1: 46233 | AH1: 46234 | AI1: 46235
B2: Diesel Dip reading (mm) | C2: 1932 | D2: 1876 | E2: 1872 | F2: 1792 | G2: 1792 | H2: 1750 | I2: 1750 | J2: 1702 | K2: 1702 | L2: 1702 | M2: 1702 | N2: 2580 | O2: 2558 | P2: 2494 | Q2: 2494 | R2: 2426 | S2: 2426 | T2: 2338 | U2: 2296 | V2: 2296 | W2: 2296 | X2: 2284 | Y2: 2268 | Z2: 2224 | AA2: 2174 | AB2: 2174 | AC2: 2150 | AD2: 2150 | AE2: 2150 | AF2: 2150 | AG2: 2150 | AH2: 2150 | AI2: 2150
B3: Nepa meter reading (KWH) | C3: 24027090 | D3: 24035940 | E3: 24047800 | F3: 24056350 | G3: 24067960 | H3: 24073080 | I3: 24073990 | J3: 24082600 | K3: 24093790 | L3: 24103700 | M3: 24112250 | N3: 24117020 | O3: 24122000 | P3: 24125140 | Q3: 24135990 | R3: 24145790 | S3: 24157430 | T3: 24167190 | U3: 24176020 | V3: 24179710 | W3: 24180500 | X3: 24189710 | Y3: 24199100 | Z3: 24208190 | AA3: 24217830 | AB3: 24229690 | AC3: 24233680 | AD3: 24237140 | AE3: 24248800 | AF3: 24259810 | AG3: 24269940 | AH3: 24278570 | AI3: 24287130
B4: 1-Comp E75 reading (Hours) | C4: 3687 | D4: 3687 | E4: 3709 | F4: 3732 | G4: 3732 | H4: 3756 | I4: 3756 | J4: 3765 | K4: 3765 | L4: 3788 | M4: 3812 | N4: 3812 | O4: 3812 | P4: 3812 | Q4: 3833 | R4: 3833 | S4: 3857 | T4: 3880 | U4: 3880 | V4: 3882 | W4: 3882 | X4: 3904 | Y4: 3904 | Z4: 3927 | AA4: 3941 | AB4: 3941 | AC4: 3941 | AD4: 3941 | AE4: 3941 | AF4: 3964 | AG4: 3988 | AH4: 3988 | AI4: 4012
B5: 2-Comp E75 reading (Hours) | C5: 6405 | D5: 6428 | E5: 6428 | F5: 6451 | G5: 6475 | H5: 6475 | I5: 6475 | J5: 6497 | K5: 6521 | L5: 6521 | M5: 6545 | N5: 6545 | O5: 6559 | P5: 6559 | Q5: 6582 | R5: 6606 | S5: 6606 | T5: 6630 | U5: 6652 | V5: 6652 | W5: 6652 | X5: 6676 | Y5: 6700 | Z5: 6700 | AA5: 6723 | AB5: 6747 | AC5: 6749 | AD5: 6749 | AE5: 6773 | AF5: 6773 | AG5: 6797 | AH5: 6821 | AI5: 6821
B6: 3-Comp E75 reading (Hours) | C6: 558 | D6: 580 | E6: 604 | F6: 604 | G6: 628 | H6: 628 | I6: 628 | J6: 642 | K6: 665 | L6: 688 | M6: 688 | N6: 712 | O6: 712 | P6: 712 | Q6: 712 | R6: 734 | S6: 758 | T6: 758 | U6: 781 | V6: 805 | W6: 805 | X6: 805 | Y6: 828 | Z6: 852 | AA6: 857 | AB6: 881 | AC6: 881 | AD6: 881 | AE6: 904 | AF6: 926 | AG6: 926 | AH6: 948 | AI6: 972
B7: 4-Comp E55 reading (Hours) | C7: 25807 | D7: 25822 | E7: 25846 | F7: 25850 | G7: 25850 | H7: 25850 | I7: 25850 | J7: 25850 | K7: 25850 | L7: 25850 | M7: 25850 | N7: 25850 | O7: 25861 | P7: 25885 | Q7: 25885 | R7: 25885 | S7: 25885 | T7: 25886 | U7: 25886 | V7: 25886 | W7: 25886 | X7: 25886 | Y7: 25886 | Z7: 25886 | AA7: 25886 | AB7: 25886 | AC7: 25907 | AD7: 25931 | AE7: 25931 | AF7: 25931 | AG7: 25931 | AH7: 25931 | AI7: 25931
B8: Milling DG reading (Hours) | C8: 5631.3 | D8: 5636.3 | E8: 5636.3 | F8: 5642.3 | G8: 5642.3 | H8: 5642.3 | I8: 5642.3 | J8: 5645 | K8: 5645 | L8: 5645 | M8: 5645 | N8: 5646.2 | O8: 5646.2 | P8: 5646.2 | Q8: 5646.2 | R8: 5649.7 | S8: 5649.7 | T8: 5651.8 | U8: 5654.6 | V8: 5654.6 | W8: 5654.6 | X8: 5655.5 | Y8: 5656.6 | Z8: 5659.7 | AA8: 5662.7 | AB8: 5662.7 | AC8: 5664.3 | AD8: 5664.3 | AE8: 5664.3 | AF8: 5664.3 | AG8: 5664.3 | AH8: 5664.3 | AI8: 5664.3
B9: Parboiling DG reading (Hours) | C9: 12488.3 | D9: 12493.3 | E9: 12494.5 | F9: 12501.1 | G9: 12501.1 | H9: 12501.1 | I9: 12501.1 | J9: 12503.8 | K9: 12503.8 | L9: 12503.8 | M9: 12503.8 | N9: 12504.9 | O9: 12507 | P9: 12512.9 | Q9: 12512.9 | R9: 12516.4 | S9: 12516.4 | T9: 12518.5 | U9: 12521.3 | V9: 12521.3 | W9: 12521.3 | X9: 12522.2 | Y9: 12523.3 | Z9: 12526.4 | AA9: 12529.4 | AB9: 12529.4 | AC9: 12532.3 | AD9: 12532.3 | AE9: 12532.3 | AF9: 12532.3 | AG9: 12532.3 | AH9: 12532.3 | AI9: 12532.3
B10: MILLING (KWH) | C10: 3203489 | D10: 3212587 | E10: 3224858 | F10: 3234941 | G10: 3247093 | H10: 3251491 | I10: 3252272 | J10: 3263073 | K10: 3275477 | L10: 3287205 | M10: 3299866 | N10: 3301119 | O10: 3303032 | P10: 3303035 | Q10: 3316063 | R10: 3326476 | S10: 3339130 | T10: 3351197 | U10: 3361064 | V10: 3362285 | W10: 3362290 | X10: 3375728 | Y10: 3386313 | Z10: 3396838 | AA10: 3407745 | AB10: 3419791 | AC10: 3420458 | AD10: 3420543 | AE10: 3432496 | AF10: 3444122 | AG10: 3458327 | AH10: 3470399 | AI10: 3482505
B11: UTILITY / PARBOILING (KWH) | C11: 300343 | D11: 305571 | E11: 312490 | F11: 316687 | G11: 323465 | H11: 326826 | I11: 327528 | J11: 331320 | K11: 337265 | L11: 342023 | M11: 344378 | N11: 349494 | O11: 354577 | P11: 358599 | Q11: 363850 | R11: 369451 | S11: 375971 | T11: 380422 | U11: 385108 | V11: 388899 | W11: 389791 | X11: 392636 | Y11: 397542 | Z11: 402146 | AA11: 407190 | AB11: 414301 | AC11: 418895 | AD11: 423191 | AE11: 430133 | AF11: 436428 | AG11: 439897 | AH11: 442882 | AI11: 445792
B12: Diesel RECEIVED | C12: 0 | D12: 0 | E12: 0 | F12: 0 | G12: 0 | H12: 0 | I12: 0 | J12: 0 | K12: 0 | L12: 0 | M12: 0 | N12: 15198 | O12: 0 | P12: 0 | Q12: 0 | R12: 0 | S12: 0 | T12: 0 | U12: 0 | V12: 0 | W12: 0 | X12: 0 | Y12: 0 | Z12: 0 | AA12: 0 | AB12: 0 | AC12: 0 | AD12: 0 | AE12: 0 | AF12: 0 | AG12: 0 | AH12: 0 | AI12: 0
B13: Diesel ISSUED | C13: 85 | D13: 0 | E13: 0 | F13: 75 | G13: 0 | H13: =150+25+687 -> 862 | I13: 10 | J13: 200 | K13: 0 | L13: 0 | M13: 10 | N13: 10 | O13: 0 | P13: 0 | Q13: 100 | R13: 0 | S13: 175 | T13: 75 | U13: 0 | V13: 0 | W13: 0 | X13: 85 | Y13: 0 | Z13: 0 | AA13: 75 | AB13: 0 | AC13: 0 | AD13: 0 | AE13: 25 | AF13: 0 | AG13: 0 | AH13: 75 | AI13: 0
B14: Service Tanks | C14: 5184 | D14: 5184 | E14: 5184 | F14: 5184 | G14: 5184 | H14: 5184 | I14: =H14-I13 -> 5174 | J14: 5184 | K14: 5184 | L14: =K14 -> 5184 | M14: =L14-M13 -> 5174 | N14: 5184 | O14: 5184 | P14: 5184 | Q14: =P14-Q13 -> 5084 | R14: 5184 | S14: =R14-S13 -> 5009 | T14: 5184 | U14: 5184 | V14: 5184 | W14: 5184 | X14: 5184 | Y14: 5184 | Z14: 5184 | AA14: 5184 | AB14: 5184 | AC14: 5184 | AD14: 5184 | AE14: =AD14-AE13 -> 5159 | AF14: 5159 | AG14: 5159 | AH14: =AG14-AH13 -> 5084 | AI14: 5084

Sheet Summary
A1: Date | B1: Diesel Consumption (LTRS) | C1: Nepa Consumption (K.W.H) | D1: Comp E75 -1 Run Hours | E1: Comp E75 -2 Run Hours | F1: Comp E75 -3 Run Hours | G1: Comp E55 Run Hours | H1: Milling DG Run Hours | I1: Parboiling DG Run Hours | J1: Admin DG Run Hours | K1: Comp E75 -1 Rem Hours To Service | L1: Comp E75 -2 Rem Hours To Service | M1: Comp E75 -3 Rem Hours To Service | N1: Comp E55 Rem Hours To Service | O1: Milling DG Rem Hours To Service | P1: Parboiling DG Rem Hours To Service | Q1: Comp E75 -1 Next Ser Hours | R1: Comp E75 -2 Next Ser Hours | S1: Comp E75 -3 Next Ser Hours | T1: Comp E55 Next Ser Hours | U1: Milling DG Next Ser Hours | V1: Parboiling DG Next Ser Hours | W1: Service tank (Liters) | X1: Current Total stock (Liters)
A2: 46202 | B2: =[1]!Table113456[[#This Row],[Consumption (Liters)]] -> #REF! | C2: =[1]!Table1135[[#This Row],[NEPA Consumption (KWH)]] -> #REF! | D2: =[1]!Table113[[#This Row],[Comp E75 -1 Run Hours]] -> #REF! | E2: =[1]!Table113[[#This Row],[Comp E75 -2 Run Hours]] -> #REF! | F2: =[1]!Table113[[#This Row],[Comp E75 -3 Run Hours]] -> #REF! | G2: =[1]!Table113[[#This Row],[Comp E55 Run Hours]] -> #REF! | H2: =[1]!Table113456[[#This Row],[DG Milling Run Hours]] -> #REF! | I2: =[1]!Table113456[[#This Row],[DG Parboiling Run Hours]] -> #REF! | K2: =[1]!Table113[[#This Row],[Comp E75 -1 Rem Hours To Service]] -> #REF! | L2: =[1]!Table113[[#This Row],[Comp E75 -2 Rem Hours To Service]] -> #REF! | M2: =[1]!Table113[[#This Row],[Comp E75 -3 Rem Hours To Service]] -> #REF! | N2: =[1]!Table113[[#This Row],[Comp E55 Rem Hours To Service]] -> #REF! | O2: =[1]!Table113456[[#This Row],[Milling DG Rem Hours To Service]] -> #REF! | P2: =[1]!Table113456[[#This Row],[Parboiling DG Rem Hours To Service]] -> #REF!
A3: 46203 | B3: =Table113456[[#This Row],[Main Tank Consumption (Liters)]] -> 1105 | C3: =Table1135[[#This Row],[NEPA Consumption (KWH)]] -> 8850 | D3: =Table113[[#This Row],[Comp E75 -1 Run Hours]] -> 0 | E3: =Table113[[#This Row],[Comp E75 -2 Run Hours]] -> 23 | F3: =Table113[[#This Row],[Comp E75 -3 Run Hours]] -> 22 | G3: =Table113[[#This Row],[Comp E55 Run Hours]] -> 15 | H3: =Table113456[[#This Row],[DG Milling Run Hours]] -> 5 | I3: =Table113456[[#This Row],[DG Parboiling Run Hours]] -> 5 | K3: =Table113[[#This Row],[Comp E75 -1 Rem Hours To Service]] -> 1753 | L3: =Table113[[#This Row],[Comp E75 -2 Rem Hours To Service]] -> 1638 | M3: =Table113[[#This Row],[Comp E75 -3 Rem Hours To Service]] -> 3420 | N3: =Table113[[#This Row],[Comp E55 Rem Hours To Service]] -> 1108 | O3: =Table113456[[#This Row],[DG Parboiling Run Hr Meter3]] -> 187.7 | P3: =Table113456[[#This Row],[DG Parboiling Run Hr Meter5]] -> 150.2 | Q3: 5440 | R3: 8066 | S3: 4000 | T3: 26930 | U3: 5824 | V3: 12643 | W3: 5184 | X3: =Diesel!I3 -> 38923
A4: 46204 | B4: =Table113456[[#This Row],[Main Tank Consumption (Liters)]] -> 79 | C4: =Table1135[[#This Row],[NEPA Consumption (KWH)]] -> 11860 | D4: =Table113[[#This Row],[Comp E75 -1 Run Hours]] -> 22 | E4: =Table113[[#This Row],[Comp E75 -2 Run Hours]] -> 0 | F4: =Table113[[#This Row],[Comp E75 -3 Run Hours]] -> 24 | G4: =Table113[[#This Row],[Comp E55 Run Hours]] -> 24 | H4: =Table113456[[#This Row],[DG Milling Run Hours]] -> 0 | I4: =Table113456[[#This Row],[DG Parboiling Run Hours]] -> 1.2 | K4: =Table113[[#This Row],[Comp E75 -1 Rem Hours To Service]] -> 1731 | L4: =Table113[[#This Row],[Comp E75 -2 Rem Hours To Service]] -> 1638 | M4: =Table113[[#This Row],[Comp E75 -3 Rem Hours To Service]] -> 3396 | N4: =Table113[[#This Row],[Comp E55 Rem Hours To Service]] -> 1084 | O4: =Table113456[[#This Row],[DG Parboiling Run Hr Meter3]] -> 187.7 | P4: =Table113456[[#This Row],[DG Parboiling Run Hr Meter5]] -> 149 | W4: 5184 | X4: =Diesel!I4 -> 38844
A5: 46205 | B5: =Table113456[[#This Row],[Main Tank Consumption (Liters)]] -> 1615 | C5: =Table1135[[#This Row],[NEPA Consumption (KWH)]] -> 8550 | D5: =Table113[[#This Row],[Comp E75 -1 Run Hours]] -> 23 | E5: =Table113[[#This Row],[Comp E75 -2 Run Hours]] -> 23 | F5: =Table113[[#This Row],[Comp E75 -3 Run Hours]] -> 0 | G5: =Table113[[#This Row],[Comp E55 Run Hours]] -> 4 | H5: =Table113456[[#This Row],[DG Milling Run Hours]] -> 6 | I5: =Table113456[[#This Row],[DG Parboiling Run Hours]] -> 6.6 | K5: =Table113[[#This Row],[Comp E75 -1 Rem Hours To Service]] -> 1708 | L5: =Table113[[#This Row],[Comp E75 -2 Rem Hours To Service]] -> 1615 | M5: =Table113[[#This Row],[Comp E75 -3 Rem Hours To Service]] -> 3396 | N5: =Table113[[#This Row],[Comp E55 Rem Hours To Service]] -> 1080 | O5: =Table113456[[#This Row],[DG Parboiling Run Hr Meter3]] -> 181.7 | P5: =Table113456[[#This Row],[DG Parboiling Run Hr Meter5]] -> 142.4 | X5: =Diesel!I5 -> 37229
A6: 46206 | B6: =Table113456[[#This Row],[Main Tank Consumption (Liters)]] -> 0 | C6: =Table1135[[#This Row],[NEPA Consumption (KWH)]] -> 11610 | D6: =Table113[[#This Row],[Comp E75 -1 Run Hours]] -> 0 | E6: =Table113[[#This Row],[Comp E75 -2 Run Hours]] -> 24 | F6: =Table113[[#This Row],[Comp E75 -3 Run Hours]] -> 24 | G6: =Table113[[#This Row],[Comp E55 Run Hours]] -> 0 | H6: =Table113456[[#This Row],[DG Milling Run Hours]] -> 0 | I6: =Table113456[[#This Row],[DG Parboiling Run Hours]] -> 0 | K6: =Table113[[#This Row],[Comp E75 -1 Rem Hours To Service]] -> 1708 | L6: =Table113[[#This Row],[Comp E75 -2 Rem Hours To Service]] -> 1591 | M6: =Table113[[#This Row],[Comp E75 -3 Rem Hours To Service]] -> 3372 | N6: =Table113[[#This Row],[Comp E55 Rem Hours To Service]] -> 1080 | O6: =Table113456[[#This Row],[DG Parboiling Run Hr Meter3]] -> 181.7 | P6: =Table113456[[#This Row],[DG Parboiling Run Hr Meter5]] -> 142.4 | X6: =Diesel!I6 -> 37229
A7: 46207 | B7: =Table113456[[#This Row],[Main Tank Consumption (Liters)]] -> 861.5 | C7: =Table1135[[#This Row],[NEPA Consumption (KWH)]] -> 5120 | D7: =Table113[[#This Row],[Comp E75 -1 Run Hours]] -> 24 | E7: =Table113[[#This Row],[Comp E75 -2 Run Hours]] -> 0 | F7: =Table113[[#This Row],[Comp E75 -3 Run Hours]] -> 0 | G7: =Table113[[#This Row],[Comp E55 Run Hours]] -> 0 | H7: =Table113456[[#This Row],[DG Milling Run Hours]] -> 0 | I7: =Table113456[[#This Row],[DG Parboiling Run Hours]] -> 0 | K7: =Table113[[#This Row],[Comp E75 -1 Rem Hours To Service]] -> 1684 | L7: =Table113[[#This Row],[Comp E75 -2 Rem Hours To Service]] -> 1591 | M7: =Table113[[#This Row],[Comp E75 -3 Rem Hours To Service]] -> 3372 | N7: =Table113[[#This Row],[Comp E55 Rem Hours To Service]] -> 1080 | O7: =Table113456[[#This Row],[DG Parboiling Run Hr Meter3]] -> 181.7 | P7: =Table113456[[#This Row],[DG Parboiling Run Hr Meter5]] -> 142.4 | X7: =Diesel!I7 -> 36367.5
A8: 46208 | B8: =Table113456[[#This Row],[Main Tank Consumption (Liters)]] -> 0 | C8: =Table1135[[#This Row],[NEPA Consumption (KWH)]] -> 910 | D8: =Table113[[#This Row],[Comp E75 -1 Run Hours]] -> 0 | E8: =Table113[[#This Row],[Comp E75 -2 Run Hours]] -> 0 | F8: =Table113[[#This Row],[Comp E75 -3 Run Hours]] -> 0 | G8: =Table113[[#This Row],[Comp E55 Run Hours]] -> 0 | H8: =Table113456[[#This Row],[DG Milling Run Hours]] -> 0 | I8: =Table113456[[#This Row],[DG Parboiling Run Hours]] -> 0 | K8: =Table113[[#This Row],[Comp E75 -1 Rem Hours To Service]] -> 1684 | L8: =Table113[[#This Row],[Comp E75 -2 Rem Hours To Service]] -> 1591 | M8: =Table113[[#This Row],[Comp E75 -3 Rem Hours To Service]] -> 3372 | N8: =Table113[[#This Row],[Comp E55 Rem Hours To Service]] -> 1080 | O8: =Table113456[[#This Row],[DG Parboiling Run Hr Meter3]] -> 181.7 | P8: =Table113456[[#This Row],[DG Parboiling Run Hr Meter5]] -> 142.4 | X8: =Diesel!I8 -> 36357.5
A9: 46209 | B9: =Table113456[[#This Row],[Main Tank Consumption (Liters)]] -> 994.5 | C9: =Table1135[[#This Row],[NEPA Consumption (KWH)]] -> 8610 | D9: =Table113[[#This Row],[Comp E75 -1 Run Hours]] -> 9 | E9: =Table113[[#This Row],[Comp E75 -2 Run Hours]] -> 22 | F9: =Table113[[#This Row],[Comp E75 -3 Run Hours]] -> 14 | G9: =Table113[[#This Row],[Comp E55 Run Hours]] -> 0 | H9: =Table113456[[#This Row],[DG Milling Run Hours]] -> 2.7 | I9: =Table113456[[#This Row],[DG Parboiling Run Hours]] -> 2.7 | K9: =Table113[[#This Row],[Comp E75 -1 Rem Hours To Service]] -> 1675 | L9: =Table113[[#This Row],[Comp E75 -2 Rem Hours To Service]] -> 1569 | M9: =Table113[[#This Row],[Comp E75 -3 Rem Hours To Service]] -> 3358 | N9: =Table113[[#This Row],[Comp E55 Rem Hours To Service]] -> 1080 | O9: =Table113456[[#This Row],[DG Parboiling Run Hr Meter3]] -> 179 | P9: =Table113456[[#This Row],[DG Parboiling Run Hr Meter5]] -> 139.7 | X9: =Diesel!I9 -> 35373
A10: 46210 | B10: =Table113456[[#This Row],[Main Tank Consumption (Liters)]] -> 0 | C10: =Table1135[[#This Row],[NEPA Consumption (KWH)]] -> 11190 | D10: =Table113[[#This Row],[Comp E75 -1 Run Hours]] -> 0 | E10: =Table113[[#This Row],[Comp E75 -2 Run Hours]] -> 24 | F10: =Table113[[#This Row],[Comp E75 -3 Run Hours]] -> 23 | G10: =Table113[[#This Row],[Comp E55 Run Hours]] -> 0 | H10: =Table113456[[#This Row],[DG Milling Run Hours]] -> 0 | I10: =Table113456[[#This Row],[DG Parboiling Run Hours]] -> 0 | K10: =Table113[[#This Row],[Comp E75 -1 Rem Hours To Service]] -> 1675 | L10: =Table113[[#This Row],[Comp E75 -2 Rem Hours To Service]] -> 1545 | M10: =Table113[[#This Row],[Comp E75 -3 Rem Hours To Service]] -> 3335 | N10: =Table113[[#This Row],[Comp E55 Rem Hours To Service]] -> 1080 | O10: =Table113456[[#This Row],[DG Parboiling Run Hr Meter3]] -> 179 | P10: =Table113456[[#This Row],[DG Parboiling Run Hr Meter5]] -> 139.7 | X10: =Diesel!I10 -> 35373
A11: 46211 | B11: =Table113456[[#This Row],[Main Tank Consumption (Liters)]] -> 0 | C11: =Table1135[[#This Row],[NEPA Consumption (KWH)]] -> 9910 | D11: =Table113[[#This Row],[Comp E75 -1 Run Hours]] -> 23 | E11: =Table113[[#This Row],[Comp E75 -2 Run Hours]] -> 0 | F11: =Table113[[#This Row],[Comp E75 -3 Run Hours]] -> 23 | G11: =Table113[[#This Row],[Comp E55 Run Hours]] -> 0 | H11: =Table113456[[#This Row],[DG Milling Run Hours]] -> 0 | I11: =Table113456[[#This Row],[DG Parboiling Run Hours]] -> 0 | K11: =Table113[[#This Row],[Comp E75 -1 Rem Hours To Service]] -> 1652 | L11: =Table113[[#This Row],[Comp E75 -2 Rem Hours To Service]] -> 1545 | M11: =Table113[[#This Row],[Comp E75 -3 Rem Hours To Service]] -> 3312 | N11: =Table113[[#This Row],[Comp E55 Rem Hours To Service]] -> 1080 | O11: =Table113456[[#This Row],[DG Parboiling Run Hr Meter3]] -> 179 | P11: =Table113456[[#This Row],[DG Parboiling Run Hr Meter5]] -> 139.7 | X11: =Diesel!I11 -> 35373
A12: 46212 | B12: =Table113456[[#This Row],[Main Tank Consumption (Liters)]] -> 0 | C12: =Table1135[[#This Row],[NEPA Consumption (KWH)]] -> 8550 | D12: =Table113[[#This Row],[Comp E75 -1 Run Hours]] -> 24 | E12: =Table113[[#This Row],[Comp E75 -2 Run Hours]] -> 24 | F12: =Table113[[#This Row],[Comp E75 -3 Run Hours]] -> 0 | G12: =Table113[[#This Row],[Comp E55 Run Hours]] -> 0 | H12: =Table113456[[#This Row],[DG Milling Run Hours]] -> 0 | I12: =Table113456[[#This Row],[DG Parboiling Run Hours]] -> 0 | K12: =Table113[[#This Row],[Comp E75 -1 Rem Hours To Service]] -> 1628 | L12: =Table113[[#This Row],[Comp E75 -2 Rem Hours To Service]] -> 1521 | M12: =Table113[[#This Row],[Comp E75 -3 Rem Hours To Service]] -> 3312 | N12: =Table113[[#This Row],[Comp E55 Rem Hours To Service]] -> 1080 | O12: =Table113456[[#This Row],[DG Parboiling Run Hr Meter3]] -> 179 | P12: =Table113456[[#This Row],[DG Parboiling Run Hr Meter5]] -> 139.7 | X12: =Diesel!I12 -> 35363
A13: 46213 | B13: =Table113456[[#This Row],[Main Tank Consumption (Liters)]] -> 361 | C13: =Table1135[[#This Row],[NEPA Consumption (KWH)]] -> 4770 | D13: =Table113[[#This Row],[Comp E75 -1 Run Hours]] -> 0 | E13: =Table113[[#This Row],[Comp E75 -2 Run Hours]] -> 0 | F13: =Table113[[#This Row],[Comp E75 -3 Run Hours]] -> 24 | G13: =Table113[[#This Row],[Comp E55 Run Hours]] -> 0 | H13: =Table113456[[#This Row],[DG Milling Run Hours]] -> 1.2 | I13: =Table113456[[#This Row],[DG Parboiling Run Hours]] -> 1.1 | K13: =Table113[[#This Row],[Comp E75 -1 Rem Hours To Service]] -> 1628 | L13: =Table113[[#This Row],[Comp E75 -2 Rem Hours To Service]] -> 1521 | M13: =Table113[[#This Row],[Comp E75 -3 Rem Hours To Service]] -> 3288 | N13: =Table113[[#This Row],[Comp E55 Rem Hours To Service]] -> 1080 | O13: =Table113456[[#This Row],[DG Parboiling Run Hr Meter3]] -> 177.8 | P13: =Table113456[[#This Row],[DG Parboiling Run Hr Meter5]] -> 138.6 | X13: =Diesel!I13 -> 50210
A14: 46214 | B14: =Table113456[[#This Row],[Main Tank Consumption (Liters)]] -> 219.5 | C14: =Table1135[[#This Row],[NEPA Consumption (KWH)]] -> 4980 | D14: =Table113[[#This Row],[Comp E75 -1 Run Hours]] -> 0 | E14: =Table113[[#This Row],[Comp E75 -2 Run Hours]] -> 14 | F14: =Table113[[#This Row],[Comp E75 -3 Run Hours]] -> 0 | G14: =Table113[[#This Row],[Comp E55 Run Hours]] -> 11 | H14: =Table113456[[#This Row],[DG Milling Run Hours]] -> 0 | I14: =Table113456[[#This Row],[DG Parboiling Run Hours]] -> 2.1 | K14: =Table113[[#This Row],[Comp E75 -1 Rem Hours To Service]] -> 1628 | L14: =Table113[[#This Row],[Comp E75 -2 Rem Hours To Service]] -> 1507 | M14: =Table113[[#This Row],[Comp E75 -3 Rem Hours To Service]] -> 3288 | N14: =Table113[[#This Row],[Comp E55 Rem Hours To Service]] -> 1069 | O14: =Table113456[[#This Row],[DG Parboiling Run Hr Meter3]] -> 177.8 | P14: =Table113456[[#This Row],[DG Parboiling Run Hr Meter5]] -> 136.5 | X14: =Diesel!I14 -> 49990.5
A15: 46215 | B15: =Table113456[[#This Row],[Main Tank Consumption (Liters)]] -> 715.5 | C15: =Table1135[[#This Row],[NEPA Consumption (KWH)]] -> 3140 | D15: =Table113[[#This Row],[Comp E75 -1 Run Hours]] -> 0 | E15: =Table113[[#This Row],[Comp E75 -2 Run Hours]] -> 0 | F15: =Table113[[#This Row],[Comp E75 -3 Run Hours]] -> 0 | G15: =Table113[[#This Row],[Comp E55 Run Hours]] -> 24 | H15: =Table113456[[#This Row],[DG Milling Run Hours]] -> 0 | I15: =Table113456[[#This Row],[DG Parboiling Run Hours]] -> 5.9 | K15: =Table113[[#This Row],[Comp E75 -1 Rem Hours To Service]] -> 1628 | L15: =Table113[[#This Row],[Comp E75 -2 Rem Hours To Service]] -> 1507 | M15: =Table113[[#This Row],[Comp E75 -3 Rem Hours To Service]] -> 3288 | N15: =Table113[[#This Row],[Comp E55 Rem Hours To Service]] -> 1045 | O15: =Table113456[[#This Row],[DG Parboiling Run Hr Meter3]] -> 177.8 | P15: =Table113456[[#This Row],[DG Parboiling Run Hr Meter5]] -> 130.6 | X15: =Diesel!I15 -> 49275
A16: 46216 | B16: =Table113456[[#This Row],[Main Tank Consumption (Liters)]] -> 0 | C16: =Table1135[[#This Row],[NEPA Consumption (KWH)]] -> 10850 | D16: =Table113[[#This Row],[Comp E75 -1 Run Hours]] -> 21 | E16: =Table113[[#This Row],[Comp E75 -2 Run Hours]] -> 23 | F16: =Table113[[#This Row],[Comp E75 -3 Run Hours]] -> 0 | G16: =Table113[[#This Row],[Comp E55 Run Hours]] -> 0 | H16: =Table113456[[#This Row],[DG Milling Run Hours]] -> 0 | I16: =Table113456[[#This Row],[DG Parboiling Run Hours]] -> 0 | K16: =Table113[[#This Row],[Comp E75 -1 Rem Hours To Service]] -> 1607 | L16: =Table113[[#This Row],[Comp E75 -2 Rem Hours To Service]] -> 1484 | M16: =Table113[[#This Row],[Comp E75 -3 Rem Hours To Service]] -> 3288 | N16: =Table113[[#This Row],[Comp E55 Rem Hours To Service]] -> 1045 | O16: =Table113456[[#This Row],[DG Parboiling Run Hr Meter3]] -> 177.8 | P16: =Table113456[[#This Row],[DG Parboiling Run Hr Meter5]] -> 130.6 | X16: =Diesel!I16 -> 49175
... A33: 46233 | B33: =Table113456[[#This Row],[Main Tank Consumption (Liters)]] -> 0 | C33: =Table1135[[#This Row],[NEPA Consumption (KWH)]] -> 8630 | D33: =Table113[[#This Row],[Comp E75 -1 Run Hours]] -> 0 | E33: =Table113[[#This Row],[Comp E75 -2 Run Hours]] -> 24 | F33: =Table113[[#This Row],[Comp E75 -3 Run Hours]] -> 22 | G33: =Table113[[#This Row],[Comp E55 Run Hours]] -> 0 | H33: =Table113456[[#This Row],[DG Milling Run Hours]] -> 0 | I33: =Table113456[[#This Row],[DG Parboiling Run Hours]] -> 0 | K33: =Table113[[#This Row],[Comp E75 -1 Rem Hours To Service]] -> 1452 | L33: =Table113[[#This Row],[Comp E75 -2 Rem Hours To Service]] -> 1245 | M33: =Table113[[#This Row],[Comp E75 -3 Rem Hours To Service]] -> 3052 | N33: =Table113[[#This Row],[Comp E55 Rem Hours To Service]] -> 999 | O33: =Table113456[[#This Row],[DG Parboiling Run Hr Meter3]] -> 159.7 | P33: =Table113456[[#This Row],[DG Parboiling Run Hr Meter5]] -> 111.2 | X33: =Diesel!I33 -> 43983
A34: 46234 | B34: =Table113456[[#This Row],[Main Tank Consumption (Liters)]] -> 0 | C34: =Table1135[[#This Row],[NEPA Consumption (KWH)]] -> 8560 | D34: =Table113[[#This Row],[Comp E75 -1 Run Hours]] -> 24 | E34: =Table113[[#This Row],[Comp E75 -2 Run Hours]] -> 0 | F34: =Table113[[#This Row],[Comp E75 -3 Run Hours]] -> 24 | G34: =Table113[[#This Row],[Comp E55 Run Hours]] -> 0 | H34: =Table113456[[#This Row],[DG Milling Run Hours]] -> 0 | I34: =Table113456[[#This Row],[DG Parboiling Run Hours]] -> 0 | K34: =Table113[[#This Row],[Comp E75 -1 Rem Hours To Service]] -> 1428 | L34: =Table113[[#This Row],[Comp E75 -2 Rem Hours To Service]] -> 1245 | M34: =Table113[[#This Row],[Comp E75 -3 Rem Hours To Service]] -> 3028 | N34: =Table113[[#This Row],[Comp E55 Rem Hours To Service]] -> 999 | O34: 159.7 | P34: 111.2 | X34: =Diesel!I34 -> 43983
A35: 46235 | B35: =Table113456[[#This Row],[Main Tank Consumption (Liters)]] -> 38899 | C35: =Table1135[[#This Row],[NEPA Consumption (KWH)]] -> -24287130 | D35: =Table113[[#This Row],[Comp E75 -1 Run Hours]] -> -4012 | E35: =Table113[[#This Row],[Comp E75 -2 Run Hours]] -> -6821 | F35: =Table113[[#This Row],[Comp E75 -3 Run Hours]] -> -972 | G35: =Table113[[#This Row],[Comp E55 Run Hours]] -> -25931 | H35: =Table113456[[#This Row],[DG Milling Run Hours]] -> -5664.3 | I35: =Table113456[[#This Row],[DG Parboiling Run Hours]] -> -12532.3 | K35: =Table113[[#This Row],[Comp E75 -1 Rem Hours To Service]] -> 5440 | L35: =Table113[[#This Row],[Comp E75 -2 Rem Hours To Service]] -> 8066 | M35: =Table113[[#This Row],[Comp E75 -3 Rem Hours To Service]] -> 4000 | N35: =Table113[[#This Row],[Comp E55 Rem Hours To Service]] -> 26930 | O35: =Table113456[[#This Row],[DG Parboiling Run Hr Meter3]] -> 5824 | P35: =Table113456[[#This Row],[DG Parboiling Run Hr Meter5]] -> 12643.5 | X35: =Diesel!I35 -> 0
A36: Hours Rem
A37: Days Rem
B38: =SUM(B4:B30) -> 10038
B39: NOTE: 23.05.2026 Receive desiel 44 X 230 = 10120 ltrs Befor Receive dip Reading 1912 = 34452 ltrs Calculation wise = 44572 ltrs After Receive dip Reading 2592 = 45121 ltrs differance getting extra = 549 ltrs

Sheet Compressor
A1: Date | B1: Comp E75 -1 Run Hours | C1: Comp E75 -1 Run Hr | D1: Comp E75 -1 Rem Hours To Service | E1: Comp E75 -2 Run Hours | F1: Comp E75 -2 Run Hr | G1: Comp E75 -2 Rem Hours To Service | H1: Comp E75 -3 Run Hours | I1: Comp E75 -3 Run Hr | J1: Comp E75 -3 Rem Hours To Service | K1: Comp E55 Run Hours | L1: Comp E55 Run Hr | M1: Comp E55 Rem Hours To Service | N1: Comp E75 -1 Next Ser Hours | O1: Comp E75 -2 Next Ser Hours | P1: Comp E75 -3 Next Ser Hours | Q1: Comp E55 Next Ser Hours
A2: 46202 | B2: 21 | C2: 3686 | D2: 1754 | E2: 22 | F2: 6405 | G2: 1661 | H2: 0 | I2: 558 | J2: 3442 | K2: 0 | L2: 25807 | M2: 1123
A3: 46203 | B3: ='PowerHouse Data'!D4-'PowerHouse Data'!C4 -> 0 | C3: ='PowerHouse Data'!$D$4 -> 3687 | D3: =$N$3-Table113[[#This Row],[Comp E75 -1 Run Hr]] -> 1753 | E3: ='PowerHouse Data'!D5-'PowerHouse Data'!C5 -> 23 | F3: ='PowerHouse Data'!$D$5 -> 6428 | G3: =$O$3-Table113[[#This Row],[Comp E75 -2 Run Hr]] -> 1638 | H3: ='PowerHouse Data'!D6-'PowerHouse Data'!C6 -> 22 | I3: ='PowerHouse Data'!$D$6 -> 580 | J3: =$P$3-Table113[[#This Row],[Comp E75 -3 Run Hr]] -> 3420 | K3: ='PowerHouse Data'!D7-'PowerHouse Data'!C7 -> 15 | L3: ='PowerHouse Data'!$D$7 -> 25822 | M3: =$Q$3-Table113[[#This Row],[Comp E55 Run Hr]] -> 1108 | N3: 5440 | O3: 8066 | P3: 4000 | Q3: 26930
A4: 46204 | B4: =Table113[[#This Row],[Comp E75 -1 Run Hr]]-C3 -> 22 | C4: ='PowerHouse Data'!$E$4 -> 3709 | D4: =$N$3-Table113[[#This Row],[Comp E75 -1 Run Hr]] -> 1731 | E4: =Table113[[#This Row],[Comp E75 -2 Run Hr]]-F3 -> 0 | F4: ='PowerHouse Data'!$E$5 -> 6428 | G4: =$O$3-Table113[[#This Row],[Comp E75 -2 Run Hr]] -> 1638 | H4: =Table113[[#This Row],[Comp E75 -3 Run Hr]]-I3 -> 24 | I4: ='PowerHouse Data'!$E$6 -> 604 | J4: =$P$3-Table113[[#This Row],[Comp E75 -3 Run Hr]] -> 3396 | K4: =Table113[[#This Row],[Comp E55 Run Hr]]-L3 -> 24 | L4: ='PowerHouse Data'!$E$7 -> 25846 | M4: =$Q$3-Table113[[#This Row],[Comp E55 Run Hr]] -> 1084
A5: 46205 | B5: =Table113[[#This Row],[Comp E75 -1 Run Hr]]-C4 -> 23 | C5: ='PowerHouse Data'!$F$4 -> 3732 | D5: =$N$3-Table113[[#This Row],[Comp E75 -1 Run Hr]] -> 1708 | E5: =Table113[[#This Row],[Comp E75 -2 Run Hr]]-F4 -> 23 | F5: ='PowerHouse Data'!$F$5 -> 6451 | G5: =$O$3-Table113[[#This Row],[Comp E75 -2 Run Hr]] -> 1615 | H5: =Table113[[#This Row],[Comp E75 -3 Run Hr]]-I4 -> 0 | I5: ='PowerHouse Data'!$F$6 -> 604 | J5: =$P$3-Table113[[#This Row],[Comp E75 -3 Run Hr]] -> 3396 | K5: =Table113[[#This Row],[Comp E55 Run Hr]]-L4 -> 4 | L5: ='PowerHouse Data'!$F$7 -> 25850 | M5: =$Q$3-Table113[[#This Row],[Comp E55 Run Hr]] -> 1080
A6: 46206 | B6: =Table113[[#This Row],[Comp E75 -1 Run Hr]]-C5 -> 0 | C6: ='PowerHouse Data'!$G$4 -> 3732 | D6: =$N$3-Table113[[#This Row],[Comp E75 -1 Run Hr]] -> 1708 | E6: =Table113[[#This Row],[Comp E75 -2 Run Hr]]-F5 -> 24 | F6: ='PowerHouse Data'!$G$5 -> 6475 | G6: =$O$3-Table113[[#This Row],[Comp E75 -2 Run Hr]] -> 1591 | H6: =Table113[[#This Row],[Comp E75 -3 Run Hr]]-I5 -> 24 | I6: ='PowerHouse Data'!$G$6 -> 628 | J6: =$P$3-Table113[[#This Row],[Comp E75 -3 Run Hr]] -> 3372 | K6: =Table113[[#This Row],[Comp E55 Run Hr]]-L5 -> 0 | L6: ='PowerHouse Data'!$G$7 -> 25850 | M6: =$Q$3-Table113[[#This Row],[Comp E55 Run Hr]] -> 1080
A7: 46207 | B7: =Table113[[#This Row],[Comp E75 -1 Run Hr]]-C6 -> 24 | C7: ='PowerHouse Data'!$H$4 -> 3756 | D7: =$N$3-Table113[[#This Row],[Comp E75 -1 Run Hr]] -> 1684 | E7: =Table113[[#This Row],[Comp E75 -2 Run Hr]]-F6 -> 0 | F7: ='PowerHouse Data'!$H$5 -> 6475 | G7: =$O$3-Table113[[#This Row],[Comp E75 -2 Run Hr]] -> 1591 | H7: =Table113[[#This Row],[Comp E75 -3 Run Hr]]-I6 -> 0 | I7: ='PowerHouse Data'!$H$6 -> 628 | J7: =$P$3-Table113[[#This Row],[Comp E75 -3 Run Hr]] -> 3372 | K7: =Table113[[#This Row],[Comp E55 Run Hr]]-L6 -> 0 | L7: ='PowerHouse Data'!$H$7 -> 25850 | M7: =$Q$3-Table113[[#This Row],[Comp E55 Run Hr]] -> 1080
A8: 46208 | B8: =Table113[[#This Row],[Comp E75 -1 Run Hr]]-C7 -> 0 | C8: ='PowerHouse Data'!$I$4 -> 3756 | D8: =$N$3-Table113[[#This Row],[Comp E75 -1 Run Hr]] -> 1684 | E8: =Table113[[#This Row],[Comp E75 -2 Run Hr]]-F7 -> 0 | F8: ='PowerHouse Data'!$I$5 -> 6475 | G8: =$O$3-Table113[[#This Row],[Comp E75 -2 Run Hr]] -> 1591 | H8: =Table113[[#This Row],[Comp E75 -3 Run Hr]]-I7 -> 0 | I8: ='PowerHouse Data'!$I$6 -> 628 | J8: =$P$3-Table113[[#This Row],[Comp E75 -3 Run Hr]] -> 3372 | K8: =Table113[[#This Row],[Comp E55 Run Hr]]-L7 -> 0 | L8: ='PowerHouse Data'!$I$7 -> 25850 | M8: =$Q$3-Table113[[#This Row],[Comp E55 Run Hr]] -> 1080
A9: 46209 | B9: =Table113[[#This Row],[Comp E75 -1 Run Hr]]-C8 -> 9 | C9: ='PowerHouse Data'!$J$4 -> 3765 | D9: =$N$3-Table113[[#This Row],[Comp E75 -1 Run Hr]] -> 1675 | E9: =Table113[[#This Row],[Comp E75 -2 Run Hr]]-F8 -> 22 | F9: ='PowerHouse Data'!$J$5 -> 6497 | G9: =$O$3-Table113[[#This Row],[Comp E75 -2 Run Hr]] -> 1569 | H9: =Table113[[#This Row],[Comp E75 -3 Run Hr]]-I8 -> 14 | I9: ='PowerHouse Data'!$J$6 -> 642 | J9: =$P$3-Table113[[#This Row],[Comp E75 -3 Run Hr]] -> 3358 | K9: =Table113[[#This Row],[Comp E55 Run Hr]]-L8 -> 0 | L9: ='PowerHouse Data'!$J$7 -> 25850 | M9: =$Q$3-Table113[[#This Row],[Comp E55 Run Hr]] -> 1080
A10: 46210 | B10: =Table113[[#This Row],[Comp E75 -1 Run Hr]]-C9 -> 0 | C10: ='PowerHouse Data'!$K$4 -> 3765 | D10: =$N$3-Table113[[#This Row],[Comp E75 -1 Run Hr]] -> 1675 | E10: =Table113[[#This Row],[Comp E75 -2 Run Hr]]-F9 -> 24 | F10: ='PowerHouse Data'!$K$5 -> 6521 | G10: =$O$3-Table113[[#This Row],[Comp E75 -2 Run Hr]] -> 1545 | H10: =Table113[[#This Row],[Comp E75 -3 Run Hr]]-I9 -> 23 | I10: ='PowerHouse Data'!$K$6 -> 665 | J10: =$P$3-Table113[[#This Row],[Comp E75 -3 Run Hr]] -> 3335 | K10: =Table113[[#This Row],[Comp E55 Run Hr]]-L9 -> 0 | L10: ='PowerHouse Data'!$K$7 -> 25850 | M10: =$Q$3-Table113[[#This Row],[Comp E55 Run Hr]] -> 1080
A11: 46211 | B11: =Table113[[#This Row],[Comp E75 -1 Run Hr]]-C10 -> 23 | C11: ='PowerHouse Data'!$L$4 -> 3788 | D11: =$N$3-Table113[[#This Row],[Comp E75 -1 Run Hr]] -> 1652 | E11: =Table113[[#This Row],[Comp E75 -2 Run Hr]]-F10 -> 0 | F11: ='PowerHouse Data'!$L$5 -> 6521 | G11: =$O$3-Table113[[#This Row],[Comp E75 -2 Run Hr]] -> 1545 | H11: =Table113[[#This Row],[Comp E75 -3 Run Hr]]-I10 -> 23 | I11: ='PowerHouse Data'!$L$6 -> 688 | J11: =$P$3-Table113[[#This Row],[Comp E75 -3 Run Hr]] -> 3312 | K11: =Table113[[#This Row],[Comp E55 Run Hr]]-L10 -> 0 | L11: ='PowerHouse Data'!$L$7 -> 25850 | M11: =$Q$3-Table113[[#This Row],[Comp E55 Run Hr]] -> 1080
A12: 46212 | B12: =Table113[[#This Row],[Comp E75 -1 Run Hr]]-C11 -> 24 | C12: ='PowerHouse Data'!$M$4 -> 3812 | D12: =$N$3-Table113[[#This Row],[Comp E75 -1 Run Hr]] -> 1628 | E12: =Table113[[#This Row],[Comp E75 -2 Run Hr]]-F11 -> 24 | F12: ='PowerHouse Data'!$M$5 -> 6545 | G12: =$O$3-Table113[[#This Row],[Comp E75 -2 Run Hr]] -> 1521 | H12: =Table113[[#This Row],[Comp E75 -3 Run Hr]]-I11 -> 0 | I12: ='PowerHouse Data'!$M$6 -> 688 | J12: =$P$3-Table113[[#This Row],[Comp E75 -3 Run Hr]] -> 3312 | K12: =Table113[[#This Row],[Comp E55 Run Hr]]-L11 -> 0 | L12: ='PowerHouse Data'!$M$7 -> 25850 | M12: =$Q$3-Table113[[#This Row],[Comp E55 Run Hr]] -> 1080
A13: 46213 | B13: =Table113[[#This Row],[Comp E75 -1 Run Hr]]-C12 -> 0 | C13: ='PowerHouse Data'!$N$4 -> 3812 | D13: =$N$3-Table113[[#This Row],[Comp E75 -1 Run Hr]] -> 1628 | E13: =Table113[[#This Row],[Comp E75 -2 Run Hr]]-F12 -> 0 | F13: ='PowerHouse Data'!$N$5 -> 6545 | G13: =$O$3-Table113[[#This Row],[Comp E75 -2 Run Hr]] -> 1521 | H13: =Table113[[#This Row],[Comp E75 -3 Run Hr]]-I12 -> 24 | I13: ='PowerHouse Data'!$N$6 -> 712 | J13: =$P$3-Table113[[#This Row],[Comp E75 -3 Run Hr]] -> 3288 | K13: =Table113[[#This Row],[Comp E55 Run Hr]]-L12 -> 0 | L13: ='PowerHouse Data'!$N$7 -> 25850 | M13: =$Q$3-Table113[[#This Row],[Comp E55 Run Hr]] -> 1080
A14: 46214 | B14: =Table113[[#This Row],[Comp E75 -1 Run Hr]]-C13 -> 0 | C14: ='PowerHouse Data'!$O$4 -> 3812 | D14: =$N$3-Table113[[#This Row],[Comp E75 -1 Run Hr]] -> 1628 | E14: =Table113[[#This Row],[Comp E75 -2 Run Hr]]-F13 -> 14 | F14: ='PowerHouse Data'!$O$5 -> 6559 | G14: =$O$3-Table113[[#This Row],[Comp E75 -2 Run Hr]] -> 1507 | H14: =Table113[[#This Row],[Comp E75 -3 Run Hr]]-I13 -> 0 | I14: ='PowerHouse Data'!$O$6 -> 712 | J14: =$P$3-Table113[[#This Row],[Comp E75 -3 Run Hr]] -> 3288 | K14: =Table113[[#This Row],[Comp E55 Run Hr]]-L13 -> 11 | L14: ='PowerHouse Data'!$O$7 -> 25861 | M14: =$Q$3-Table113[[#This Row],[Comp E55 Run Hr]] -> 1069
A15: 46215 | B15: =Table113[[#This Row],[Comp E75 -1 Run Hr]]-C14 -> 0 | C15: ='PowerHouse Data'!$P$4 -> 3812 | D15: =$N$3-Table113[[#This Row],[Comp E75 -1 Run Hr]] -> 1628 | E15: =Table113[[#This Row],[Comp E75 -2 Run Hr]]-F14 -> 0 | F15: ='PowerHouse Data'!$P$5 -> 6559 | G15: =$O$3-Table113[[#This Row],[Comp E75 -2 Run Hr]] -> 1507 | H15: =Table113[[#This Row],[Comp E75 -3 Run Hr]]-I14 -> 0 | I15: ='PowerHouse Data'!$P$6 -> 712 | J15: =$P$3-Table113[[#This Row],[Comp E75 -3 Run Hr]] -> 3288 | K15: =Table113[[#This Row],[Comp E55 Run Hr]]-L14 -> 24 | L15: ='PowerHouse Data'!$P$7 -> 25885 | M15: =$Q$3-Table113[[#This Row],[Comp E55 Run Hr]] -> 1045
A16: 46216 | B16: =Table113[[#This Row],[Comp E75 -1 Run Hr]]-C15 -> 21 | C16: ='PowerHouse Data'!$Q$4 -> 3833 | D16: =$N$3-Table113[[#This Row],[Comp E75 -1 Run Hr]] -> 1607 | E16: =Table113[[#This Row],[Comp E75 -2 Run Hr]]-F15 -> 23 | F16: ='PowerHouse Data'!$Q$5 -> 6582 | G16: =$O$3-Table113[[#This Row],[Comp E75 -2 Run Hr]] -> 1484 | H16: =Table113[[#This Row],[Comp E75 -3 Run Hr]]-I15 -> 0 | I16: ='PowerHouse Data'!$Q$6 -> 712 | J16: =$P$3-Table113[[#This Row],[Comp E75 -3 Run Hr]] -> 3288 | K16: =Table113[[#This Row],[Comp E55 Run Hr]]-L15 -> 0 | L16: ='PowerHouse Data'!$Q$7 -> 25885 | M16: =$Q$3-Table113[[#This Row],[Comp E55 Run Hr]] -> 1045
A17: 46217 | B17: =Table113[[#This Row],[Comp E75 -1 Run Hr]]-C16 -> 0 | C17: ='PowerHouse Data'!$R$4 -> 3833 | D17: =$N$3-Table113[[#This Row],[Comp E75 -1 Run Hr]] -> 1607 | E17: =Table113[[#This Row],[Comp E75 -2 Run Hr]]-F16 -> 24 | F17: ='PowerHouse Data'!$R$5 -> 6606 | G17: =$O$3-Table113[[#This Row],[Comp E75 -2 Run Hr]] -> 1460 | H17: =Table113[[#This Row],[Comp E75 -3 Run Hr]]-I16 -> 22 | I17: ='PowerHouse Data'!$R$6 -> 734 | J17: =$P$3-Table113[[#This Row],[Comp E75 -3 Run Hr]] -> 3266 | K17: =Table113[[#This Row],[Comp E55 Run Hr]]-L16 -> 0 | L17: ='PowerHouse Data'!$R$7 -> 25885 | M17: =$Q$3-Table113[[#This Row],[Comp E55 Run Hr]] -> 1045
A18: 46218 | B18: =Table113[[#This Row],[Comp E75 -1 Run Hr]]-C17 -> 24 | C18: ='PowerHouse Data'!$S$4 -> 3857 | D18: =$N$3-Table113[[#This Row],[Comp E75 -1 Run Hr]] -> 1583 | E18: =Table113[[#This Row],[Comp E75 -2 Run Hr]]-F17 -> 0 | F18: ='PowerHouse Data'!$S$5 -> 6606 | G18: =$O$3-Table113[[#This Row],[Comp E75 -2 Run Hr]] -> 1460 | H18: =Table113[[#This Row],[Comp E75 -3 Run Hr]]-I17 -> 24 | I18: ='PowerHouse Data'!$S$6 -> 758 | J18: =$P$3-Table113[[#This Row],[Comp E75 -3 Run Hr]] -> 3242 | K18: =Table113[[#This Row],[Comp E55 Run Hr]]-L17 -> 0 | L18: ='PowerHouse Data'!$S$7 -> 25885 | M18: =$Q$3-Table113[[#This Row],[Comp E55 Run Hr]] -> 1045
A19: 46219 | B19: =Table113[[#This Row],[Comp E75 -1 Run Hr]]-C18 -> 23 | C19: ='PowerHouse Data'!$T$4 -> 3880 | D19: =$N$3-Table113[[#This Row],[Comp E75 -1 Run Hr]] -> 1560 | E19: =Table113[[#This Row],[Comp E75 -2 Run Hr]]-F18 -> 24 | F19: ='PowerHouse Data'!$T$5 -> 6630 | G19: =$O$3-Table113[[#This Row],[Comp E75 -2 Run Hr]] -> 1436 | H19: =Table113[[#This Row],[Comp E75 -3 Run Hr]]-I18 -> 0 | I19: ='PowerHouse Data'!$T$6 -> 758 | J19: =$P$3-Table113[[#This Row],[Comp E75 -3 Run Hr]] -> 3242 | K19: =Table113[[#This Row],[Comp E55 Run Hr]]-L18 -> 1 | L19: ='PowerHouse Data'!$T$7 -> 25886 | M19: =$Q$3-Table113[[#This Row],[Comp E55 Run Hr]] -> 1044
A20: 46220 | B20: =Table113[[#This Row],[Comp E75 -1 Run Hr]]-C19 -> 0 | C20: ='PowerHouse Data'!$U$4 -> 3880 | D20: =$N$3-Table113[[#This Row],[Comp E75 -1 Run Hr]] -> 1560 | E20: =Table113[[#This Row],[Comp E75 -2 Run Hr]]-F19 -> 22 | F20: ='PowerHouse Data'!$U$5 -> 6652 | G20: =$O$3-Table113[[#This Row],[Comp E75 -2 Run Hr]] -> 1414 | H20: =Table113[[#This Row],[Comp E75 -3 Run Hr]]-I19 -> 23 | I20: ='PowerHouse Data'!$U$6 -> 781 | J20: =$P$3-Table113[[#This Row],[Comp E75 -3 Run Hr]] -> 3219 | K20: =Table113[[#This Row],[Comp E55 Run Hr]]-L19 -> 0 | L20: ='PowerHouse Data'!$U$7 -> 25886 | M20: =$Q$3-Table113[[#This Row],[Comp E55 Run Hr]] -> 1044
A21: 46221 | B21: =Table113[[#This Row],[Comp E75 -1 Run Hr]]-C20 -> 2 | C21: ='PowerHouse Data'!$V$4 -> 3882 | D21: =$N$3-Table113[[#This Row],[Comp E75 -1 Run Hr]] -> 1558 | E21: =Table113[[#This Row],[Comp E75 -2 Run Hr]]-F20 -> 0 | F21: ='PowerHouse Data'!$V$5 -> 6652 | G21: =$O$3-Table113[[#This Row],[Comp E75 -2 Run Hr]] -> 1414 | H21: =Table113[[#This Row],[Comp E75 -3 Run Hr]]-I20 -> 24 | I21: ='PowerHouse Data'!$V$6 -> 805 | J21: =$P$3-Table113[[#This Row],[Comp E75 -3 Run Hr]] -> 3195 | K21: =Table113[[#This Row],[Comp E55 Run Hr]]-L20 -> 0 | L21: ='PowerHouse Data'!$V$7 -> 25886 | M21: =$Q$3-Table113[[#This Row],[Comp E55 Run Hr]] -> 1044
A22: 46222 | B22: =Table113[[#This Row],[Comp E75 -1 Run Hr]]-C21 -> 0 | C22: ='PowerHouse Data'!$W$4 -> 3882 | D22: =$N$3-Table113[[#This Row],[Comp E75 -1 Run Hr]] -> 1558 | E22: =Table113[[#This Row],[Comp E75 -2 Run Hr]]-F21 -> 0 | F22: ='PowerHouse Data'!$W$5 -> 6652 | G22: =$O$3-Table113[[#This Row],[Comp E75 -2 Run Hr]] -> 1414 | H22: =Table113[[#This Row],[Comp E75 -3 Run Hr]]-I21 -> 0 | I22: ='PowerHouse Data'!$W$6 -> 805 | J22: =$P$3-Table113[[#This Row],[Comp E75 -3 Run Hr]] -> 3195 | K22: =Table113[[#This Row],[Comp E55 Run Hr]]-L21 -> 0 | L22: ='PowerHouse Data'!$W$7 -> 25886 | M22: =$Q$3-Table113[[#This Row],[Comp E55 Run Hr]] -> 1044
A23: 46223 | B23: =Table113[[#This Row],[Comp E75 -1 Run Hr]]-C22 -> 22 | C23: ='PowerHouse Data'!$X$4 -> 3904 | D23: =$N$3-Table113[[#This Row],[Comp E75 -1 Run Hr]] -> 1536 | E23: =Table113[[#This Row],[Comp E75 -2 Run Hr]]-F22 -> 24 | F23: ='PowerHouse Data'!$X$5 -> 6676 | G23: =$O$3-Table113[[#This Row],[Comp E75 -2 Run Hr]] -> 1390 | H23: =Table113[[#This Row],[Comp E75 -3 Run Hr]]-I22 -> 0 | I23: ='PowerHouse Data'!$X$6 -> 805 | J23: =$P$3-Table113[[#This Row],[Comp E75 -3 Run Hr]] -> 3195 | K23: =Table113[[#This Row],[Comp E55 Run Hr]]-L22 -> 0 | L23: ='PowerHouse Data'!$X$7 -> 25886 | M23: =$Q$3-Table113[[#This Row],[Comp E55 Run Hr]] -> 1044
A24: 46224 | B24: =Table113[[#This Row],[Comp E75 -1 Run Hr]]-C23 -> 0 | C24: ='PowerHouse Data'!$Y$4 -> 3904 | D24: =$N$3-Table113[[#This Row],[Comp E75 -1 Run Hr]] -> 1536 | E24: =Table113[[#This Row],[Comp E75 -2 Run Hr]]-F23 -> 24 | F24: ='PowerHouse Data'!$Y$5 -> 6700 | G24: =$O$3-Table113[[#This Row],[Comp E75 -2 Run Hr]] -> 1366 | H24: =Table113[[#This Row],[Comp E75 -3 Run Hr]]-I23 -> 23 | I24: ='PowerHouse Data'!$Y$6 -> 828 | J24: =$P$3-Table113[[#This Row],[Comp E75 -3 Run Hr]] -> 3172 | K24: =Table113[[#This Row],[Comp E55 Run Hr]]-L23 -> 0 | L24: ='PowerHouse Data'!$Y$7 -> 25886 | M24: =$Q$3-Table113[[#This Row],[Comp E55 Run Hr]] -> 1044
A25: 46225 | B25: =Table113[[#This Row],[Comp E75 -1 Run Hr]]-C24 -> 23 | C25: ='PowerHouse Data'!$Z$4 -> 3927 | D25: =$N$3-Table113[[#This Row],[Comp E75 -1 Run Hr]] -> 1513 | E25: =Table113[[#This Row],[Comp E75 -2 Run Hr]]-F24 -> 0 | F25: ='PowerHouse Data'!$Z$5 -> 6700 | G25: =$O$3-Table113[[#This Row],[Comp E75 -2 Run Hr]] -> 1366 | H25: =Table113[[#This Row],[Comp E75 -3 Run Hr]]-I24 -> 24 | I25: ='PowerHouse Data'!$Z$6 -> 852 | J25: =$P$3-Table113[[#This Row],[Comp E75 -3 Run Hr]] -> 3148 | K25: =Table113[[#This Row],[Comp E55 Run Hr]]-L24 -> 0 | L25: ='PowerHouse Data'!$Z$7 -> 25886 | M25: =$Q$3-Table113[[#This Row],[Comp E55 Run Hr]] -> 1044
A26: 46226 | B26: =Table113[[#This Row],[Comp E75 -1 Run Hr]]-C25 -> 14 | C26: ='PowerHouse Data'!$AA$4 -> 3941 | D26: =$N$3-Table113[[#This Row],[Comp E75 -1 Run Hr]] -> 1499 | E26: =Table113[[#This Row],[Comp E75 -2 Run Hr]]-F25 -> 23 | F26: ='PowerHouse Data'!$AA$5 -> 6723 | G26: =$O$3-Table113[[#This Row],[Comp E75 -2 Run Hr]] -> 1343 | H26: =Table113[[#This Row],[Comp E75 -3 Run Hr]]-I25 -> 5 | I26: ='PowerHouse Data'!$AA$6 -> 857 | J26: =$P$3-Table113[[#This Row],[Comp E75 -3 Run Hr]] -> 3143 | K26: =Table113[[#This Row],[Comp E55 Run Hr]]-L25 -> 0 | L26: ='PowerHouse Data'!$AA$7 -> 25886 | M26: =$Q$3-Table113[[#This Row],[Comp E55 Run Hr]] -> 1044
A27: 46227 | B27: =Table113[[#This Row],[Comp E75 -1 Run Hr]]-C26 -> 0 | C27: ='PowerHouse Data'!$AB$4 -> 3941 | D27: =$N$3-Table113[[#This Row],[Comp E75 -1 Run Hr]] -> 1499 | E27: =Table113[[#This Row],[Comp E75 -2 Run Hr]]-F26 -> 24 | F27: ='PowerHouse Data'!$AB$5 -> 6747 | G27: =$O$3-Table113[[#This Row],[Comp E75 -2 Run Hr]] -> 1319 | H27: =Table113[[#This Row],[Comp E75 -3 Run Hr]]-I26 -> 24 | I27: ='PowerHouse Data'!$AB$6 -> 881 | J27: =$P$3-Table113[[#This Row],[Comp E75 -3 Run Hr]] -> 3119 | K27: =Table113[[#This Row],[Comp E55 Run Hr]]-L26 -> 0 | L27: ='PowerHouse Data'!$AB$7 -> 25886 | M27: =$Q$3-Table113[[#This Row],[Comp E55 Run Hr]] -> 1044
A28: 46228 | B28: =Table113[[#This Row],[Comp E75 -1 Run Hr]]-C27 -> 0 | C28: ='PowerHouse Data'!$AC$4 -> 3941 | D28: =$N$3-Table113[[#This Row],[Comp E75 -1 Run Hr]] -> 1499 | E28: =Table113[[#This Row],[Comp E75 -2 Run Hr]]-F27 -> 2 | F28: ='PowerHouse Data'!$AC$5 -> 6749 | G28: =$O$3-Table113[[#This Row],[Comp E75 -2 Run Hr]] -> 1317 | H28: =Table113[[#This Row],[Comp E75 -3 Run Hr]]-I27 -> 0 | I28: ='PowerHouse Data'!$AC$6 -> 881 | J28: =$P$3-Table113[[#This Row],[Comp E75 -3 Run Hr]] -> 3119 | K28: =Table113[[#This Row],[Comp E55 Run Hr]]-L27 -> 21 | L28: ='PowerHouse Data'!$AC$7 -> 25907 | M28: =$Q$3-Table113[[#This Row],[Comp E55 Run Hr]] -> 1023
A29: 46229 | B29: =Table113[[#This Row],[Comp E75 -1 Run Hr]]-C28 -> 0 | C29: ='PowerHouse Data'!$AD$4 -> 3941 | D29: =$N$3-Table113[[#This Row],[Comp E75 -1 Run Hr]] -> 1499 | E29: =Table113[[#This Row],[Comp E75 -2 Run Hr]]-F28 -> 0 | F29: ='PowerHouse Data'!$AD$5 -> 6749 | G29: =$O$3-Table113[[#This Row],[Comp E75 -2 Run Hr]] -> 1317 | H29: =Table113[[#This Row],[Comp E75 -3 Run Hr]]-I28 -> 0 | I29: ='PowerHouse Data'!$AD$6 -> 881 | J29: =$P$3-Table113[[#This Row],[Comp E75 -3 Run Hr]] -> 3119 | K29: =Table113[[#This Row],[Comp E55 Run Hr]]-L28 -> 24 | L29: ='PowerHouse Data'!$AD$7 -> 25931 | M29: =$Q$3-Table113[[#This Row],[Comp E55 Run Hr]] -> 999
A30: 46230 | B30: =Table113[[#This Row],[Comp E75 -1 Run Hr]]-C29 -> 0 | C30: ='PowerHouse Data'!$AE$4 -> 3941 | D30: =$N$3-Table113[[#This Row],[Comp E75 -1 Run Hr]] -> 1499 | E30: =Table113[[#This Row],[Comp E75 -2 Run Hr]]-F29 -> 24 | F30: ='PowerHouse Data'!$AE$5 -> 6773 | G30: =$O$3-Table113[[#This Row],[Comp E75 -2 Run Hr]] -> 1293 | H30: =Table113[[#This Row],[Comp E75 -3 Run Hr]]-I29 -> 23 | I30: ='PowerHouse Data'!$AE$6 -> 904 | J30: =$P$3-Table113[[#This Row],[Comp E75 -3 Run Hr]] -> 3096 | K30: =Table113[[#This Row],[Comp E55 Run Hr]]-L29 -> 0 | L30: ='PowerHouse Data'!$AE$7 -> 25931 | M30: =$Q$3-Table113[[#This Row],[Comp E55 Run Hr]] -> 999
A31: 46231 | B31: =Table113[[#This Row],[Comp E75 -1 Run Hr]]-C30 -> 23 | C31: ='PowerHouse Data'!$AF$4 -> 3964 | D31: =$N$3-Table113[[#This Row],[Comp E75 -1 Run Hr]] -> 1476 | E31: =Table113[[#This Row],[Comp E75 -2 Run Hr]]-F30 -> 0 | F31: ='PowerHouse Data'!$AF$5 -> 6773 | G31: =$O$3-Table113[[#This Row],[Comp E75 -2 Run Hr]] -> 1293 | H31: =Table113[[#This Row],[Comp E75 -3 Run Hr]]-I30 -> 22 | I31: ='PowerHouse Data'!$AF$6 -> 926 | J31: =$P$3-Table113[[#This Row],[Comp E75 -3 Run Hr]] -> 3074 | K31: =Table113[[#This Row],[Comp E55 Run Hr]]-L30 -> 0 | L31: ='PowerHouse Data'!$AF$7 -> 25931 | M31: =$Q$3-Table113[[#This Row],[Comp E55 Run Hr]] -> 999
A32: 46232 | B32: =Table113[[#This Row],[Comp E75 -1 Run Hr]]-C31 -> 24 | C32: ='PowerHouse Data'!$AG$4 -> 3988 | D32: =$N$3-Table113[[#This Row],[Comp E75 -1 Run Hr]] -> 1452 | E32: =Table113[[#This Row],[Comp E75 -2 Run Hr]]-F31 -> 24 | F32: ='PowerHouse Data'!$AG$5 -> 6797 | G32: =$O$3-Table113[[#This Row],[Comp E75 -2 Run Hr]] -> 1269 | H32: =Table113[[#This Row],[Comp E75 -3 Run Hr]]-I31 -> 0 | I32: ='PowerHouse Data'!$AG$6 -> 926 | J32: =$P$3-Table113[[#This Row],[Comp E75 -3 Run Hr]] -> 3074 | K32: =Table113[[#This Row],[Comp E55 Run Hr]]-L31 -> 0 | L32: ='PowerHouse Data'!$AG$7 -> 25931 | M32: =$Q$3-Table113[[#This Row],[Comp E55 Run Hr]] -> 999
A33: 46233 | B33: =Table113[[#This Row],[Comp E75 -1 Run Hr]]-C32 -> 0 | C33: ='PowerHouse Data'!$AH$4 -> 3988 | D33: =$N$3-Table113[[#This Row],[Comp E75 -1 Run Hr]] -> 1452 | E33: =Table113[[#This Row],[Comp E75 -2 Run Hr]]-F32 -> 24 | F33: ='PowerHouse Data'!$AH$5 -> 6821 | G33: =$O$3-Table113[[#This Row],[Comp E75 -2 Run Hr]] -> 1245 | H33: =Table113[[#This Row],[Comp E75 -3 Run Hr]]-I32 -> 22 | I33: ='PowerHouse Data'!$AH$6 -> 948 | J33: =$P$3-Table113[[#This Row],[Comp E75 -3 Run Hr]] -> 3052 | K33: =Table113[[#This Row],[Comp E55 Run Hr]]-L32 -> 0 | L33: ='PowerHouse Data'!$AH$7 -> 25931 | M33: =$Q$3-Table113[[#This Row],[Comp E55 Run Hr]] -> 999
A34: 46234 | B34: =Table113[[#This Row],[Comp E75 -1 Run Hr]]-C33 -> 24 | C34: ='PowerHouse Data'!$AI$4 -> 4012 | D34: =$N$3-Table113[[#This Row],[Comp E75 -1 Run Hr]] -> 1428 | E34: =Table113[[#This Row],[Comp E75 -2 Run Hr]]-F33 -> 0 | F34: ='PowerHouse Data'!$AI$5 -> 6821 | G34: =$O$3-Table113[[#This Row],[Comp E75 -2 Run Hr]] -> 1245 | H34: =Table113[[#This Row],[Comp E75 -3 Run Hr]]-I33 -> 24 | I34: ='PowerHouse Data'!$AI$6 -> 972 | J34: =$P$3-Table113[[#This Row],[Comp E75 -3 Run Hr]] -> 3028 | K34: =Table113[[#This Row],[Comp E55 Run Hr]]-L33 -> 0 | L34: ='PowerHouse Data'!$AI$7 -> 25931 | M34: =$Q$3-Table113[[#This Row],[Comp E55 Run Hr]] -> 999
A35: 46235 | B35: =Table113[[#This Row],[Comp E75 -1 Run Hr]]-C34 -> -4012 | C35: ='PowerHouse Data'!$AJ$4 -> 0 | D35: =$N$3-Table113[[#This Row],[Comp E75 -1 Run Hr]] -> 5440 | E35: =Table113[[#This Row],[Comp E75 -2 Run Hr]]-F34 -> -6821 | F35: ='PowerHouse Data'!$AJ$5 -> 0 | G35: =$O$3-Table113[[#This Row],[Comp E75 -2 Run Hr]] -> 8066 | H35: =Table113[[#This Row],[Comp E75 -2 Run Hr]]-I34 -> -972 | I35: ='PowerHouse Data'!$AJ$6 -> 0 | J35: =$P$3-Table113[[#This Row],[Comp E75 -2 Run Hr]] -> 4000 | K35: =Table113[[#This Row],[Comp E55 Run Hr]]-L34 -> -25931 | L35: ='PowerHouse Data'!$AJ$7 -> 0 | M35: =$Q$3-Table113[[#This Row],[Comp E55 Run Hr]] -> 26930

Sheet Diesel
A1: Date | B1: TIME | C1: Dip Stick Reading O/P Stock | D1: Dip Stick Reading C/L Stock | E1: Main Tank Opening Stock (Liters) | F1: Received (Liters) | G1: Main Tank Consumption (Liters) | H1: Main Tank Closing Stock (Liters) | I1: Current Total stock (Liters) | J1: DG Milling Run Hours | K1: DG Milling Run Hr Meter | L1: DG Parboiling Run Hours | M1: DG Parboiling Run Hr Meter | N1: DG Parboiling Run Hr Meter2 | O1: DG Parboiling Run Hr Meter3 | P1: DG Parboiling Run Hr Meter4 | Q1: DG Parboiling Run Hr Meter5 | R1: DIESEL ISSUE | S1: total consumption | T1: Dip / mm | U1: Volume / Litters | V1: Service tank (Liters)
A2: 46202 | C2: 2060 | D2: 1932 | E2: 0 | F2: 37278 | G2: 0 | H2: 0 | I2: 2434 | J2: 34844 | K2: 5184 | L2: 9 | M2: 5631.3 | N2: 9 | O2: 12488.3 | P2: 5824 | Q2: 192.7 | R2: 0 | S2: =Table113456[[#This Row],[Main Tank Consumption (Liters)]]-Table113456[[#This Row],[DIESEL ISSUE]] -> 0 | V2: ='PowerHouse Data'!C14 -> 5184
A3: 46203 | B3: 0.29166667 | C3: ='PowerHouse Data'!C2 -> 1932 | D3: ='PowerHouse Data'!$D$2 -> 1876 | E3: =VLOOKUP(C3,$T$3:$U$1366,2,FALSE) -> 34844 | F3: ='PowerHouse Data'!$D$12 -> 0 | G3: =Table113456[[#This Row],[Main Tank Opening Stock (Liters)]]-Table113456[[#This Row],[Main Tank Closing Stock (Liters)]]+Table113456[[#This Row],[Received (Liters)]] -> 1105 | H3: =VLOOKUP(D3,$T$3:$U$1366,2,FALSE) -> 33739 | I3: =Table113456[[#This Row],[Main Tank Closing Stock (Liters)]]+V3 -> 38923 | J3: ='PowerHouse Data'!D8-'PowerHouse Data'!C8 -> 5 | K3: ='PowerHouse Data'!$D$8 -> 5636.3 | L3: ='PowerHouse Data'!D9-'PowerHouse Data'!C9 -> 5 | M3: ='PowerHouse Data'!$D$9 -> 12493.3 | N3: 5824 | O3: =Table113456[[#This Row],[DG Parboiling Run Hr Meter2]]-Table113456[[#This Row],[DG Milling Run Hr Meter]] -> 187.7 | P3: 12643.5 | Q3: =Table113456[[#This Row],[DG Parboiling Run Hr Meter4]]-Table113456[[#This Row],[DG Parboiling Run Hr Meter]] -> 150.2 | R3: ='PowerHouse Data'!$D$13 -> 0 | S3: =Table113456[[#This Row],[Main Tank Consumption (Liters)]]-Table113456[[#This Row],[DIESEL ISSUE]] -> 1105 | T3: 0 | U3: 0 | V3: ='PowerHouse Data'!$D$14 -> 5184
A4: 46204 | B4: 0.29166667 | C4: =D3 -> 1876 | D4: ='PowerHouse Data'!$E$2 -> 1872 | E4: =VLOOKUP(C4,$T$3:$U$1366,2,FALSE) -> 33739 | F4: ='PowerHouse Data'!$E$12 -> 0 | G4: =Table113456[[#This Row],[Main Tank Opening Stock (Liters)]]-Table113456[[#This Row],[Main Tank Closing Stock (Liters)]]+Table113456[[#This Row],[Received (Liters)]] -> 79 | H4: =VLOOKUP(D4,$T$3:$U$1366,2,FALSE) -> 33660 | I4: =Table113456[[#This Row],[Main Tank Closing Stock (Liters)]]+V4 -> 38844 | J4: =Table113456[[#This Row],[DG Milling Run Hr Meter]]-K3 -> 0 | K4: ='PowerHouse Data'!$E$8 -> 5636.3 | L4: =Table113456[[#This Row],[DG Parboiling Run Hr Meter]]-M3 -> 1.2 | M4: ='PowerHouse Data'!$E$9 -> 12494.5 | N4: 5824 | O4: =Table113456[[#This Row],[DG Parboiling Run Hr Meter2]]-Table113456[[#This Row],[DG Milling Run Hr Meter]] -> 187.7 | P4: 12643.5 | Q4: =Table113456[[#This Row],[DG Parboiling Run Hr Meter4]]-Table113456[[#This Row],[DG Parboiling Run Hr Meter]] -> 149 | R4: ='PowerHouse Data'!$E$13 -> 0 | S4: =Table113456[[#This Row],[Main Tank Consumption (Liters)]]+Table113456[[#This Row],[DIESEL ISSUE]] -> 79 | T4: 2 | U4: 2 | V4: ='PowerHouse Data'!$E$14 -> 5184
A5: 46205 | B5: 0.29166667 | C5: =D4 -> 1872 | D5: ='PowerHouse Data'!$F$2 -> 1792 | E5: =VLOOKUP(C5,$T$3:$U$1366,2,FALSE) -> 33660 | F5: ='PowerHouse Data'!$F$12 -> 0 | G5: =Table113456[[#This Row],[Main Tank Opening Stock (Liters)]]-Table113456[[#This Row],[Main Tank Closing Stock (Liters)]]+Table113456[[#This Row],[Received (Liters)]] -> 1615 | H5: =VLOOKUP(D5,$T$3:$U$1366,2,FALSE) -> 32045 | I5: =Table113456[[#This Row],[Main Tank Closing Stock (Liters)]]+V5 -> 37229 | J5: =Table113456[[#This Row],[DG Milling Run Hr Meter]]-K4 -> 6 | K5: ='PowerHouse Data'!$F$8 -> 5642.3 | L5: =Table113456[[#This Row],[DG Parboiling Run Hr Meter]]-M4 -> 6.6 | M5: ='PowerHouse Data'!$F$9 -> 12501.1 | N5: 5824 | O5: =Table113456[[#This Row],[DG Parboiling Run Hr Meter2]]-Table113456[[#This Row],[DG Milling Run Hr Meter]] -> 181.7 | P5: 12643.5 | Q5: =Table113456[[#This Row],[DG Parboiling Run Hr Meter4]]-Table113456[[#This Row],[DG Parboiling Run Hr Meter]] -> 142.4 | R5: ='PowerHouse Data'!$F$13 -> 75 | S5: =Table113456[[#This Row],[Main Tank Consumption (Liters)]]-Table113456[[#This Row],[DIESEL ISSUE]] -> 1540 | T5: 4 | U5: 4 | V5: ='PowerHouse Data'!$F$14 -> 5184
A6: 46206 | B6: 0.29166667 | C6: =D5 -> 1792 | D6: ='PowerHouse Data'!$G$2 -> 1792 | E6: =VLOOKUP(C6,$T$3:$U$1366,2,FALSE) -> 32045 | F6: ='PowerHouse Data'!$G$12 -> 0 | G6: =Table113456[[#This Row],[Main Tank Opening Stock (Liters)]]-Table113456[[#This Row],[Main Tank Closing Stock (Liters)]]+Table113456[[#This Row],[Received (Liters)]] -> 0 | H6: =VLOOKUP(D6,$T$3:$U$1366,2,FALSE) -> 32045 | I6: =Table113456[[#This Row],[Main Tank Closing Stock (Liters)]]+V6 -> 37229 | J6: =Table113456[[#This Row],[DG Milling Run Hr Meter]]-K5 -> 0 | K6: ='PowerHouse Data'!$G$8 -> 5642.3 | L6: =Table113456[[#This Row],[DG Parboiling Run Hr Meter]]-M5 -> 0 | M6: ='PowerHouse Data'!$G$9 -> 12501.1 | N6: 5824 | O6: =Table113456[[#This Row],[DG Parboiling Run Hr Meter2]]-Table113456[[#This Row],[DG Milling Run Hr Meter]] -> 181.7 | P6: 12643.5 | Q6: =Table113456[[#This Row],[DG Parboiling Run Hr Meter4]]-Table113456[[#This Row],[DG Parboiling Run Hr Meter]] -> 142.4 | R6: ='PowerHouse Data'!$G$13 -> 0 | S6: =Table113456[[#This Row],[DIESEL ISSUE]]+Table113456[[#This Row],[Main Tank Consumption (Liters)]] -> 0 | T6: 6 | U6: 8 | V6: ='PowerHouse Data'!$G$14 -> 5184
A7: 46207 | B7: 0.29166667 | C7: =D6 -> 1792 | D7: ='PowerHouse Data'!$H$2 -> 1750 | E7: =VLOOKUP(C7,$T$3:$U$1366,2,FALSE) -> 32045 | F7: ='PowerHouse Data'!$H$12 -> 0 | G7: =Table113456[[#This Row],[Main Tank Opening Stock (Liters)]]-Table113456[[#This Row],[Main Tank Closing Stock (Liters)]]+Table113456[[#This Row],[Received (Liters)]] -> 861.5 | H7: =VLOOKUP(D7,$T$3:$U$1366,2,FALSE) -> 31183.5 | I7: =Table113456[[#This Row],[Main Tank Closing Stock (Liters)]]+V7 -> 36367.5 | J7: =Table113456[[#This Row],[DG Milling Run Hr Meter]]-K6 -> 0 | K7: ='PowerHouse Data'!$H$8 -> 5642.3 | L7: =Table113456[[#This Row],[DG Parboiling Run Hr Meter]]-M6 -> 0 | M7: ='PowerHouse Data'!$H$9 -> 12501.1 | N7: 5824 | O7: =Table113456[[#This Row],[DG Parboiling Run Hr Meter2]]-Table113456[[#This Row],[DG Milling Run Hr Meter]] -> 181.7 | P7: 12643.5 | Q7: =Table113456[[#This Row],[DG Parboiling Run Hr Meter4]]-Table113456[[#This Row],[DG Parboiling Run Hr Meter]] -> 142.4 | R7: ='PowerHouse Data'!$H$13 -> 862 | S7: =(Table113456[[#This Row],[Main Tank Consumption (Liters)]]+Table113456[[#This Row],[DIESEL ISSUE]])-Table113456[[#This Row],[DIESEL ISSUE]] -> 861.5 | T7: 8 | U7: 12 | V7: ='PowerHouse Data'!$H$14 -> 5184
A8: 46208 | B8: 0.29166667 | C8: =D7 -> 1750 | D8: ='PowerHouse Data'!$I$2 -> 1750 | E8: =VLOOKUP(C8,$T$3:$U$1366,2,FALSE) -> 31183.5 | F8: ='PowerHouse Data'!$I$12 -> 0 | G8: =Table113456[[#This Row],[Main Tank Opening Stock (Liters)]]-Table113456[[#This Row],[Main Tank Closing Stock (Liters)]]+Table113456[[#This Row],[Received (Liters)]] -> 0 | H8: =VLOOKUP(D8,$T$3:$U$1366,2,FALSE) -> 31183.5 | I8: =Table113456[[#This Row],[Main Tank Closing Stock (Liters)]]+V8 -> 36357.5 | J8: =Table113456[[#This Row],[DG Milling Run Hr Meter]]-K7 -> 0 | K8: ='PowerHouse Data'!$I$8 -> 5642.3 | L8: =Table113456[[#This Row],[DG Parboiling Run Hr Meter]]-M7 -> 0 | M8: ='PowerHouse Data'!$I$9 -> 12501.1 | N8: 5824 | O8: =Table113456[[#This Row],[DG Parboiling Run Hr Meter2]]-Table113456[[#This Row],[DG Milling Run Hr Meter]] -> 181.7 | P8: 12643.5 | Q8: =Table113456[[#This Row],[DG Parboiling Run Hr Meter4]]-Table113456[[#This Row],[DG Parboiling Run Hr Meter]] -> 142.4 | R8: ='PowerHouse Data'!$I$13 -> 10 | S8: =Table113456[[#This Row],[DIESEL ISSUE]]+Table113456[[#This Row],[Main Tank Consumption (Liters)]] -> 10 | T8: 10 | U8: 17 | V8: ='PowerHouse Data'!$I$14 -> 5174
A9: 46209 | B9: 0.29166667 | C9: =D8 -> 1750 | D9: ='PowerHouse Data'!$J$2 -> 1702 | E9: =VLOOKUP(C9,$T$3:$U$1366,2,FALSE) -> 31183.5 | F9: ='PowerHouse Data'!$J$12 -> 0 | G9: =Table113456[[#This Row],[Main Tank Opening Stock (Liters)]]-Table113456[[#This Row],[Main Tank Closing Stock (Liters)]]+Table113456[[#This Row],[Received (Liters)]] -> 994.5 | H9: =VLOOKUP(D9,$T$3:$U$1366,2,FALSE) -> 30189 | I9: =Table113456[[#This Row],[Main Tank Closing Stock (Liters)]]+V9 -> 35373 | J9: =Table113456[[#This Row],[DG Milling Run Hr Meter]]-K8 -> 2.7 | K9: ='PowerHouse Data'!$J$8 -> 5645 | L9: =Table113456[[#This Row],[DG Parboiling Run Hr Meter]]-M8 -> 2.7 | M9: ='PowerHouse Data'!$J$9 -> 12503.8 | N9: 5824 | O9: =Table113456[[#This Row],[DG Parboiling Run Hr Meter2]]-Table113456[[#This Row],[DG Milling Run Hr Meter]] -> 179 | P9: 12643.5 | Q9: =Table113456[[#This Row],[DG Parboiling Run Hr Meter4]]-Table113456[[#This Row],[DG Parboiling Run Hr Meter]] -> 139.7 | R9: ='PowerHouse Data'!$J$13 -> 200 | S9: =Table113456[[#This Row],[Main Tank Consumption (Liters)]]-Table113456[[#This Row],[DIESEL ISSUE]] -> 794.5 | T9: 12 | U9: 22 | V9: ='PowerHouse Data'!$J$14 -> 5184
A10: 46210 | B10: 0.29166667 | C10: =D9 -> 1702 | D10: ='PowerHouse Data'!$K$2 -> 1702 | E10: =VLOOKUP(C10,$T$3:$U$1366,2,FALSE) -> 30189 | F10: ='PowerHouse Data'!$IO$12 -> 0 | G10: =Table113456[[#This Row],[Main Tank Opening Stock (Liters)]]-Table113456[[#This Row],[Main Tank Closing Stock (Liters)]]+Table113456[[#This Row],[Received (Liters)]] -> 0 | H10: =VLOOKUP(D10,$T$3:$U$1366,2,FALSE) -> 30189 | I10: =Table113456[[#This Row],[Main Tank Closing Stock (Liters)]]+V10 -> 35373 | J10: =Table113456[[#This Row],[DG Milling Run Hr Meter]]-K9 -> 0 | K10: ='PowerHouse Data'!$K$8 -> 5645 | L10: =Table113456[[#This Row],[DG Parboiling Run Hr Meter]]-M9 -> 0 | M10: ='PowerHouse Data'!$K$9 -> 12503.8 | N10: 5824 | O10: =Table113456[[#This Row],[DG Parboiling Run Hr Meter2]]-Table113456[[#This Row],[DG Milling Run Hr Meter]] -> 179 | P10: 12643.5 | Q10: =Table113456[[#This Row],[DG Parboiling Run Hr Meter4]]-Table113456[[#This Row],[DG Parboiling Run Hr Meter]] -> 139.7 | R10: ='PowerHouse Data'!$K$13 -> 0 | S10: =Table113456[[#This Row],[DIESEL ISSUE]]+Table113456[[#This Row],[Main Tank Consumption (Liters)]] -> 0 | T10: 14 | U10: 28 | V10: ='PowerHouse Data'!$K$14 -> 5184
A11: 46211 | B11: 0.29166667 | C11: =D10 -> 1702 | D11: ='PowerHouse Data'!$L$2 -> 1702 | E11: =VLOOKUP(C11,$T$3:$U$1366,2,FALSE) -> 30189 | F11: ='PowerHouse Data'!$JO$12 -> 0 | G11: =Table113456[[#This Row],[Main Tank Opening Stock (Liters)]]-Table113456[[#This Row],[Main Tank Closing Stock (Liters)]]+Table113456[[#This Row],[Received (Liters)]] -> 0 | H11: =VLOOKUP(D11,$T$3:$U$1366,2,FALSE) -> 30189 | I11: =Table113456[[#This Row],[Main Tank Closing Stock (Liters)]]+V11 -> 35373 | J11: =Table113456[[#This Row],[DG Milling Run Hr Meter]]-K10 -> 0 | K11: ='PowerHouse Data'!$L$8 -> 5645 | L11: =Table113456[[#This Row],[DG Parboiling Run Hr Meter]]-M10 -> 0 | M11: ='PowerHouse Data'!$L$9 -> 12503.8 | N11: 5824 | O11: =Table113456[[#This Row],[DG Parboiling Run Hr Meter2]]-Table113456[[#This Row],[DG Milling Run Hr Meter]] -> 179 | P11: 12643.5 | Q11: =Table113456[[#This Row],[DG Parboiling Run Hr Meter4]]-Table113456[[#This Row],[DG Parboiling Run Hr Meter]] -> 139.7 | R11: ='PowerHouse Data'!$L$13 -> 0 | S11: =Table113456[[#This Row],[DIESEL ISSUE]]+Table113456[[#This Row],[Main Tank Consumption (Liters)]] -> 0 | T11: 16 | U11: 34 | V11: ='PowerHouse Data'!$L$14 -> 5184
A12: 46212 | B12: 0.29166667 | C12: =D11 -> 1702 | D12: ='PowerHouse Data'!$M$2 -> 1702 | E12: =VLOOKUP(C12,$T$3:$U$1366,2,FALSE) -> 30189 | F12: ='PowerHouse Data'!$M$12 -> 0 | G12: =Table113456[[#This Row],[Main Tank Opening Stock (Liters)]]-Table113456[[#This Row],[Main Tank Closing Stock (Liters)]]+Table113456[[#This Row],[Received (Liters)]] -> 0 | H12: =VLOOKUP(D12,$T$3:$U$1366,2,FALSE) -> 30189 | I12: =Table113456[[#This Row],[Main Tank Closing Stock (Liters)]]+V12 -> 35363 | J12: =Table113456[[#This Row],[DG Milling Run Hr Meter]]-K11 -> 0 | K12: ='PowerHouse Data'!$M$8 -> 5645 | L12: =Table113456[[#This Row],[DG Parboiling Run Hr Meter]]-M11 -> 0 | M12: ='PowerHouse Data'!$M$9 -> 12503.8 | N12: 5824 | O12: =Table113456[[#This Row],[DG Parboiling Run Hr Meter2]]-Table113456[[#This Row],[DG Milling Run Hr Meter]] -> 179 | P12: 12643.5 | Q12: =Table113456[[#This Row],[DG Parboiling Run Hr Meter4]]-Table113456[[#This Row],[DG Parboiling Run Hr Meter]] -> 139.7 | R12: ='PowerHouse Data'!$M$13 -> 10 | S12: =Table113456[[#This Row],[DIESEL ISSUE]]+Table113456[[#This Row],[Main Tank Consumption (Liters)]] -> 10 | T12: 18 | U12: 41 | V12: ='PowerHouse Data'!$M$14 -> 5174
