Workbook

Sheet Summary
A1: Date | B1: Diesel Consumption (LTRS) | C1: Nepa Consumption (K.W.H) | D1: Comp E75 -1 Run Hours | E1: Comp E75 -2 Run Hours | F1: Comp E75 -3 Run Hours | G1: Comp E55 Run Hours | H1: Milling DG Run Hours | I1: Parboiling DG Run Hours | J1: Admin DG Run Hours | K1: Comp E75 -1 Rem Hours To Service | L1: Comp E75 -2 Rem Hours To Service | M1: Comp E75 -3 Rem Hours To Service | N1: Comp E55 Rem Hours To Service | O1: Milling DG Rem Hours To Service | P1: Parboiling DG Rem Hours To Service
A2: 46174 | B2: =Table113456[[#This Row],[Consumption (Liters)]] -> 3596 | C2: =Table1135[[#This Row],[NEPA Consumption (KWH)]] -> 5570 | D2: =Table113[[#This Row],[Comp E75 -1 Run Hours]] -> 0 | E2: =Table113[[#This Row],[Comp E75 -2 Run Hours]] -> 24 | F2: =Table113[[#This Row],[Comp E75 -3 Run Hours]] -> 23 | G2: =Table113[[#This Row],[Comp E55 Run Hours]] -> 0 | H2: =Table113456[[#This Row],[DG Milling Run Hours]] -> 12 | I2: =Table113456[[#This Row],[DG Parboiling Run Hours]] -> 12 | K2: =Table113[[#This Row],[Comp E75 -1 Rem Hours To Service]] -> 2079 | L2: =Table113[[#This Row],[Comp E75 -2 Rem Hours To Service]] -> 2060 | M2: =Table113[[#This Row],[Comp E75 -3 Rem Hours To Service]] -> 3828 | N2: =Table113[[#This Row],[Comp E55 Rem Hours To Service]] -> 1205 | O2: =Table113456[[#This Row],[Milling DG Rem Hours To Service]] -> 223.6 | P2: =Table113456[[#This Row],[Parboiling DG Rem Hours To Service]] -> 207.3
A3: 46175 | B3: =Table113456[[#This Row],[Consumption (Liters)]] -> 361 | C3: =Table1135[[#This Row],[NEPA Consumption (KWH)]] -> 10900 | D3: =Table113[[#This Row],[Comp E75 -1 Run Hours]] -> 0 | E3: =Table113[[#This Row],[Comp E75 -2 Run Hours]] -> 24 | F3: =Table113[[#This Row],[Comp E75 -3 Run Hours]] -> 24 | G3: =Table113[[#This Row],[Comp E55 Run Hours]] -> 0 | H3: =Table113456[[#This Row],[DG Milling Run Hours]] -> 1.7 | I3: =Table113456[[#This Row],[DG Parboiling Run Hours]] -> 1.7 | K3: =Table113[[#This Row],[Comp E75 -1 Rem Hours To Service]] -> 2079 | L3: =Table113[[#This Row],[Comp E75 -2 Rem Hours To Service]] -> 2036 | M3: =Table113[[#This Row],[Comp E75 -3 Rem Hours To Service]] -> 3804 | N3: =Table113[[#This Row],[Comp E55 Rem Hours To Service]] -> 1205 | O3: =Table113456[[#This Row],[Milling DG Rem Hours To Service]] -> 221.9 | P3: =Table113456[[#This Row],[Parboiling DG Rem Hours To Service]] -> 205.6
A4: 46176 | B4: =Table113456[[#This Row],[Consumption (Liters)]] -> 218 | C4: =Table1135[[#This Row],[NEPA Consumption (KWH)]] -> 9290 | D4: =Table113[[#This Row],[Comp E75 -1 Run Hours]] -> 22 | E4: =Table113[[#This Row],[Comp E75 -2 Run Hours]] -> 0 | F4: =Table113[[#This Row],[Comp E75 -3 Run Hours]] -> 18 | G4: =Table113[[#This Row],[Comp E55 Run Hours]] -> 0 | H4: =Table113456[[#This Row],[DG Milling Run Hours]] -> 1 | I4: =Table113456[[#This Row],[DG Parboiling Run Hours]] -> 1 | K4: =Table113[[#This Row],[Comp E75 -1 Rem Hours To Service]] -> 2057 | L4: =Table113[[#This Row],[Comp E75 -2 Rem Hours To Service]] -> 2036 | M4: =Table113[[#This Row],[Comp E75 -3 Rem Hours To Service]] -> 3786 | N4: =Table113[[#This Row],[Comp E55 Rem Hours To Service]] -> 1205 | O4: =Table113456[[#This Row],[Milling DG Rem Hours To Service]] -> 220.9 | P4: =Table113456[[#This Row],[Parboiling DG Rem Hours To Service]] -> 204.6
A5: 46177 | B5: =Table113456[[#This Row],[Consumption (Liters)]] -> 0 | C5: =Table1135[[#This Row],[NEPA Consumption (KWH)]] -> 11460 | D5: =Table113[[#This Row],[Comp E75 -1 Run Hours]] -> 23 | E5: =Table113[[#This Row],[Comp E75 -2 Run Hours]] -> 24 | F5: =Table113[[#This Row],[Comp E75 -3 Run Hours]] -> 0 | G5: =Table113[[#This Row],[Comp E55 Run Hours]] -> 0 | H5: =Table113456[[#This Row],[DG Milling Run Hours]] -> 0 | I5: =Table113456[[#This Row],[DG Parboiling Run Hours]] -> 0 | K5: =Table113[[#This Row],[Comp E75 -1 Rem Hours To Service]] -> 2034 | L5: =Table113[[#This Row],[Comp E75 -2 Rem Hours To Service]] -> 2012 | M5: =Table113[[#This Row],[Comp E75 -3 Rem Hours To Service]] -> 3786 | N5: =Table113[[#This Row],[Comp E55 Rem Hours To Service]] -> 1205 | O5: =Table113456[[#This Row],[Milling DG Rem Hours To Service]] -> 220.9 | P5: =Table113456[[#This Row],[Parboiling DG Rem Hours To Service]] -> 204.6
A6: 46178 | B6: =Table113456[[#This Row],[Consumption (Liters)]] -> 0 | C6: =Table1135[[#This Row],[NEPA Consumption (KWH)]] -> 11870 | D6: =Table113[[#This Row],[Comp E75 -1 Run Hours]] -> 0 | E6: =Table113[[#This Row],[Comp E75 -2 Run Hours]] -> 24 | F6: =Table113[[#This Row],[Comp E75 -3 Run Hours]] -> 24 | G6: =Table113[[#This Row],[Comp E55 Run Hours]] -> 0 | H6: =Table113456[[#This Row],[DG Milling Run Hours]] -> 0 | I6: =Table113456[[#This Row],[DG Parboiling Run Hours]] -> 0 | K6: =Table113[[#This Row],[Comp E75 -1 Rem Hours To Service]] -> 2034 | L6: =Table113[[#This Row],[Comp E75 -2 Rem Hours To Service]] -> 1988 | M6: =Table113[[#This Row],[Comp E75 -3 Rem Hours To Service]] -> 3762 | N6: =Table113[[#This Row],[Comp E55 Rem Hours To Service]] -> 1205 | O6: =Table113456[[#This Row],[Milling DG Rem Hours To Service]] -> 220.9 | P6: =Table113456[[#This Row],[Parboiling DG Rem Hours To Service]] -> 204.6
A7: 46179 | B7: =Table113456[[#This Row],[Consumption (Liters)]] -> 739 | C7: =Table1135[[#This Row],[NEPA Consumption (KWH)]] -> 10550 | D7: =Table113[[#This Row],[Comp E75 -1 Run Hours]] -> 23 | E7: =Table113[[#This Row],[Comp E75 -2 Run Hours]] -> 0 | F7: =Table113[[#This Row],[Comp E75 -3 Run Hours]] -> 23 | G7: =Table113[[#This Row],[Comp E55 Run Hours]] -> 0 | H7: =Table113456[[#This Row],[DG Milling Run Hours]] -> 2 | I7: =Table113456[[#This Row],[DG Parboiling Run Hours]] -> 2 | K7: =Table113[[#This Row],[Comp E75 -1 Rem Hours To Service]] -> 2011 | L7: =Table113[[#This Row],[Comp E75 -2 Rem Hours To Service]] -> 1988 | M7: =Table113[[#This Row],[Comp E75 -3 Rem Hours To Service]] -> 3739 | N7: =Table113[[#This Row],[Comp E55 Rem Hours To Service]] -> 1205 | O7: =Table113456[[#This Row],[Milling DG Rem Hours To Service]] -> 218.9 | P7: =Table113456[[#This Row],[Parboiling DG Rem Hours To Service]] -> 202.6
A8: 46180 | B8: =Table113456[[#This Row],[Consumption (Liters)]] -> 1211 | C8: =Table1135[[#This Row],[NEPA Consumption (KWH)]] -> 9340 | D8: =Table113[[#This Row],[Comp E75 -1 Run Hours]] -> 10 | E8: =Table113[[#This Row],[Comp E75 -2 Run Hours]] -> 23 | F8: =Table113[[#This Row],[Comp E75 -3 Run Hours]] -> 11 | G8: =Table113[[#This Row],[Comp E55 Run Hours]] -> 1 | H8: =Table113456[[#This Row],[DG Milling Run Hours]] -> 3.5 | I8: =Table113456[[#This Row],[DG Parboiling Run Hours]] -> 3.5 | K8: =Table113[[#This Row],[Comp E75 -1 Rem Hours To Service]] -> 2001 | L8: =Table113[[#This Row],[Comp E75 -2 Rem Hours To Service]] -> 1965 | M8: =Table113[[#This Row],[Comp E75 -3 Rem Hours To Service]] -> 3728 | N8: =Table113[[#This Row],[Comp E55 Rem Hours To Service]] -> 1204 | O8: =Table113456[[#This Row],[Milling DG Rem Hours To Service]] -> 215.4 | P8: =Table113456[[#This Row],[Parboiling DG Rem Hours To Service]] -> 199.1
A9: 46181 | B9: =Table113456[[#This Row],[Consumption (Liters)]] -> 541 | C9: =Table1135[[#This Row],[NEPA Consumption (KWH)]] -> 3610 | D9: =Table113[[#This Row],[Comp E75 -1 Run Hours]] -> 0 | E9: =Table113[[#This Row],[Comp E75 -2 Run Hours]] -> 0 | F9: =Table113[[#This Row],[Comp E75 -3 Run Hours]] -> 0 | G9: =Table113[[#This Row],[Comp E55 Run Hours]] -> 24 | H9: =Table113456[[#This Row],[DG Milling Run Hours]] -> 0 | I9: =Table113456[[#This Row],[DG Parboiling Run Hours]] -> 5.4 | K9: =Table113[[#This Row],[Comp E75 -1 Rem Hours To Service]] -> 2001 | L9: =Table113[[#This Row],[Comp E75 -2 Rem Hours To Service]] -> 1965 | M9: =Table113[[#This Row],[Comp E75 -3 Rem Hours To Service]] -> 3728 | N9: =Table113[[#This Row],[Comp E55 Rem Hours To Service]] -> 1180 | O9: =Table113456[[#This Row],[Milling DG Rem Hours To Service]] -> 215.4 | P9: =Table113456[[#This Row],[Parboiling DG Rem Hours To Service]] -> 193.7
A10: 46182 | B10: =Table113456[[#This Row],[Consumption (Liters)]] -> 389 | C10: =Table1135[[#This Row],[NEPA Consumption (KWH)]] -> 10420 | D10: =Table113[[#This Row],[Comp E75 -1 Run Hours]] -> 23 | E10: =Table113[[#This Row],[Comp E75 -2 Run Hours]] -> 24 | F10: =Table113[[#This Row],[Comp E75 -3 Run Hours]] -> 0 | G10: =Table113[[#This Row],[Comp E55 Run Hours]] -> 0 | H10: =Table113456[[#This Row],[DG Milling Run Hours]] -> 1.6 | I10: =Table113456[[#This Row],[DG Parboiling Run Hours]] -> 1.6 | K10: =Table113[[#This Row],[Comp E75 -1 Rem Hours To Service]] -> 1978 | L10: =Table113[[#This Row],[Comp E75 -2 Rem Hours To Service]] -> 1941 | M10: =Table113[[#This Row],[Comp E75 -3 Rem Hours To Service]] -> 3728 | N10: =Table113[[#This Row],[Comp E55 Rem Hours To Service]] -> 1180 | O10: =Table113456[[#This Row],[Milling DG Rem Hours To Service]] -> 213.8 | P10: =Table113456[[#This Row],[Parboiling DG Rem Hours To Service]] -> 192.1
A11: 46183 | B11: =Table113456[[#This Row],[Consumption (Liters)]] -> 0 | C11: =Table1135[[#This Row],[NEPA Consumption (KWH)]] -> 11830 | D11: =Table113[[#This Row],[Comp E75 -1 Run Hours]] -> 0 | E11: =Table113[[#This Row],[Comp E75 -2 Run Hours]] -> 23 | F11: =Table113[[#This Row],[Comp E75 -3 Run Hours]] -> 24 | G11: =Table113[[#This Row],[Comp E55 Run Hours]] -> 0 | H11: =Table113456[[#This Row],[DG Milling Run Hours]] -> 0 | I11: =Table113456[[#This Row],[DG Parboiling Run Hours]] -> 0 | K11: =Table113[[#This Row],[Comp E75 -1 Rem Hours To Service]] -> 1978 | L11: =Table113[[#This Row],[Comp E75 -2 Rem Hours To Service]] -> 1918 | M11: =Table113[[#This Row],[Comp E75 -3 Rem Hours To Service]] -> 3704 | N11: =Table113[[#This Row],[Comp E55 Rem Hours To Service]] -> 1180 | O11: =Table113456[[#This Row],[Milling DG Rem Hours To Service]] -> 213.8 | P11: =Table113456[[#This Row],[Parboiling DG Rem Hours To Service]] -> 192.1
A12: 46184 | B12: =Table113456[[#This Row],[Consumption (Liters)]] -> 1506 | C12: =Table1135[[#This Row],[NEPA Consumption (KWH)]] -> 8880 | D12: =Table113[[#This Row],[Comp E75 -1 Run Hours]] -> 23 | E12: =Table113[[#This Row],[Comp E75 -2 Run Hours]] -> 0 | F12: =Table113[[#This Row],[Comp E75 -3 Run Hours]] -> 24 | G12: =Table113[[#This Row],[Comp E55 Run Hours]] -> 0 | H12: =Table113456[[#This Row],[DG Milling Run Hours]] -> 0 | I12: =Table113456[[#This Row],[DG Parboiling Run Hours]] -> 11.4 | K12: =Table113[[#This Row],[Comp E75 -1 Rem Hours To Service]] -> 1955 | L12: =Table113[[#This Row],[Comp E75 -2 Rem Hours To Service]] -> 1918 | M12: =Table113[[#This Row],[Comp E75 -3 Rem Hours To Service]] -> 3680 | N12: =Table113[[#This Row],[Comp E55 Rem Hours To Service]] -> 1180 | O12: =Table113456[[#This Row],[Milling DG Rem Hours To Service]] -> 213.8 | P12: =Table113456[[#This Row],[Parboiling DG Rem Hours To Service]] -> 180.7
A13: 46185 | B13: =Table113456[[#This Row],[Consumption (Liters)]] -> 322 | C13: =Table1135[[#This Row],[NEPA Consumption (KWH)]] -> 11110 | D13: =Table113[[#This Row],[Comp E75 -1 Run Hours]] -> 23 | E13: =Table113[[#This Row],[Comp E75 -2 Run Hours]] -> 24 | F13: =Table113[[#This Row],[Comp E75 -3 Run Hours]] -> 0 | G13: =Table113[[#This Row],[Comp E55 Run Hours]] -> 0 | H13: =Table113456[[#This Row],[DG Milling Run Hours]] -> 0 | I13: =Table113456[[#This Row],[DG Parboiling Run Hours]] -> 4 | K13: =Table113[[#This Row],[Comp E75 -1 Rem Hours To Service]] -> 1932 | L13: =Table113[[#This Row],[Comp E75 -2 Rem Hours To Service]] -> 1894 | M13: =Table113[[#This Row],[Comp E75 -3 Rem Hours To Service]] -> 3680 | N13: =Table113[[#This Row],[Comp E55 Rem Hours To Service]] -> 1180 | O13: =Table113456[[#This Row],[Milling DG Rem Hours To Service]] -> 213.8 | P13: =Table113456[[#This Row],[Parboiling DG Rem Hours To Service]] -> 176.7
... A31: 46203 | B31: =Table113456[[#This Row],[Consumption (Liters)]] -> 37278 | C31: =Table1135[[#This Row],[NEPA Consumption (KWH)]] -> -24021430 | D31: =Table113[[#This Row],[Comp E75 -1 Run Hours]] -> -3665 | E31: =Table113[[#This Row],[Comp E75 -2 Run Hours]] -> -6383 | F31: =Table113[[#This Row],[Comp E75 -3 Run Hours]] -> -558 | G31: =Table113[[#This Row],[Comp E55 Run Hours]] -> -25807 | H31: =Table113456[[#This Row],[DG Milling Run Hours]] -> -5622.3 | I31: =Table113456[[#This Row],[DG Parboiling Run Hours]] -> -12479.3 | K31: =Table113[[#This Row],[Comp E75 -1 Rem Hours To Service]] -> 5440 | L31: =Table113[[#This Row],[Comp E75 -2 Rem Hours To Service]] -> 8066 | M31: =Table113[[#This Row],[Comp E75 -3 Rem Hours To Service]] -> 4000 | N31: =Table113[[#This Row],[Comp E55 Rem Hours To Service]] -> 26930 | O31: =Table113456[[#This Row],[Milling DG Rem Hours To Service]] -> 5824 | P31: =Table113456[[#This Row],[Parboiling DG Rem Hours To Service]] -> 12643.5
A33: Hours Rem | K33: =SMALL(Table11[Comp E75 -1 Rem Hours To Service],1) -> 1775 | L33: =SMALL(Table11[Comp E75 -2 Rem Hours To Service],1) -> 1683 | N33: =SMALL(Table11[Comp E55 Rem Hours To Service],1) -> 1123 | O33: =SMALL(Table11[Milling DG Rem Hours To Service],1) -> 201.7 | P33: =SMALL(Table11[Parboiling DG Rem Hours To Service],1) -> 164.2
A34: Days Rem | K34: =K33/24 -> 73.958333 | L34: =L33/24 -> 70.125 | N34: =N33/24 -> 46.791667
A36: NOTE: 12.06.2026 Receive desiel 50 X 230 = 11500 ltrs Befor Receive dip Reading 1836 = 32938 ltrs Calculation wise = 44438 ltrs After Receive dip Reading 2584 = 45065 ltrs differance getting extra = 627 ltrs on 18.06.2026 - 4414 Ltrs of Diesel lose due to inlet underground pipe damage

Sheet PowerHouse Data
B1: Date Equipments | C1: 46173 | D1: 46174 | E1: 46175 | F1: 46176 | G1: 46177 | H1: 46178 | I1: 46179 | J1: 46180 | K1: 46181 | L1: 46182 | M1: 46183 | N1: 46184 | O1: 46185 | P1: 46186 | Q1: 46187 | R1: 46188 | S1: 46189 | T1: 46190 | U1: 46191 | V1: 46192 | W1: 46193 | X1: 46194 | Y1: 46195 | Z1: 46196 | AA1: 46197 | AB1: 46198 | AC1: 46199 | AD1: 46200 | AE1: 46201 | AF1: 46202 | AG1: 46203 | AH1: 46204
B2: Diesel Dip reading (mm) | C2: 2328 | D2: 2112 | E2: 2092 | F2: 2080 | G2: 2080 | H2: 2080 | I2: 2040 | J2: 1976 | K2: 1948 | L2: 1928 | M2: 1928 | N2: 1852 | O2: 1836 | P2: 2536 | Q2: 2520 | R2: 2424 | S2: 2424 | T2: 2404 | U2: 2404 | V2: 2128 | W2: 2128 | X2: 2128 | Y2: 2096 | Z2: 2076 | AA2: 2076 | AB2: 2076 | AC2: 2076 | AD2: 2076 | AE2: 2060 | AF2: 2060
B3: Nepa meter reading (KWH) | C3: 23758960 | D3: 23764530 | E3: 23775430 | F3: 23784720 | G3: 23796180 | H3: 23808050 | I3: 23818600 | J3: 23827940 | K3: 23831550 | L3: 23841970 | M3: 23853800 | N3: 23862680 | O3: 23873790 | P3: 23884700 | Q3: 23893900 | R3: 23897100 | S3: 23906310 | T3: 23915980 | U3: 23928600 | V3: 23940000 | W3: 23951960 | X3: 23958020 | Y3: 23962110 | Z3: 23971780 | AA3: 23982860 | AB3: 23994370 | AC3: 24006320 | AD3: 24017590 | AE3: 24020930 | AF3: 24021430
B4: 1-Comp E75 reading (Hours) | C4: 3361 | D4: 3361 | E4: 3361 | F4: 3383 | G4: 3406 | H4: 3406 | I4: 3429 | J4: 3439 | K4: 3439 | L4: 3462 | M4: 3462 | N4: 3485 | O4: 3508 | P4: 3508 | Q4: 3526 | R4: 3530 | S4: 3530 | T4: 3553 | U4: 3577 | V4: 3577 | W4: 3600 | X4: 3600 | Y4: 3600 | Z4: 3621 | AA4: 3621 | AB4: 3641 | AC4: 3665 | AD4: 3665 | AE4: 3665 | AF4: 3665
B5: 2-Comp E75 reading (Hours) | C5: 5982 | D5: 6006 | E5: 6030 | F5: 6030 | G5: 6054 | H5: 6078 | I5: 6078 | J5: 6101 | K5: 6101 | L5: 6125 | M5: 6148 | N5: 6148 | O5: 6172 | P5: 6196 | Q5: 6196 | R5: 6206 | S5: 6229 | T5: 6229 | U5: 6253 | V5: 6276 | W5: 6276 | X5: 6287 | Y5: 6287 | Z5: 6311 | AA5: 6334 | AB5: 6334 | AC5: 6358 | AD5: 6382 | AE5: 6383 | AF5: 6383
B6: 3-Comp E75 reading (Hours) | C6: 149 | D6: 172 | E6: 196 | F6: 214 | G6: 214 | H6: 238 | I6: 261 | J6: 272 | K6: 272 | L6: 272 | M6: 296 | N6: 320 | O6: 320 | P6: 344 | Q6: 364 | R6: 367 | S6: 389 | T6: 413 | U6: 413 | V6: 437 | W6: 461 | X6: 473 | Y6: 473 | Z6: 473 | AA6: 497 | AB6: 521 | AC6: 521 | AD6: 545 | AE6: 558 | AF6: 558
B7: 4-Comp E55 reading (Hours) | C7: 25725 | D7: 25725 | E7: 25725 | F7: 25725 | G7: 25725 | H7: 25725 | I7: 25725 | J7: 25726 | K7: 25750 | L7: 25750 | M7: 25750 | N7: 25750 | O7: 25750 | P7: 25750 | Q7: 25750 | R7: 25760 | S7: 25762 | T7: 25762 | U7: 25762 | V7: 25762 | W7: 25762 | X7: 25773 | Y7: 25797 | Z7: 25797 | AA7: 25797 | AB7: 25797 | AC7: 25797 | AD7: 25797 | AE7: 25807 | AF7: 25807
B8: Milling DG reading (Hours) | C8: 5588.4 | D8: 5600.4 | E8: 5602.1 | F8: 5603.1 | G8: 5603.1 | H8: 5603.1 | I8: 5605.1 | J8: 5608.6 | K8: 5608.6 | L8: 5610.2 | M8: 5610.2 | N8: 5610.2 | O8: 5610.2 | P8: 5611.3 | Q8: 5611.9 | R8: 5617.2 | S8: 5617.2 | T8: 5618.9 | U8: 5618.9 | V8: 5619.8 | W8: 5619.8 | X8: 5621.3 | Y8: 5621.3 | Z8: 5622.3 | AA8: 5622.3 | AB8: 5622.3 | AC8: 5622.3 | AD8: 5622.3 | AE8: 5622.3 | AF8: 5622.3
B9: Parboiling DG reading (Hours) | C9: 12424.2 | D9: 12436.2 | E9: 12437.9 | F9: 12438.9 | G9: 12438.9 | H9: 12438.9 | I9: 12440.9 | J9: 12444.4 | K9: 12449.8 | L9: 12451.4 | M9: 12451.4 | N9: 12462.8 | O9: 12466.8 | P9: 12467.9 | Q9: 12468.5 | R9: 12475.5 | S9: 12475.5 | T9: 12475.5 | U9: 12475.5 | V9: 12476.4 | W9: 12476.4 | X9: 12477.9 | Y9: 12477.9 | Z9: 12478.9 | AA9: 12478.9 | AB9: 12478.9 | AC9: 12478.9 | AD9: 12478.9 | AE9: 12479.3 | AF9: 12479.3
B10: Diesel RECEIVED | C10: 0 | D10: 0 | E10: 0 | F10: 0 | G10: 0 | H10: 0 | I10: 0 | J10: 0 | K10: 0 | L10: 0 | M10: 0 | N10: 0 | O10: 0 | P10: 11500 | Q10: 0 | R10: 0 | S10: 0 | T10: 0 | U10: 0 | V10: 0 | W10: 0 | X10: 0 | Y10: 0 | Z10: 0 | AA10: 0 | AB10: 0 | AC10: 0 | AD10: 0 | AE10: 0 | AF10: 0 | AG10: 0 | AH10: 0
B11: Diesel Dip After Receive | C11: 0 | D11: 0 | E11: 0 | F11: 0 | G11: 0 | H11: 0 | I11: 0 | J11: 0 | K11: 0 | L11: 0 | M11: 0 | N11: 0 | O11: 0 | P11: 2584 | Q11: 0 | R11: 0 | S11: 0 | T11: 0 | U11: 0 | V11: 0 | W11: 0 | X11: 0 | Y11: 0 | Z11: 0 | AA11: 0 | AB11: 0 | AC11: 0 | AD11: 0 | AE11: 0 | AF11: 0 | AG11: 0 | AH11: 0
B12: Diesel flow meter reading | C12: 6185 | D12: 6185 | E12: 6185 | F12: 6185 | G12: 6185 | H12: 6185 | I12: 6185 | J12: 6185 | K12: 6185 | L12: 6185 | M12: 6185 | N12: 6185 | O12: 6185 | P12: 6185 | Q12: 6185 | R12: 6185 | S12: 6185 | T12: 6185 | U12: 6185 | V12: 6185 | W12: 6185 | X12: 6185 | Y12: 6185 | Z12: 6185 | AA12: 6185 | AB12: 6185 | AC12: 6185 | AD12: 6185 | AE12: 6185 | AF12: 6185 | AG12: 6185 | AH12: 6185
B13: MILLING | H13: 2968086 | I13: 2980067 | J13: 2990744 | K13: 2991037 | L13: 3003647 | M13: 3015954 | N13: 3027820 | O13: 3042532 | P13: 3054119 | Q13: 3062290 | R13: 3063882 | S13: 3076581 | T13: 3088580 | U13: 3104289 | V13: 3116116 | W13: 3128819 | X13: 3130932 | Y13: 3131047 | Z13: 3144692 | AA13: 3157101 | AB13: 3168687 | AC13: 3183038 | AD13: 3194853 | AE13: 3195519 | AF13: 3195743
B14: UTILITY / PARBOILING | H14: 180262 | I14: 185816 | J14: 190653 | K14: 195064 | L14: 199949 | M14: 206631 | N14: 210087 | O14: 214368 | P14: 220490 | Q14: 226589 | R14: 229474 | S14: 232657 | T14: 236803 | U14: 242351 | V14: 248869 | W14: 255495 | X14: 261688 | Y14: 266727 | Z14: 269888 | AA14: 275668 | AB14: 282512 | AC14: 288044 | AD14: 294440 | AE14: 297997 | AF14: 298346
B15: DIESEL ISSUED | D15: 25 | E15: 25 | F15: 50 | G15: 40 | K15: 50 | M15: 25 | R15: 50 | S15: 15 | T15: 25 | V15: 60 | W15: 25 | Y15: 50 | Z15: 25 | AB15: 50 | AC15: 25

Sheet Compressor
A1: Date | B1: Comp E75 -1 Run Hours | C1: Comp E75 -1 Run Hr | D1: Comp E75 -1 Rem Hours To Service | E1: Comp E75 -2 Run Hours | F1: Comp E75 -2 Run Hr | G1: Comp E75 -2 Rem Hours To Service | H1: Comp E75 -3 Run Hours | I1: Comp E75 -3 Run Hr | J1: Comp E75 -3 Rem Hours To Service | K1: Comp E55 Run Hours | L1: Comp E55 Run Hr | M1: Comp E55 Rem Hours To Service | N1: Comp E75 -1 Next Ser Hours | O1: Comp E75 -2 Next Ser Hours | P1: Comp E75 -3 Next Ser Hours | Q1: Comp E55 Next Ser Hours
A2: 46174 | B2: ='PowerHouse Data'!D4-'PowerHouse Data'!C4 -> 0 | C2: ='PowerHouse Data'!$D$4 -> 3361 | D2: =$N$2-Table113[[#This Row],[Comp E75 -1 Run Hr]] -> 2079 | E2: ='PowerHouse Data'!D5-'PowerHouse Data'!C5 -> 24 | F2: ='PowerHouse Data'!$D$5 -> 6006 | G2: =$O$2-Table113[[#This Row],[Comp E75 -2 Run Hr]] -> 2060 | H2: ='PowerHouse Data'!D6-'PowerHouse Data'!C6 -> 23 | I2: ='PowerHouse Data'!$D$6 -> 172 | J2: =$P$2-Table113[[#This Row],[Comp E75 -3 Run Hr]] -> 3828 | K2: ='PowerHouse Data'!D7-'PowerHouse Data'!C7 -> 0 | L2: ='PowerHouse Data'!$D$7 -> 25725 | M2: =$Q$2-Table113[[#This Row],[Comp E55 Run Hr]] -> 1205 | N2: 5440 | O2: 8066 | P2: 4000 | Q2: 26930
A3: 46175 | B3: =Table113[[#This Row],[Comp E75 -1 Run Hr]]-C2 -> 0 | C3: ='PowerHouse Data'!$E$4 -> 3361 | D3: =$N$2-Table113[[#This Row],[Comp E75 -1 Run Hr]] -> 2079 | E3: =Table113[[#This Row],[Comp E75 -2 Run Hr]]-F2 -> 24 | F3: ='PowerHouse Data'!$E$5 -> 6030 | G3: =$O$2-Table113[[#This Row],[Comp E75 -2 Run Hr]] -> 2036 | H3: =Table113[[#This Row],[Comp E75 -3 Run Hr]]-I2 -> 24 | I3: ='PowerHouse Data'!$E$6 -> 196 | J3: =$P$2-Table113[[#This Row],[Comp E75 -3 Run Hr]] -> 3804 | K3: =Table113[[#This Row],[Comp E55 Run Hr]]-L2 -> 0 | L3: ='PowerHouse Data'!$E$7 -> 25725 | M3: =$Q$2-Table113[[#This Row],[Comp E55 Run Hr]] -> 1205
A4: 46176 | B4: =Table113[[#This Row],[Comp E75 -1 Run Hr]]-C3 -> 22 | C4: ='PowerHouse Data'!$F$4 -> 3383 | D4: =$N$2-Table113[[#This Row],[Comp E75 -1 Run Hr]] -> 2057 | E4: =Table113[[#This Row],[Comp E75 -2 Run Hr]]-F3 -> 0 | F4: ='PowerHouse Data'!$F$5 -> 6030 | G4: =$O$2-Table113[[#This Row],[Comp E75 -2 Run Hr]] -> 2036 | H4: =Table113[[#This Row],[Comp E75 -3 Run Hr]]-I3 -> 18 | I4: ='PowerHouse Data'!$F$6 -> 214 | J4: =$P$2-Table113[[#This Row],[Comp E75 -3 Run Hr]] -> 3786 | K4: =Table113[[#This Row],[Comp E55 Run Hr]]-L3 -> 0 | L4: ='PowerHouse Data'!$F$7 -> 25725 | M4: =$Q$2-Table113[[#This Row],[Comp E55 Run Hr]] -> 1205
A5: 46177 | B5: =Table113[[#This Row],[Comp E75 -1 Run Hr]]-C4 -> 23 | C5: ='PowerHouse Data'!$G$4 -> 3406 | D5: =$N$2-Table113[[#This Row],[Comp E75 -1 Run Hr]] -> 2034 | E5: =Table113[[#This Row],[Comp E75 -2 Run Hr]]-F4 -> 24 | F5: ='PowerHouse Data'!$G$5 -> 6054 | G5: =$O$2-Table113[[#This Row],[Comp E75 -2 Run Hr]] -> 2012 | H5: =Table113[[#This Row],[Comp E75 -3 Run Hr]]-I4 -> 0 | I5: ='PowerHouse Data'!$G$6 -> 214 | J5: =$P$2-Table113[[#This Row],[Comp E75 -3 Run Hr]] -> 3786 | K5: =Table113[[#This Row],[Comp E55 Run Hr]]-L4 -> 0 | L5: ='PowerHouse Data'!$G$7 -> 25725 | M5: =$Q$2-Table113[[#This Row],[Comp E55 Run Hr]] -> 1205
A6: 46179 | B6: =Table113[[#This Row],[Comp E75 -1 Run Hr]]-C5 -> 0 | C6: ='PowerHouse Data'!$H$4 -> 3406 | D6: =$N$2-Table113[[#This Row],[Comp E75 -1 Run Hr]] -> 2034 | E6: =Table113[[#This Row],[Comp E75 -2 Run Hr]]-F5 -> 24 | F6: ='PowerHouse Data'!$H$5 -> 6078 | G6: =$O$2-Table113[[#This Row],[Comp E75 -2 Run Hr]] -> 1988 | H6: =Table113[[#This Row],[Comp E75 -3 Run Hr]]-I5 -> 24 | I6: ='PowerHouse Data'!$H$6 -> 238 | J6: =$P$2-Table113[[#This Row],[Comp E75 -3 Run Hr]] -> 3762 | K6: =Table113[[#This Row],[Comp E55 Run Hr]]-L5 -> 0 | L6: ='PowerHouse Data'!$H$7 -> 25725 | M6: =$Q$2-Table113[[#This Row],[Comp E55 Run Hr]] -> 1205
A7: 46179 | B7: =Table113[[#This Row],[Comp E75 -1 Run Hr]]-C6 -> 23 | C7: ='PowerHouse Data'!$I$4 -> 3429 | D7: =$N$2-Table113[[#This Row],[Comp E75 -1 Run Hr]] -> 2011 | E7: =Table113[[#This Row],[Comp E75 -2 Run Hr]]-F6 -> 0 | F7: ='PowerHouse Data'!$I$5 -> 6078 | G7: =$O$2-Table113[[#This Row],[Comp E75 -2 Run Hr]] -> 1988 | H7: =Table113[[#This Row],[Comp E75 -3 Run Hr]]-I6 -> 23 | I7: ='PowerHouse Data'!$I$6 -> 261 | J7: =$P$2-Table113[[#This Row],[Comp E75 -3 Run Hr]] -> 3739 | K7: =Table113[[#This Row],[Comp E55 Run Hr]]-L6 -> 0 | L7: ='PowerHouse Data'!$I$7 -> 25725 | M7: =$Q$2-Table113[[#This Row],[Comp E55 Run Hr]] -> 1205
A8: 46180 | B8: =Table113[[#This Row],[Comp E75 -1 Run Hr]]-C7 -> 10 | C8: ='PowerHouse Data'!$J$4 -> 3439 | D8: =$N$2-Table113[[#This Row],[Comp E75 -1 Run Hr]] -> 2001 | E8: =Table113[[#This Row],[Comp E75 -2 Run Hr]]-F7 -> 23 | F8: ='PowerHouse Data'!$J$5 -> 6101 | G8: =$O$2-Table113[[#This Row],[Comp E75 -2 Run Hr]] -> 1965 | H8: =Table113[[#This Row],[Comp E75 -3 Run Hr]]-I7 -> 11 | I8: ='PowerHouse Data'!$J$6 -> 272 | J8: =$P$2-Table113[[#This Row],[Comp E75 -3 Run Hr]] -> 3728 | K8: =Table113[[#This Row],[Comp E55 Run Hr]]-L7 -> 1 | L8: ='PowerHouse Data'!$J$7 -> 25726 | M8: =$Q$2-Table113[[#This Row],[Comp E55 Run Hr]] -> 1204
A9: 46181 | B9: =Table113[[#This Row],[Comp E75 -1 Run Hr]]-C8 -> 0 | C9: ='PowerHouse Data'!$K$4 -> 3439 | D9: =$N$2-Table113[[#This Row],[Comp E75 -1 Run Hr]] -> 2001 | E9: =Table113[[#This Row],[Comp E75 -2 Run Hr]]-F8 -> 0 | F9: ='PowerHouse Data'!$K$5 -> 6101 | G9: =$O$2-Table113[[#This Row],[Comp E75 -2 Run Hr]] -> 1965 | H9: =Table113[[#This Row],[Comp E75 -3 Run Hr]]-I8 -> 0 | I9: ='PowerHouse Data'!$K$6 -> 272 | J9: =$P$2-Table113[[#This Row],[Comp E75 -3 Run Hr]] -> 3728 | K9: =Table113[[#This Row],[Comp E55 Run Hr]]-L8 -> 24 | L9: ='PowerHouse Data'!$K$7 -> 25750 | M9: =$Q$2-Table113[[#This Row],[Comp E55 Run Hr]] -> 1180
A10: 46182 | B10: =Table113[[#This Row],[Comp E75 -1 Run Hr]]-C9 -> 23 | C10: ='PowerHouse Data'!$L$4 -> 3462 | D10: =$N$2-Table113[[#This Row],[Comp E75 -1 Run Hr]] -> 1978 | E10: =Table113[[#This Row],[Comp E75 -2 Run Hr]]-F9 -> 24 | F10: ='PowerHouse Data'!$L$5 -> 6125 | G10: =$O$2-Table113[[#This Row],[Comp E75 -2 Run Hr]] -> 1941 | H10: =Table113[[#This Row],[Comp E75 -3 Run Hr]]-I9 -> 0 | I10: ='PowerHouse Data'!$L$6 -> 272 | J10: =$P$2-Table113[[#This Row],[Comp E75 -3 Run Hr]] -> 3728 | K10: =Table113[[#This Row],[Comp E55 Run Hr]]-L9 -> 0 | L10: ='PowerHouse Data'!$L$7 -> 25750 | M10: =$Q$2-Table113[[#This Row],[Comp E55 Run Hr]] -> 1180
A11: 46183 | B11: =Table113[[#This Row],[Comp E75 -1 Run Hr]]-C10 -> 0 | C11: ='PowerHouse Data'!$M$4 -> 3462 | D11: =$N$2-Table113[[#This Row],[Comp E75 -1 Run Hr]] -> 1978 | E11: =Table113[[#This Row],[Comp E75 -2 Run Hr]]-F10 -> 23 | F11: ='PowerHouse Data'!$M$5 -> 6148 | G11: =$O$2-Table113[[#This Row],[Comp E75 -2 Run Hr]] -> 1918 | H11: =Table113[[#This Row],[Comp E75 -3 Run Hr]]-I10 -> 24 | I11: ='PowerHouse Data'!$M$6 -> 296 | J11: =$P$2-Table113[[#This Row],[Comp E75 -3 Run Hr]] -> 3704 | K11: =Table113[[#This Row],[Comp E55 Run Hr]]-L10 -> 0 | L11: ='PowerHouse Data'!$M$7 -> 25750 | M11: =$Q$2-Table113[[#This Row],[Comp E55 Run Hr]] -> 1180
A12: 46184 | B12: =Table113[[#This Row],[Comp E75 -1 Run Hr]]-C11 -> 23 | C12: ='PowerHouse Data'!$N$4 -> 3485 | D12: =$N$2-Table113[[#This Row],[Comp E75 -1 Run Hr]] -> 1955 | E12: =Table113[[#This Row],[Comp E75 -2 Run Hr]]-F11 -> 0 | F12: ='PowerHouse Data'!$N$5 -> 6148 | G12: =$O$2-Table113[[#This Row],[Comp E75 -2 Run Hr]] -> 1918 | H12: =Table113[[#This Row],[Comp E75 -3 Run Hr]]-I11 -> 24 | I12: ='PowerHouse Data'!$N$6 -> 320 | J12: =$P$2-Table113[[#This Row],[Comp E75 -3 Run Hr]] -> 3680 | K12: =Table113[[#This Row],[Comp E55 Run Hr]]-L11 -> 0 | L12: ='PowerHouse Data'!$N$7 -> 25750 | M12: =$Q$2-Table113[[#This Row],[Comp E55 Run Hr]] -> 1180
A13: 46185 | B13: =Table113[[#This Row],[Comp E75 -1 Run Hr]]-C12 -> 23 | C13: ='PowerHouse Data'!$O$4 -> 3508 | D13: =$N$2-Table113[[#This Row],[Comp E75 -1 Run Hr]] -> 1932 | E13: =Table113[[#This Row],[Comp E75 -2 Run Hr]]-F12 -> 24 | F13: ='PowerHouse Data'!$O$5 -> 6172 | G13: =$O$2-Table113[[#This Row],[Comp E75 -2 Run Hr]] -> 1894 | H13: =Table113[[#This Row],[Comp E75 -3 Run Hr]]-I12 -> 0 | I13: ='PowerHouse Data'!$O$6 -> 320 | J13: =$P$2-Table113[[#This Row],[Comp E75 -3 Run Hr]] -> 3680 | K13: =Table113[[#This Row],[Comp E55 Run Hr]]-L12 -> 0 | L13: ='PowerHouse Data'!$O$7 -> 25750 | M13: =$Q$2-Table113[[#This Row],[Comp E55 Run Hr]] -> 1180
A14: 46186 | B14: =Table113[[#This Row],[Comp E75 -1 Run Hr]]-C13 -> 0 | C14: ='PowerHouse Data'!$P$4 -> 3508 | D14: =$N$2-Table113[[#This Row],[Comp E75 -1 Run Hr]] -> 1932 | E14: =Table113[[#This Row],[Comp E75 -2 Run Hr]]-F13 -> 24 | F14: ='PowerHouse Data'!$P$5 -> 6196 | G14: =$O$2-Table113[[#This Row],[Comp E75 -2 Run Hr]] -> 1870 | H14: =Table113[[#This Row],[Comp E75 -3 Run Hr]]-I13 -> 24 | I14: ='PowerHouse Data'!$P$6 -> 344 | J14: =$P$2-Table113[[#This Row],[Comp E75 -3 Run Hr]] -> 3656 | K14: =Table113[[#This Row],[Comp E55 Run Hr]]-L13 -> 0 | L14: ='PowerHouse Data'!$P$7 -> 25750 | M14: =$Q$2-Table113[[#This Row],[Comp E55 Run Hr]] -> 1180
A15: 46187 | B15: =Table113[[#This Row],[Comp E75 -1 Run Hr]]-C14 -> 18 | C15: ='PowerHouse Data'!$Q$4 -> 3526 | D15: =$N$2-Table113[[#This Row],[Comp E75 -1 Run Hr]] -> 1914 | E15: =Table113[[#This Row],[Comp E75 -2 Run Hr]]-F14 -> 0 | F15: ='PowerHouse Data'!$Q$5 -> 6196 | G15: =$O$2-Table113[[#This Row],[Comp E75 -2 Run Hr]] -> 1870 | H15: =Table113[[#This Row],[Comp E75 -3 Run Hr]]-I14 -> 20 | I15: ='PowerHouse Data'!$Q$6 -> 364 | J15: =$P$2-Table113[[#This Row],[Comp E75 -3 Run Hr]] -> 3636 | K15: =Table113[[#This Row],[Comp E55 Run Hr]]-L14 -> 0 | L15: ='PowerHouse Data'!$Q$7 -> 25750 | M15: =$Q$2-Table113[[#This Row],[Comp E55 Run Hr]] -> 1180
A16: 46188 | B16: =Table113[[#This Row],[Comp E75 -1 Run Hr]]-C15 -> 4 | C16: ='PowerHouse Data'!$R$4 -> 3530 | D16: =$N$2-Table113[[#This Row],[Comp E75 -1 Run Hr]] -> 1910 | E16: =Table113[[#This Row],[Comp E75 -2 Run Hr]]-F15 -> 10 | F16: ='PowerHouse Data'!$R$5 -> 6206 | G16: =$O$2-Table113[[#This Row],[Comp E75 -2 Run Hr]] -> 1860 | H16: =Table113[[#This Row],[Comp E75 -3 Run Hr]]-I15 -> 3 | I16: ='PowerHouse Data'!$R$6 -> 367 | J16: =$P$2-Table113[[#This Row],[Comp E75 -3 Run Hr]] -> 3633 | K16: =Table113[[#This Row],[Comp E55 Run Hr]]-L15 -> 10 | L16: ='PowerHouse Data'!$R$7 -> 25760 | M16: =$Q$2-Table113[[#This Row],[Comp E55 Run Hr]] -> 1170
A17: 46189 | B17: =Table113[[#This Row],[Comp E75 -1 Run Hr]]-C16 -> 0 | C17: ='PowerHouse Data'!$S$4 -> 3530 | D17: =$N$2-Table113[[#This Row],[Comp E75 -1 Run Hr]] -> 1910 | E17: =Table113[[#This Row],[Comp E75 -2 Run Hr]]-F16 -> 23 | F17: ='PowerHouse Data'!$S$5 -> 6229 | G17: =$O$2-Table113[[#This Row],[Comp E75 -2 Run Hr]] -> 1837 | H17: =Table113[[#This Row],[Comp E75 -3 Run Hr]]-I16 -> 22 | I17: ='PowerHouse Data'!$S$6 -> 389 | J17: =$P$2-Table113[[#This Row],[Comp E75 -3 Run Hr]] -> 3611 | K17: =Table113[[#This Row],[Comp E55 Run Hr]]-L16 -> 2 | L17: ='PowerHouse Data'!$S$7 -> 25762 | M17: =$Q$2-Table113[[#This Row],[Comp E55 Run Hr]] -> 1168
A18: 46190 | B18: =Table113[[#This Row],[Comp E75 -1 Run Hr]]-C17 -> 23 | C18: ='PowerHouse Data'!$T$4 -> 3553 | D18: =$N$2-Table113[[#This Row],[Comp E75 -1 Run Hr]] -> 1887 | E18: =Table113[[#This Row],[Comp E75 -2 Run Hr]]-F17 -> 0 | F18: ='PowerHouse Data'!$T$5 -> 6229 | G18: =$O$2-Table113[[#This Row],[Comp E75 -2 Run Hr]] -> 1837 | H18: =Table113[[#This Row],[Comp E75 -3 Run Hr]]-I17 -> 24 | I18: ='PowerHouse Data'!$T$6 -> 413 | J18: =$P$2-Table113[[#This Row],[Comp E75 -3 Run Hr]] -> 3587 | K18: =Table113[[#This Row],[Comp E55 Run Hr]]-L17 -> 0 | L18: ='PowerHouse Data'!$T$7 -> 25762 | M18: =$Q$2-Table113[[#This Row],[Comp E55 Run Hr]] -> 1168
A19: 46191 | B19: =Table113[[#This Row],[Comp E75 -1 Run Hr]]-C18 -> 24 | C19: ='PowerHouse Data'!$U$4 -> 3577 | D19: =$N$2-Table113[[#This Row],[Comp E75 -1 Run Hr]] -> 1863 | E19: =Table113[[#This Row],[Comp E75 -2 Run Hr]]-F18 -> 24 | F19: ='PowerHouse Data'!$U$5 -> 6253 | G19: =$O$2-Table113[[#This Row],[Comp E75 -2 Run Hr]] -> 1813 | H19: =Table113[[#This Row],[Comp E75 -3 Run Hr]]-I18 -> 0 | I19: ='PowerHouse Data'!$U$6 -> 413 | J19: =$P$2-Table113[[#This Row],[Comp E75 -3 Run Hr]] -> 3587 | K19: =Table113[[#This Row],[Comp E55 Run Hr]]-L18 -> 0 | L19: ='PowerHouse Data'!$U$7 -> 25762 | M19: =$Q$2-Table113[[#This Row],[Comp E55 Run Hr]] -> 1168
A20: 46192 | B20: =Table113[[#This Row],[Comp E75 -1 Run Hr]]-C19 -> 0 | C20: ='PowerHouse Data'!$V$4 -> 3577 | D20: =$N$2-Table113[[#This Row],[Comp E75 -1 Run Hr]] -> 1863 | E20: =Table113[[#This Row],[Comp E75 -2 Run Hr]]-F19 -> 23 | F20: ='PowerHouse Data'!$V$5 -> 6276 | G20: =$O$2-Table113[[#This Row],[Comp E75 -2 Run Hr]] -> 1790 | H20: =Table113[[#This Row],[Comp E75 -3 Run Hr]]-I19 -> 24 | I20: ='PowerHouse Data'!$V$6 -> 437 | J20: =$P$2-Table113[[#This Row],[Comp E75 -3 Run Hr]] -> 3563 | K20: =Table113[[#This Row],[Comp E55 Run Hr]]-L19 -> 0 | L20: ='PowerHouse Data'!$V$7 -> 25762 | M20: =$Q$2-Table113[[#This Row],[Comp E55 Run Hr]] -> 1168
A21: 46193 | B21: =Table113[[#This Row],[Comp E75 -1 Run Hr]]-C20 -> 23 | C21: ='PowerHouse Data'!$W$4 -> 3600 | D21: =$N$2-Table113[[#This Row],[Comp E75 -1 Run Hr]] -> 1840 | E21: =Table113[[#This Row],[Comp E75 -2 Run Hr]]-F20 -> 0 | F21: ='PowerHouse Data'!$W$5 -> 6276 | G21: =$O$2-Table113[[#This Row],[Comp E75 -2 Run Hr]] -> 1790 | H21: =Table113[[#This Row],[Comp E75 -3 Run Hr]]-I20 -> 24 | I21: ='PowerHouse Data'!$W$6 -> 461 | J21: =$P$2-Table113[[#This Row],[Comp E75 -3 Run Hr]] -> 3539 | K21: =Table113[[#This Row],[Comp E55 Run Hr]]-L20 -> 0 | L21: ='PowerHouse Data'!$W$7 -> 25762 | M21: =$Q$2-Table113[[#This Row],[Comp E55 Run Hr]] -> 1168
A22: 46194 | B22: =Table113[[#This Row],[Comp E75 -1 Run Hr]]-C21 -> 0 | C22: ='PowerHouse Data'!$X$4 -> 3600 | D22: =$N$2-Table113[[#This Row],[Comp E75 -1 Run Hr]] -> 1840 | E22: =Table113[[#This Row],[Comp E75 -2 Run Hr]]-F21 -> 11 | F22: ='PowerHouse Data'!$X$5 -> 6287 | G22: =$O$2-Table113[[#This Row],[Comp E75 -2 Run Hr]] -> 1779 | H22: =Table113[[#This Row],[Comp E75 -3 Run Hr]]-I21 -> 12 | I22: ='PowerHouse Data'!$X$6 -> 473 | J22: =$P$2-Table113[[#This Row],[Comp E75 -3 Run Hr]] -> 3527 | K22: =Table113[[#This Row],[Comp E55 Run Hr]]-L21 -> 11 | L22: ='PowerHouse Data'!$X$7 -> 25773 | M22: =$Q$2-Table113[[#This Row],[Comp E55 Run Hr]] -> 1157
A23: 46195 | B23: =Table113[[#This Row],[Comp E75 -1 Run Hr]]-C22 -> 0 | C23: ='PowerHouse Data'!$Y$4 -> 3600 | D23: =$N$2-Table113[[#This Row],[Comp E75 -1 Run Hr]] -> 1840 | E23: =Table113[[#This Row],[Comp E75 -2 Run Hr]]-F22 -> 0 | F23: ='PowerHouse Data'!$Y$5 -> 6287 | G23: =$O$2-Table113[[#This Row],[Comp E75 -2 Run Hr]] -> 1779 | H23: =Table113[[#This Row],[Comp E75 -3 Run Hr]]-I22 -> 0 | I23: ='PowerHouse Data'!$Y$6 -> 473 | J23: =$P$2-Table113[[#This Row],[Comp E75 -3 Run Hr]] -> 3527 | K23: =Table113[[#This Row],[Comp E55 Run Hr]]-L22 -> 24 | L23: ='PowerHouse Data'!$Y$7 -> 25797 | M23: =$Q$2-Table113[[#This Row],[Comp E55 Run Hr]] -> 1133
A24: 46196 | B24: =Table113[[#This Row],[Comp E75 -1 Run Hr]]-C23 -> 21 | C24: ='PowerHouse Data'!$Z$4 -> 3621 | D24: =$N$2-Table113[[#This Row],[Comp E75 -1 Run Hr]] -> 1819 | E24: =Table113[[#This Row],[Comp E75 -2 Run Hr]]-F23 -> 24 | F24: ='PowerHouse Data'!$Z$5 -> 6311 | G24: =$O$2-Table113[[#This Row],[Comp E75 -2 Run Hr]] -> 1755 | H24: =Table113[[#This Row],[Comp E75 -3 Run Hr]]-I23 -> 0 | I24: ='PowerHouse Data'!$Z$6 -> 473 | J24: =$P$2-Table113[[#This Row],[Comp E75 -3 Run Hr]] -> 3527 | K24: =Table113[[#This Row],[Comp E55 Run Hr]]-L23 -> 0 | L24: ='PowerHouse Data'!$Z$7 -> 25797 | M24: =$Q$2-Table113[[#This Row],[Comp E55 Run Hr]] -> 1133
A25: 46197 | B25: =Table113[[#This Row],[Comp E75 -1 Run Hr]]-C24 -> 0 | C25: ='PowerHouse Data'!$AA$4 -> 3621 | D25: =$N$2-Table113[[#This Row],[Comp E75 -1 Run Hr]] -> 1819 | E25: =Table113[[#This Row],[Comp E75 -2 Run Hr]]-F24 -> 23 | F25: ='PowerHouse Data'!$AA$5 -> 6334 | G25: =$O$2-Table113[[#This Row],[Comp E75 -2 Run Hr]] -> 1732 | H25: =Table113[[#This Row],[Comp E75 -3 Run Hr]]-I24 -> 24 | I25: ='PowerHouse Data'!$AA$6 -> 497 | J25: =$P$2-Table113[[#This Row],[Comp E75 -3 Run Hr]] -> 3503 | K25: =Table113[[#This Row],[Comp E55 Run Hr]]-L24 -> 0 | L25: ='PowerHouse Data'!$AA$7 -> 25797 | M25: =$Q$2-Table113[[#This Row],[Comp E55 Run Hr]] -> 1133
A26: 46198 | B26: =Table113[[#This Row],[Comp E75 -1 Run Hr]]-C25 -> 20 | C26: ='PowerHouse Data'!$AB$4 -> 3641 | D26: =$N$2-Table113[[#This Row],[Comp E75 -1 Run Hr]] -> 1799 | E26: =Table113[[#This Row],[Comp E75 -2 Run Hr]]-F25 -> 0 | F26: ='PowerHouse Data'!$AB$5 -> 6334 | G26: =$O$2-Table113[[#This Row],[Comp E75 -2 Run Hr]] -> 1732 | H26: =Table113[[#This Row],[Comp E75 -3 Run Hr]]-I25 -> 24 | I26: ='PowerHouse Data'!$AB$6 -> 521 | J26: =$P$2-Table113[[#This Row],[Comp E75 -3 Run Hr]] -> 3479 | K26: =Table113[[#This Row],[Comp E55 Run Hr]]-L25 -> 0 | L26: ='PowerHouse Data'!$AB$7 -> 25797 | M26: =$Q$2-Table113[[#This Row],[Comp E55 Run Hr]] -> 1133
A27: 46199 | B27: =Table113[[#This Row],[Comp E75 -1 Run Hr]]-C26 -> 24 | C27: ='PowerHouse Data'!$AC$4 -> 3665 | D27: =$N$2-Table113[[#This Row],[Comp E75 -1 Run Hr]] -> 1775 | E27: =Table113[[#This Row],[Comp E75 -2 Run Hr]]-F26 -> 24 | F27: ='PowerHouse Data'!$AC$5 -> 6358 | G27: =$O$2-Table113[[#This Row],[Comp E75 -2 Run Hr]] -> 1708 | H27: =Table113[[#This Row],[Comp E75 -3 Run Hr]]-I26 -> 0 | I27: ='PowerHouse Data'!$AC$6 -> 521 | J27: =$P$2-Table113[[#This Row],[Comp E75 -3 Run Hr]] -> 3479 | K27: =Table113[[#This Row],[Comp E55 Run Hr]]-L26 -> 0 | L27: ='PowerHouse Data'!$AC$7 -> 25797 | M27: =$Q$2-Table113[[#This Row],[Comp E55 Run Hr]] -> 1133
A28: 46200 | B28: =Table113[[#This Row],[Comp E75 -1 Run Hr]]-C27 -> 0 | C28: ='PowerHouse Data'!$AD$4 -> 3665 | D28: =$N$2-Table113[[#This Row],[Comp E75 -1 Run Hr]] -> 1775 | E28: =Table113[[#This Row],[Comp E75 -2 Run Hr]]-F27 -> 24 | F28: ='PowerHouse Data'!$AD$5 -> 6382 | G28: =$O$2-Table113[[#This Row],[Comp E75 -2 Run Hr]] -> 1684 | H28: =Table113[[#This Row],[Comp E75 -3 Run Hr]]-I27 -> 24 | I28: ='PowerHouse Data'!$AD$6 -> 545 | J28: =$P$2-Table113[[#This Row],[Comp E75 -3 Run Hr]] -> 3455 | K28: =Table113[[#This Row],[Comp E55 Run Hr]]-L27 -> 0 | L28: ='PowerHouse Data'!$AD$7 -> 25797 | M28: =$Q$2-Table113[[#This Row],[Comp E55 Run Hr]] -> 1133
A29: 46201 | B29: =Table113[[#This Row],[Comp E75 -1 Run Hr]]-C28 -> 0 | C29: ='PowerHouse Data'!$AE$4 -> 3665 | D29: =$N$2-Table113[[#This Row],[Comp E75 -1 Run Hr]] -> 1775 | E29: =Table113[[#This Row],[Comp E75 -2 Run Hr]]-F28 -> 1 | F29: ='PowerHouse Data'!$AE$5 -> 6383 | G29: =$O$2-Table113[[#This Row],[Comp E75 -2 Run Hr]] -> 1683 | H29: =Table113[[#This Row],[Comp E75 -3 Run Hr]]-I28 -> 13 | I29: ='PowerHouse Data'!$AE$6 -> 558 | J29: =$P$2-Table113[[#This Row],[Comp E75 -3 Run Hr]] -> 3442 | K29: =Table113[[#This Row],[Comp E55 Run Hr]]-L28 -> 10 | L29: ='PowerHouse Data'!$AE$7 -> 25807 | M29: =$Q$2-Table113[[#This Row],[Comp E55 Run Hr]] -> 1123
A30: 46202 | B30: =Table113[[#This Row],[Comp E75 -1 Run Hr]]-C29 -> 0 | C30: ='PowerHouse Data'!$AF$4 -> 3665 | D30: =$N$2-Table113[[#This Row],[Comp E75 -1 Run Hr]] -> 1775 | E30: =Table113[[#This Row],[Comp E75 -2 Run Hr]]-F29 -> 0 | F30: ='PowerHouse Data'!$AF$5 -> 6383 | G30: =$O$2-Table113[[#This Row],[Comp E75 -2 Run Hr]] -> 1683 | H30: =Table113[[#This Row],[Comp E75 -3 Run Hr]]-I29 -> 0 | I30: ='PowerHouse Data'!$AF$6 -> 558 | J30: =$P$2-Table113[[#This Row],[Comp E75 -3 Run Hr]] -> 3442 | K30: =Table113[[#This Row],[Comp E55 Run Hr]]-L29 -> 0 | L30: ='PowerHouse Data'!$AF$7 -> 25807 | M30: =$Q$2-Table113[[#This Row],[Comp E55 Run Hr]] -> 1123
A31: 46203 | B31: =Table113[[#This Row],[Comp E75 -1 Run Hr]]-C30 -> -3665 | C31: ='PowerHouse Data'!$AG$4 -> 0 | D31: =$N$2-Table113[[#This Row],[Comp E75 -1 Run Hr]] -> 5440 | E31: =Table113[[#This Row],[Comp E75 -2 Run Hr]]-F30 -> -6383 | F31: ='PowerHouse Data'!$AG$5 -> 0 | G31: =$O$2-Table113[[#This Row],[Comp E75 -2 Run Hr]] -> 8066 | H31: =Table113[[#This Row],[Comp E75 -3 Run Hr]]-I30 -> -558 | I31: ='PowerHouse Data'!$AG$6 -> 0 | J31: =$P$2-Table113[[#This Row],[Comp E75 -3 Run Hr]] -> 4000 | K31: =Table113[[#This Row],[Comp E55 Run Hr]]-L30 -> -25807 | L31: ='PowerHouse Data'!$AG$7 -> 0 | M31: =$Q$2-Table113[[#This Row],[Comp E55 Run Hr]] -> 26930
C32: ='PowerHouse Data'!$AH$4 -> 0 | D32: =$N$2-Table113[[#This Row],[Comp E75 -1 Run Hr]] -> 5440 | F32: ='PowerHouse Data'!$AH$5 -> 0 | G32: =$O$2-Table113[[#This Row],[Comp E75 -2 Run Hr]] -> 8066 | H32: =Table113[[#This Row],[Comp E75 -2 Run Hr]]-I31 -> 0 | I32: ='PowerHouse Data'!$AH$6 -> 0 | J32: =$O$2-Table113[[#This Row],[Comp E75 -2 Run Hr]] -> 8066 | L32: ='PowerHouse Data'!$AH$7 -> 0 | M32: =$Q$2-Table113[[#This Row],[Comp E55 Run Hr]] -> 26930

Sheet Diesel
A1: Date | B1: TIME | C1: Dip Stick Reading O/P Stock | D1: Dip Stick Reading C/L Stock | E1: Dip Stick Reading After receive Diesel | F1: Opening Stock (Liters) | G1: Received (Liters) | H1: After receive Diesel (Liters) | I1: Consumption (Liters) | J1: Closing Stock (Liters) | K1: Service Tank | L1: DG Milling Run Hours | M1: DG Milling Run Hr Meter | N1: DG Parboiling Run Hours | O1: DG Parboiling Run Hr Meter | P1: Milling DG Next Ser Hours | Q1: Milling DG Rem Hours To Service | R1: Parboiling DG Next Ser Hours | S1: Parboiling DG Rem Hours To Service | T1: REMARKS | V1: Dip / mm | W1: Volume / Litters
A2: 46174 | B2: 0.29166667 | C2: ='PowerHouse Data'!C2 -> 2328 | D2: ='PowerHouse Data'!$D$2 -> 2112 | E2: ='PowerHouse Data'!$D$11 -> 0 | F2: =VLOOKUP(C2,$V$2:$W$681,2,FALSE) -> 41821 | G2: ='PowerHouse Data'!$D$10 -> 0 | H2: =VLOOKUP(E2,$V$2:$W$681,2,FALSE) -> 0 | I2: =Table113456[[#This Row],[Opening Stock (Liters)]]-Table113456[[#This Row],[Closing Stock (Liters)]]+Table113456[[#This Row],[Received (Liters)]] -> 3596 | J2: =VLOOKUP(D2,$V$2:$W$681,2,FALSE) -> 38225 | K2: 5184 | L2: ='PowerHouse Data'!D8-'PowerHouse Data'!C8 -> 12 | M2: ='PowerHouse Data'!$D$8 -> 5600.4 | N2: ='PowerHouse Data'!D9-'PowerHouse Data'!C9 -> 12 | O2: ='PowerHouse Data'!$D$9 -> 12436.2 | P2: 5824 | Q2: =Table113456[[#This Row],[Milling DG Next Ser Hours]]-Table113456[[#This Row],[DG Milling Run Hr Meter]] -> 223.6 | R2: 12643.5 | S2: =Table113456[[#This Row],[Parboiling DG Next Ser Hours]]-Table113456[[#This Row],[DG Parboiling Run Hr Meter]] -> 207.3 | V2: 0 | W2: 0
A3: 46175 | B3: 0.29166667 | C3: =D2 -> 2112 | D3: ='PowerHouse Data'!$E$2 -> 2092 | E3: ='PowerHouse Data'!$E$11 -> 0 | F3: =J2 -> 38225 | G3: ='PowerHouse Data'!$E$10 -> 0 | H3: =VLOOKUP(E3,$V$2:$W$681,2,FALSE) -> 0 | I3: =Table113456[[#This Row],[Opening Stock (Liters)]]-Table113456[[#This Row],[Closing Stock (Liters)]]+Table113456[[#This Row],[Received (Liters)]] -> 361 | J3: =VLOOKUP(D3,$V$2:$W$681,2,FALSE) -> 37864 | K3: 5184 | L3: =Table113456[[#This Row],[DG Milling Run Hr Meter]]-M2 -> 1.7 | M3: ='PowerHouse Data'!$E$8 -> 5602.1 | N3: =Table113456[[#This Row],[DG Parboiling Run Hr Meter]]-O2 -> 1.7 | O3: ='PowerHouse Data'!$E$9 -> 12437.9 | P3: 5824 | Q3: =Table113456[[#This Row],[Milling DG Next Ser Hours]]-Table113456[[#This Row],[DG Milling Run Hr Meter]] -> 221.9 | R3: 12643.5 | S3: =Table113456[[#This Row],[Parboiling DG Next Ser Hours]]-Table113456[[#This Row],[DG Parboiling Run Hr Meter]] -> 205.6 | V3: 4 | W3: 4
A4: 46176 | B4: 0.29166667 | C4: =D3 -> 2092 | D4: ='PowerHouse Data'!$F$2 -> 2080 | E4: ='PowerHouse Data'!$F$11 -> 0 | F4: =J3 -> 37864 | G4: ='PowerHouse Data'!$F$10 -> 0 | H4: =VLOOKUP(E4,$V$2:$W$681,2,FALSE) -> 0 | I4: =Table113456[[#This Row],[Opening Stock (Liters)]]-Table113456[[#This Row],[Closing Stock (Liters)]]+Table113456[[#This Row],[Received (Liters)]] -> 218 | J4: =VLOOKUP(D4,$V$2:$W$681,2,FALSE) -> 37646 | K4: 5184 | L4: =Table113456[[#This Row],[DG Milling Run Hr Meter]]-M3 -> 1 | M4: ='PowerHouse Data'!$F$8 -> 5603.1 | N4: =Table113456[[#This Row],[DG Parboiling Run Hr Meter]]-O3 -> 1 | O4: ='PowerHouse Data'!$F$9 -> 12438.9 | P4: 5824 | Q4: =Table113456[[#This Row],[Milling DG Next Ser Hours]]-Table113456[[#This Row],[DG Milling Run Hr Meter]] -> 220.9 | R4: 12643.5 | S4: =Table113456[[#This Row],[Parboiling DG Next Ser Hours]]-Table113456[[#This Row],[DG Parboiling Run Hr Meter]] -> 204.6 | V4: 8 | W4: 12
A5: 46177 | B5: 0.29166667 | C5: =D4 -> 2080 | D5: ='PowerHouse Data'!$G$2 -> 2080 | E5: ='PowerHouse Data'!$G$11 -> 0 | F5: =J4 -> 37646 | G5: ='PowerHouse Data'!$G$10 -> 0 | H5: =VLOOKUP(E5,$V$2:$W$681,2,FALSE) -> 0 | I5: =Table113456[[#This Row],[Opening Stock (Liters)]]-Table113456[[#This Row],[Closing Stock (Liters)]]+Table113456[[#This Row],[Received (Liters)]] -> 0 | J5: =VLOOKUP(D5,$V$2:$W$681,2,FALSE) -> 37646 | K5: 5184 | L5: =Table113456[[#This Row],[DG Milling Run Hr Meter]]-M4 -> 0 | M5: ='PowerHouse Data'!$G$8 -> 5603.1 | N5: =Table113456[[#This Row],[DG Parboiling Run Hr Meter]]-O4 -> 0 | O5: ='PowerHouse Data'!$G$9 -> 12438.9 | P5: 5824 | Q5: =Table113456[[#This Row],[Milling DG Next Ser Hours]]-Table113456[[#This Row],[DG Milling Run Hr Meter]] -> 220.9 | R5: 12643.5 | S5: =Table113456[[#This Row],[Parboiling DG Next Ser Hours]]-Table113456[[#This Row],[DG Parboiling Run Hr Meter]] -> 204.6 | V5: 12 | W5: 22
A6: 46179 | B6: 0.29166667 | C6: =D5 -> 2080 | D6: ='PowerHouse Data'!$H$2 -> 2080 | E6: ='PowerHouse Data'!$H$11 -> 0 | F6: =J5 -> 37646 | G6: ='PowerHouse Data'!$H$10 -> 0 | H6: =VLOOKUP(E6,$V$2:$W$681,2,FALSE) -> 0 | I6: =Table113456[[#This Row],[Opening Stock (Liters)]]-Table113456[[#This Row],[Closing Stock (Liters)]]+Table113456[[#This Row],[Received (Liters)]] -> 0 | J6: =VLOOKUP(D6,$V$2:$W$681,2,FALSE) -> 37646 | K6: 5184 | L6: =Table113456[[#This Row],[DG Milling Run Hr Meter]]-M5 -> 0 | M6: ='PowerHouse Data'!$H$8 -> 5603.1 | N6: =Table113456[[#This Row],[DG Parboiling Run Hr Meter]]-O5 -> 0 | O6: ='PowerHouse Data'!$H$9 -> 12438.9 | P6: 5824 | Q6: =Table113456[[#This Row],[Milling DG Next Ser Hours]]-Table113456[[#This Row],[DG Milling Run Hr Meter]] -> 220.9 | R6: 12643.5 | S6: =Table113456[[#This Row],[Parboiling DG Next Ser Hours]]-Table113456[[#This Row],[DG Parboiling Run Hr Meter]] -> 204.6 | V6: 16 | W6: 34
A7: 46179 | B7: 0.29166667 | C7: =D6 -> 2080 | D7: ='PowerHouse Data'!$I$2 -> 2040 | E7: ='PowerHouse Data'!$I$11 -> 0 | F7: =J6 -> 37646 | G7: ='PowerHouse Data'!$I$10 -> 0 | H7: =VLOOKUP(E7,$V$2:$W$681,2,FALSE) -> 0 | I7: =Table113456[[#This Row],[Opening Stock (Liters)]]-Table113456[[#This Row],[Closing Stock (Liters)]]+Table113456[[#This Row],[Received (Liters)]] -> 739 | J7: =VLOOKUP(D7,$V$2:$W$681,2,FALSE) -> 36907 | K7: 5184 | L7: =Table113456[[#This Row],[DG Milling Run Hr Meter]]-M6 -> 2 | M7: ='PowerHouse Data'!$I$8 -> 5605.1 | N7: =Table113456[[#This Row],[DG Parboiling Run Hr Meter]]-O6 -> 2 | O7: ='PowerHouse Data'!$I$9 -> 12440.9 | P7: 5824 | Q7: =Table113456[[#This Row],[Milling DG Next Ser Hours]]-Table113456[[#This Row],[DG Milling Run Hr Meter]] -> 218.9 | R7: 12643.5 | S7: =Table113456[[#This Row],[Parboiling DG Next Ser Hours]]-Table113456[[#This Row],[DG Parboiling Run Hr Meter]] -> 202.6 | V7: 20 | W7: 48
A8: 46180 | B8: 0.29166667 | C8: =D7 -> 2040 | D8: ='PowerHouse Data'!$J$2 -> 1976 | E8: ='PowerHouse Data'!$J$11 -> 0 | F8: =J7 -> 36907 | G8: ='PowerHouse Data'!$J$10 -> 0 | H8: =VLOOKUP(E8,$V$2:$W$681,2,FALSE) -> 0 | I8: =Table113456[[#This Row],[Opening Stock (Liters)]]-Table113456[[#This Row],[Closing Stock (Liters)]]+Table113456[[#This Row],[Received (Liters)]] -> 1211 | J8: =VLOOKUP(D8,$V$2:$W$681,2,FALSE) -> 35696 | K8: 5184 | L8: =Table113456[[#This Row],[DG Milling Run Hr Meter]]-M7 -> 3.5 | M8: ='PowerHouse Data'!$J$8 -> 5608.6 | N8: =Table113456[[#This Row],[DG Parboiling Run Hr Meter]]-O7 -> 3.5 | O8: ='PowerHouse Data'!$J$9 -> 12444.4 | P8: 5824 | Q8: =Table113456[[#This Row],[Milling DG Next Ser Hours]]-Table113456[[#This Row],[DG Milling Run Hr Meter]] -> 215.4 | R8: 12643.5 | S8: =Table113456[[#This Row],[Parboiling DG Next Ser Hours]]-Table113456[[#This Row],[DG Parboiling Run Hr Meter]] -> 199.1 | V8: 24 | W8: 63
A9: 46181 | B9: 0.29166667 | C9: =D8 -> 1976 | D9: ='PowerHouse Data'!$K$2 -> 1948 | E9: ='PowerHouse Data'!$K$11 -> 0 | F9: =J8 -> 35696 | G9: ='PowerHouse Data'!$IO$10 -> 0 | H9: =VLOOKUP(E9,$V$2:$W$681,2,FALSE) -> 0 | I9: =Table113456[[#This Row],[Opening Stock (Liters)]]-Table113456[[#This Row],[Closing Stock (Liters)]]+Table113456[[#This Row],[Received (Liters)]] -> 541 | J9: =VLOOKUP(D9,$V$2:$W$681,2,FALSE) -> 35155 | K9: 5184 | L9: =Table113456[[#This Row],[DG Milling Run Hr Meter]]-M8 -> 0 | M9: ='PowerHouse Data'!$K$8 -> 5608.6 | N9: =Table113456[[#This Row],[DG Parboiling Run Hr Meter]]-O8 -> 5.4 | O9: ='PowerHouse Data'!$K$9 -> 12449.8 | P9: 5824 | Q9: =Table113456[[#This Row],[Milling DG Next Ser Hours]]-Table113456[[#This Row],[DG Milling Run Hr Meter]] -> 215.4 | R9: 12643.5 | S9: =Table113456[[#This Row],[Parboiling DG Next Ser Hours]]-Table113456[[#This Row],[DG Parboiling Run Hr Meter]] -> 193.7 | V9: 28 | W9: 80
A10: 46182 | B10: 0.29166667 | C10: =D9 -> 1948 | D10: ='PowerHouse Data'!$L$2 -> 1928 | E10: ='PowerHouse Data'!$L$11 -> 0 | F10: =J9 -> 35155 | G10: ='PowerHouse Data'!$JO$10 -> 0 | H10: =VLOOKUP(E10,$V$2:$W$681,2,FALSE) -> 0 | I10: =Table113456[[#This Row],[Opening Stock (Liters)]]-Table113456[[#This Row],[Closing Stock (Liters)]]+Table113456[[#This Row],[Received (Liters)]] -> 389 | J10: =VLOOKUP(D10,$V$2:$W$681,2,FALSE) -> 34766 | K10: 5184 | L10: =Table113456[[#This Row],[DG Milling Run Hr Meter]]-M9 -> 1.6 | M10: ='PowerHouse Data'!$L$8 -> 5610.2 | N10: =Table113456[[#This Row],[DG Parboiling Run Hr Meter]]-O9 -> 1.6 | O10: ='PowerHouse Data'!$L$9 -> 12451.4 | P10: 5824 | Q10: =Table113456[[#This Row],[Milling DG Next Ser Hours]]-Table113456[[#This Row],[DG Milling Run Hr Meter]] -> 213.8 | R10: 12643.5 | S10: =Table113456[[#This Row],[Parboiling DG Next Ser Hours]]-Table113456[[#This Row],[DG Parboiling Run Hr Meter]] -> 192.1 | V10: 32 | W10: 98
A11: 46183 | B11: 0.29166667 | C11: =D10 -> 1928 | D11: ='PowerHouse Data'!$M$2 -> 1928 | E11: ='PowerHouse Data'!$M$11 -> 0 | F11: =J10 -> 34766 | G11: ='PowerHouse Data'!$M$10 -> 0 | H11: =VLOOKUP(E11,$V$2:$W$681,2,FALSE) -> 0 | I11: =Table113456[[#This Row],[Opening Stock (Liters)]]-Table113456[[#This Row],[Closing Stock (Liters)]]+Table113456[[#This Row],[Received (Liters)]] -> 0 | J11: =VLOOKUP(D11,$V$2:$W$681,2,FALSE) -> 34766 | K11: 5184 | L11: =Table113456[[#This Row],[DG Milling Run Hr Meter]]-M10 -> 0 | M11: ='PowerHouse Data'!$M$8 -> 5610.2 | N11: =Table113456[[#This Row],[DG Parboiling Run Hr Meter]]-O10 -> 0 | O11: ='PowerHouse Data'!$M$9 -> 12451.4 | P11: 5824 | Q11: =Table113456[[#This Row],[Milling DG Next Ser Hours]]-Table113456[[#This Row],[DG Milling Run Hr Meter]] -> 213.8 | R11: 12643.5 | S11: =Table113456[[#This Row],[Parboiling DG Next Ser Hours]]-Table113456[[#This Row],[DG Parboiling Run Hr Meter]] -> 192.1 | V11: 36 | W11: 116
A12: 46184 | B12: 0.29166667 | C12: =D11 -> 1928 | D12: ='PowerHouse Data'!$N$2 -> 1852 | E12: ='PowerHouse Data'!$N$11 -> 0 | F12: =J11 -> 34766 | G12: ='PowerHouse Data'!$N$10 -> 0 | H12: =VLOOKUP(E12,$V$2:$W$681,2,FALSE) -> 0 | I12: =Table113456[[#This Row],[Opening Stock (Liters)]]-Table113456[[#This Row],[Closing Stock (Liters)]]+Table113456[[#This Row],[Received (Liters)]] -> 1506 | J12: =VLOOKUP(D12,$V$2:$W$681,2,FALSE) -> 33260 | K12: 5184 | L12: =Table113456[[#This Row],[DG Milling Run Hr Meter]]-M11 -> 0 | M12: ='PowerHouse Data'!$N$8 -> 5610.2 | N12: =Table113456[[#This Row],[DG Parboiling Run Hr Meter]]-O11 -> 11.4 | O12: ='PowerHouse Data'!$N$9 -> 12462.8 | P12: 5824 | Q12: =Table113456[[#This Row],[Milling DG Next Ser Hours]]-Table113456[[#This Row],[DG Milling Run Hr Meter]] -> 213.8 | R12: 12643.5 | S12: =Table113456[[#This Row],[Parboiling DG Next Ser Hours]]-Table113456[[#This Row],[DG Parboiling Run Hr Meter]] -> 180.7 | V12: 40 | W12: 136
A13: 46185 | B13: 0.29166667 | C13: =D12 -> 1852 | D13: ='PowerHouse Data'!$O$2 -> 1836 | E13: ='PowerHouse Data'!$O$11 -> 0 | F13: =J12 -> 33260 | G13: ='PowerHouse Data'!$O$10 -> 0 | H13: =VLOOKUP(E13,$V$2:$W$681,2,FALSE) -> 0 | I13: =Table113456[[#This Row],[Opening Stock (Liters)]]-Table113456[[#This Row],[Closing Stock (Liters)]]+Table113456[[#This Row],[Received (Liters)]] -> 322 | J13: =VLOOKUP(D13,$V$2:$W$681,2,FALSE) -> 32938 | K13: 5184 | L13: =Table113456[[#This Row],[DG Milling Run Hr Meter]]-M12 -> 0 | M13: ='PowerHouse Data'!$O$8 -> 5610.2 | N13: =Table113456[[#This Row],[DG Parboiling Run Hr Meter]]-O12 -> 4 | O13: ='PowerHouse Data'!$O$9 -> 12466.8 | P13: 5824 | Q13: =Table113456[[#This Row],[Milling DG Next Ser Hours]]-Table113456[[#This Row],[DG Milling Run Hr Meter]] -> 213.8 | R13: 12643.5 | S13: =Table113456[[#This Row],[Parboiling DG Next Ser Hours]]-Table113456[[#This Row],[DG Parboiling Run Hr Meter]] -> 176.7 | V13: 44 | W13: 157
A14: 46186 | B14: 0.29166667 | C14: =D13 -> 1836 | D14: ='PowerHouse Data'!$P$2 -> 2536 | E14: ='PowerHouse Data'!$P$11 -> 2584 | F14: =J13 -> 32938 | G14: ='PowerHouse Data'!$P$10 -> 11500 | H14: =VLOOKUP(E14,$V$2:$W$681,2,FALSE) -> 45065 | I14: =Table113456[[#This Row],[Opening Stock (Liters)]]-Table113456[[#This Row],[Closing Stock (Liters)]]+Table113456[[#This Row],[Received (Liters)]]+627 -> 493 | J14: =VLOOKUP(D14,$V$2:$W$681,2,FALSE) -> 44572 | K14: 5184 | L14: =Table113456[[#This Row],[DG Milling Run Hr Meter]]-M13 -> 1.1 | M14: ='PowerHouse Data'!$P$8 -> 5611.3 | N14: =Table113456[[#This Row],[DG Parboiling Run Hr Meter]]-O13 -> 1.1 | O14: ='PowerHouse Data'!$P$9 -> 12467.9 | P14: 5824 | Q14: =Table113456[[#This Row],[Milling DG Next Ser Hours]]-Table113456[[#This Row],[DG Milling Run Hr Meter]] -> 212.7 | R14: 12643.5 | S14: =Table113456[[#This Row],[Parboiling DG Next Ser Hours]]-Table113456[[#This Row],[DG Parboiling Run Hr Meter]] -> 175.6 | V14: 48 | W14: 179
A15: 46187 | B15: 0.29166667 | C15: =D14 -> 2536 | D15: ='PowerHouse Data'!$Q$2 -> 2520 | E15: ='PowerHouse Data'!$Q$11 -> 0 | F15: =J14 -> 44572 | G15: ='PowerHouse Data'!$Q$10 -> 0 | H15: =VLOOKUP(E15,$V$2:$W$681,2,FALSE) -> 0 | I15: =Table113456[[#This Row],[Opening Stock (Liters)]]-Table113456[[#This Row],[Closing Stock (Liters)]]+Table113456[[#This Row],[Received (Liters)]] -> 178 | J15: =VLOOKUP(D15,$V$2:$W$681,2,FALSE) -> 44394 | K15: 5184 | L15: =Table113456[[#This Row],[DG Milling Run Hr Meter]]-M14 -> 0.6 | M15: ='PowerHouse Data'!$Q$8 -> 5611.9 | N15: =Table113456[[#This Row],[DG Parboiling Run Hr Meter]]-O14 -> 0.6 | O15: ='PowerHouse Data'!$Q$9 -> 12468.5 | P15: 5824 | Q15: =Table113456[[#This Row],[Milling DG Next Ser Hours]]-Table113456[[#This Row],[DG Milling Run Hr Meter]] -> 212.1 | R15: 12643.5 | S15: =Table113456[[#This Row],[Parboiling DG Next Ser Hours]]-Table113456[[#This Row],[DG Parboiling Run Hr Meter]] -> 175 | V15: 52 | W15: 202
A16: 46188 | B16: 0.29166667 | C16: =D15 -> 2520 | D16: ='PowerHouse Data'!$R$2 -> 2424 | E16: ='PowerHouse Data'!$R$11 -> 0 | F16: =J15 -> 44394 | G16: ='PowerHouse Data'!$R$10 -> 0 | H16: =VLOOKUP(E16,$V$2:$W$681,2,FALSE) -> 0 | I16: =Table113456[[#This Row],[Opening Stock (Liters)]]-Table113456[[#This Row],[Closing Stock (Liters)]]+Table113456[[#This Row],[Received (Liters)]] -> 1195 | J16: =VLOOKUP(D16,$V$2:$W$681,2,FALSE) -> 43199 | K16: 5184 | L16: =Table113456[[#This Row],[DG Milling Run Hr Meter]]-M15 -> 5.3 | M16: ='PowerHouse Data'!$R$8 -> 5617.2 | N16: =Table113456[[#This Row],[DG Parboiling Run Hr Meter]]-O15 -> 7 | O16: ='PowerHouse Data'!$R$9 -> 12475.5 | P16: 5824 | Q16: =Table113456[[#This Row],[Milling DG Next Ser Hours]]-Table113456[[#This Row],[DG Milling Run Hr Meter]] -> 206.8 | R16: 12643.5 | S16: =Table113456[[#This Row],[Parboiling DG Next Ser Hours]]-Table113456[[#This Row],[DG Parboiling Run Hr Meter]] -> 168 | V16: 56 | W16: 226
A17: 46189 | B17: 0.29166667 | C17: =D16 -> 2424 | D17: ='PowerHouse Data'!$S$2 -> 2424 | E17: ='PowerHouse Data'!$S$11 -> 0 | F17: =J16 -> 43199 | G17: ='PowerHouse Data'!$S$10 -> 0 | H17: =VLOOKUP(E17,$V$2:$W$681,2,FALSE) -> 0 | I17: =Table113456[[#This Row],[Opening Stock (Liters)]]-Table113456[[#This Row],[Closing Stock (Liters)]]+Table113456[[#This Row],[Received (Liters)]] -> 0 | J17: =VLOOKUP(D17,$V$2:$W$681,2,FALSE) -> 43199 | K17: 5184 | L17: =Table113456[[#This Row],[DG Milling Run Hr Meter]]-M16 -> 0 | M17: ='PowerHouse Data'!$S$8 -> 5617.2 | N17: =Table113456[[#This Row],[DG Parboiling Run Hr Meter]]-O16 -> 0 | O17: ='PowerHouse Data'!$S$9 -> 12475.5 | P17: 5824 | Q17: =Table113456[[#This Row],[Milling DG Next Ser Hours]]-Table113456[[#This Row],[DG Milling Run Hr Meter]] -> 206.8 | R17: 12643.5 | S17: =Table113456[[#This Row],[Parboiling DG Next Ser Hours]]-Table113456[[#This Row],[DG Parboiling Run Hr Meter]] -> 168 | V17: 60 | W17: 251
A18: 46190 | B18: 0.29166667 | C18: =D17 -> 2424 | D18: ='PowerHouse Data'!$T$2 -> 2404 | E18: ='PowerHouse Data'!$T$11 -> 0 | F18: =J17 -> 43199 | G18: ='PowerHouse Data'!$T$10 -> 0 | H18: =VLOOKUP(E18,$V$2:$W$681,2,FALSE) -> 0 | I18: =Table113456[[#This Row],[Opening Stock (Liters)]]-Table113456[[#This Row],[Closing Stock (Liters)]]+Table113456[[#This Row],[Received (Liters)]] -> 274 | J18: =VLOOKUP(D18,$V$2:$W$681,2,FALSE) -> 42925 | K18: 5184 | L18: =Table113456[[#This Row],[DG Milling Run Hr Meter]]-M17 -> 1.7 | M18: ='PowerHouse Data'!$T$8 -> 5618.9 | N18: =Table113456[[#This Row],[DG Parboiling Run Hr Meter]]-O17 -> 0 | O18: ='PowerHouse Data'!$T$9 -> 12475.5 | P18: 5824 | Q18: =Table113456[[#This Row],[Milling DG Next Ser Hours]]-Table113456[[#This Row],[DG Milling Run Hr Meter]] -> 205.1 | R18: 12643.5 | S18: =Table113456[[#This Row],[Parboiling DG Next Ser Hours]]-Table113456[[#This Row],[DG Parboiling Run Hr Meter]] -> 168 | V18: 64 | W18: 276
A19: 46191 | B19: 0.29166667 | C19: =D18 -> 2404 | D19: ='PowerHouse Data'!$U$2 -> 2404 | E19: ='PowerHouse Data'!$U$11 -> 0 | F19: =J18 -> 42925 | G19: ='PowerHouse Data'!$U$10 -> 0 | H19: =VLOOKUP(E19,$V$2:$W$681,2,FALSE) -> 0 | I19: =Table113456[[#This Row],[Opening Stock (Liters)]]-Table113456[[#This Row],[Closing Stock (Liters)]]+Table113456[[#This Row],[Received (Liters)]] -> 0 | J19: =VLOOKUP(D19,$V$2:$W$681,2,FALSE) -> 42925 | K19: 5184 | L19: =Table113456[[#This Row],[DG Milling Run Hr Meter]]-M18 -> 0 | M19: ='PowerHouse Data'!$U$8 -> 5618.9 | N19: =Table113456[[#This Row],[DG Parboiling Run Hr Meter]]-O18 -> 0 | O19: ='PowerHouse Data'!$U$9 -> 12475.5 | P19: 5824 | Q19: =Table113456[[#This Row],[Milling DG Next Ser Hours]]-Table113456[[#This Row],[DG Milling Run Hr Meter]] -> 205.1 | R19: 12643.5 | S19: =Table113456[[#This Row],[Parboiling DG Next Ser Hours]]-Table113456[[#This Row],[DG Parboiling Run Hr Meter]] -> 168 | V19: 68 | W19: 302
A20: 46192 | B20: 0.29166667 | C20: =D19 -> 2404 | D20: ='PowerHouse Data'!$V$2 -> 2128 | E20: ='PowerHouse Data'!$V$11 -> 0 | F20: =J19 -> 42925 | G20: ='PowerHouse Data'!$V$10 -> 0 | H20: =VLOOKUP(E20,$V$2:$W$681,2,FALSE) -> 0 | I20: =Table113456[[#This Row],[Opening Stock (Liters)]]-Table113456[[#This Row],[Closing Stock (Liters)]]+Table113456[[#This Row],[Received (Liters)]] -> 4414 | J20: =VLOOKUP(D20,$V$2:$W$681,2,FALSE) -> 38511 | K20: 5184 | L20: =Table113456[[#This Row],[DG Milling Run Hr Meter]]-M19 -> 0.9 | M20: ='PowerHouse Data'!$V$8 -> 5619.8 | N20: =Table113456[[#This Row],[DG Parboiling Run Hr Meter]]-O19 -> 0.9 | O20: ='PowerHouse Data'!$V$9 -> 12476.4 | P20: 5824 | Q20: =Table113456[[#This Row],[Milling DG Next Ser Hours]]-Table113456[[#This Row],[DG Milling Run Hr Meter]] -> 204.2 | R20: 12643.5 | S20: =Table113456[[#This Row],[Parboiling DG Next Ser Hours]]-Table113456[[#This Row],[DG Parboiling Run Hr Meter]] -> 167.1 | V20: 72 | W20: 329
A21: 46193 | B21: 0.29166667 | C21: =D20 -> 2128 | D21: ='PowerHouse Data'!$W$2 -> 2128 | E21: ='PowerHouse Data'!$W$11 -> 0 | F21: =J20 -> 38511 | G21: ='PowerHouse Data'!$W$10 -> 0 | H21: =VLOOKUP(E21,$V$2:$W$681,2,FALSE) -> 0 | I21: =Table113456[[#This Row],[Opening Stock (Liters)]]-Table113456[[#This Row],[Closing Stock (Liters)]]+Table113456[[#This Row],[Received (Liters)]] -> 0 | J21: =VLOOKUP(D21,$V$2:$W$681,2,FALSE) -> 38511 | K21: 5184 | L21: =Table113456[[#This Row],[DG Milling Run Hr Meter]]-M20 -> 0 | M21: ='PowerHouse Data'!$W$8 -> 5619.8 | N21: =Table113456[[#This Row],[DG Parboiling Run Hr Meter]]-O20 -> 0 | O21: ='PowerHouse Data'!$W$9 -> 12476.4 | P21: 5824 | Q21: =Table113456[[#This Row],[Milling DG Next Ser Hours]]-Table113456[[#This Row],[DG Milling Run Hr Meter]] -> 204.2 | R21: 12643.5 | S21: =Table113456[[#This Row],[Parboiling DG Next Ser Hours]]-Table113456[[#This Row],[DG Parboiling Run Hr Meter]] -> 167.1 | V21: 76 | W21: 357
