Workbook

Sheet PowerHouse Data
B1: Date Equipments | C1: 46265 | D1: 46266 | E1: 46267 | F1: 46268 | G1: 46269 | H1: 46270 | I1: 46271 | J1: 46272 | K1: 46273 | L1: 46274 | M1: 46275 | N1: 46276 | O1: 46277 | P1: 46278 | Q1: 46279 | R1: 46280 | S1: 46281 | T1: 46282 | U1: 46283 | V1: 46284 | W1: 46285 | X1: 46286 | Y1: 46287 | Z1: 46288 | AA1: 46289 | AB1: 46290 | AC1: 46291 | AD1: 46292 | AE1: 46293 | AF1: 46294 | AG1: 46295 | AH1: 46296
B2: Diesel Dip reading (mm) | C2: 2244 | D2: 2242 | E2: 2242 | F2: 2236 | G2: 2236 | H2: 2236 | I2: 2220 | J2: 2220 | K2: 2178 | L2: 2160 | M2: 2156 | N2: 2146 | O2: 2146 | P2: 2146 | Q2: 2146 | R2: 2146 | S2: 2126
B3: Diesel RECEIVED | C3: 0 | D3: 0 | E3: 0 | F3: 0 | G3: 0 | H3: 0 | I3: 0 | J3: 0 | K3: 0 | L3: 0 | M3: 0 | N3: 0 | O3: 0 | P3: 0 | Q3: 0 | R3: 0 | S3: 0
B4: Diesel ISSUED | C4: 0 | D4: 33 | E4: 0 | F4: 38 | G4: 0 | H4: 56 | I4: 10 | J4: 0 | K4: 712 | L4: 10 | M4: 28 | N4: 38 | O4: 0 | P4: 66 | Q4: 0 | R4: 10 | S4: 277
B5: Service Tanks | C5: 5184 | D5: 5184 | E5: 5184 | F5: 5184 | G5: 5184 | H5: =G5-H4 -> 5128 | I5: 5184 | J5: 5184 | K5: 5184 | L5: 5184 | M5: 5184 | N5: 5184 | O5: 5184 | P5: =O5-P4 -> 5118 | Q5: 5118 | R5: 5108 | S5: 5184
B6: Nepa meter reading (KWH) | C6: 24323210 | D6: 24324380 | E6: 24325660 | F6: 24326800 | G6: 24328160 | H6: 24329420 | I6: 24330310 | J6: 24331300 | K6: 24332540 | L6: 24333580 | M6: 24334800 | N6: 24335820 | O6: 24336970 | P6: 24338040 | Q6: 24339030 | R6: 24340100 | S6: 24340840
B7: MILLING (KWH) | C7: 3492166 | D7: 3492168 | E7: 3492168 | F7: 3492168 | G7: 3492168 | H7: 3492168 | I7: 3492168 | J7: 3492168 | K7: 3492168 | L7: 3492168 | M7: 3492168 | N7: 3492168 | O7: 3492168 | P7: 3492168 | Q7: 3492168 | R7: 3492168 | S7: 3492168
B8: UTILITY / PARBOILING (KWH) | C8: 482528 | D8: 483902 | E8: 485381 | F8: 486728 | G8: 488279 | H8: 489717 | I8: 490748 | J8: 491828 | K8: 493324 | L8: 494550 | M8: 495946 | N8: 497106 | O8: 498500 | P8: 499743 | Q8: 500939 | R8: 502219 | S8: 503113
B9: 1-Comp E75 reading (Hours) | C9: 4033 | D9: 4033 | E9: 4033 | F9: 4033 | G9: 4033 | H9: 4033 | I9: 4033 | J9: 4033 | K9: 4033 | L9: 4033 | M9: 4033 | N9: 4033 | O9: 4033 | P9: 4033 | Q9: 4033 | R9: 4033 | S9: 4033
B10: 2-Comp E75 reading (Hours) | C10: 6841 | D10: 6841 | E10: 6841 | F10: 6841 | G10: 6841 | H10: 6841 | I10: 6841 | J10: 6841 | K10: 6841 | L10: 6841 | M10: 6841 | N10: 6841 | O10: 6841 | P10: 6841 | Q10: 6841 | R10: 6841 | S10: 6841
B11: 3-Comp E75 reading (Hours) | C11: 972 | D11: 972 | E11: 972 | F11: 972 | G11: 972 | H11: 972 | I11: 972 | J11: 972 | K11: 972 | L11: 972 | M11: 972 | N11: 972 | O11: 972 | P11: 972 | Q11: 972 | R11: 972 | S11: 972
B12: 4-Comp E55 reading (Hours) | C12: 25941 | D12: 25941 | E12: 25941 | F12: 25941 | G12: 25941 | H12: 25941 | I12: 25941 | J12: 25941 | K12: 25941 | L12: 25941 | M12: 25941 | N12: 25941 | O12: 25941 | P12: 25941 | Q12: 25941 | R12: 25941 | S12: 25941
B13: Milling DG reading (Hours) | C13: 5687.4 | D13: 5687.4 | E13: 5687.4 | F13: 5688.7 | G13: 5688.7 | H13: 5688.7 | I13: 5693 | J13: 5693 | K13: 5693 | L13: 5698.7 | M13: 5699.6 | N13: 5702.5 | O13: 5702.5 | P13: 5702.5 | Q13: 5702.5 | R13: 5702.5 | S13: 5702.5
B14: Parboiling DG reading (Hours) | C14: 12538.2 | D14: 12538.2 | E14: 12538.2 | F14: 12538.2 | G14: 12538.2 | H14: 12538.2 | I14: 12538.2 | J14: 12538.2 | K14: 12538.2 | L14: 12538.2 | M14: 12538.2 | N14: 12538.2 | O14: 12538.2 | P14: 12538.2 | Q14: 12538.2 | R14: 12538.2 | S14: 12538.2
B15: Utility DG reading (Hours) | C15: 30943 | D15: 30944 | E15: 30944.7 | F15: 30944.7 | G15: 30944.7 | H15: 30944.7 | I15: 30944.7 | J15: 30944.7 | K15: 30944.7 | L15: 30944.7 | M15: 30945.4 | N15: 30946.2 | O15: 30948.5 | P15: 30949.8 | Q15: 30949.8 | R15: 30951.1 | S15: 30957
B16: Admin DG reading (Hours) | C16: 3501.8 | D16: 3502.8 | E16: 3502.8 | F16: 3502.8 | G16: 3502.8 | H16: 3502.8 | I16: 3504.2 | J16: 3504.2 | K16: 3504.2 | L16: 3504.2 | M16: 3504.2 | N16: 3504.2 | O16: 3504.2 | P16: 3504.2 | Q16: 3504.2 | R16: 3504.2 | S16: 3504.2
B17: NEPA Availablity | C17: 3501.8 | D17: 23.3 | E17: 23.3 | F17: 22.7 | G17: 24 | H17: 24 | I17: 18.3 | J17: 24 | K17: 24 | L17: 18.3 | M17: 22.4 | N17: 20.3 | O17: 21.7 | P17: 22.7 | Q17: 24 | R17: 22.7 | S17: 18

Sheet Summary
A1: Date | B1: Diesel Consumption (LTRS) | C1: Nepa Consumption (K.W.H) | D1: NEPA AVABILITY ( HH ) | E1: Comp E75 -1 Run Hours | F1: Comp E75 -2 Run Hours | G1: Comp E75 -3 Run Hours | H1: Comp E55 Run Hours | I1: Milling DG Run Hours | J1: Parboiling DG Run Hours | K1: Utility DG Run Hours | L1: Admin DG Run Hours | M1: Comp E75 -1 Rem Hours To Service | N1: Comp E75 -2 Rem Hours To Service | O1: Comp E75 -3 Rem Hours To Service | P1: Comp E55 Rem Hours To Service | Q1: Milling DG Rem Hours To Service | R1: Parboiling DG Rem Hours To Service | S1: Utility DG Rem Hours To Service | T1: Admin DG Rem Hours To Service | U1: Comp E75 -1 Next Ser Hours | V1: Comp E75 -2 Next Ser Hours | W1: Comp E75 -3 Next Ser Hours | X1: Comp E55 Next Ser Hours | Y1: Milling DG Next Ser Hours | Z1: Parboiling DG Next Ser Hours | AA1: Utility DG Next Ser Hours | AB1: Admin DG Next Ser Hours | AC1: Service tank (Liters) | AD1: Current Total stock (Liters)
A2: 46203 | B2: 0 | C2: 8630 | E2: 0 | F2: 24 | G2: 22 | H2: 0 | I2: 0 | J2: 0 | K2: 0 | L2: 0 | M2: 1452 | N2: 1245 | O2: 3052 | P2: 999 | Q2: 136.6 | R2: 105.3 | S2: =Table113456[[#This Row],[DG Utility REM SERVICE Hr]] -> 206 | T2: =Table113456[[#This Row],[DG Admin REM SERVICE Hr]] -> 38.2 | AD2: 44058
A3: ='PowerHouse Data'!$C$1 -> 46265 | B3: =Table113456[[#This Row],[Main Tank Consumption (Liters)]] -> 32.5 | C3: =Table1135[[#This Row],[NEPA Consumption (KWH)]] -> 1170 | E3: =Table113[[#This Row],[Comp E75 -1 Run Hours]] -> 0 | F3: =Table113[[#This Row],[Comp E75 -2 Run Hours]] -> 0 | G3: =Table113[[#This Row],[Comp E75 -3 Run Hours]] -> 0 | H3: =Table113[[#This Row],[Comp E55 Run Hours]] -> 0 | I3: =Table113456[[#This Row],[DG Milling Run Hours]] -> 0 | J3: =Table113456[[#This Row],[DG Parboiling Run Hours]] -> 0 | K3: =Table113456[[#This Row],[DG Utility Run Hours]] -> 1 | L3: =Table113456[[#This Row],[DG Admin Run Hours]] -> 1 | M3: =Table113[[#This Row],[Comp E75 -1 Rem Hours To Service]] -> 1407 | N3: =Table113[[#This Row],[Comp E75 -2 Rem Hours To Service]] -> 1225 | O3: =Table113[[#This Row],[Comp E75 -3 Rem Hours To Service]] -> 3028 | P3: =Table113[[#This Row],[Comp E55 Rem Hours To Service]] -> 989 | Q3: =$Y$3-Table113456[[#This Row],[DG Milling Run Hr Meter]] -> 136.6 | R3: =Table113456[[#This Row],[DG Parboil REM SERVICE Hr]] -> 105.3 | S3: =Table113456[[#This Row],[DG Utility REM SERVICE Hr]] -> 206 | T3: =Table113456[[#This Row],[DG Admin REM SERVICE Hr]] -> 37.2 | U3: 5440 | V3: 8066 | W3: 4000 | X3: 26930 | Y3: 5824 | Z3: 12643 | AA3: 31150 | AB3: 3540 | AC3: 5184 | AD3: =Diesel!I3 -> 45646.5
A4: ='PowerHouse Data'!$D$1 -> 46266 | B4: =Table113456[[#This Row],[Main Tank Consumption (Liters)]] -> 0 | C4: =Table1135[[#This Row],[NEPA Consumption (KWH)]] -> 1280 | D4: =Table1135[[#This Row],[NEPA Availablity]] -> 23.3 | E4: =Table113[[#This Row],[Comp E75 -1 Run Hours]] -> 0 | F4: =Table113[[#This Row],[Comp E75 -2 Run Hours]] -> 0 | G4: =Table113[[#This Row],[Comp E75 -3 Run Hours]] -> 0 | H4: =Table113[[#This Row],[Comp E55 Run Hours]] -> 0 | I4: =Table113456[[#This Row],[DG Milling Run Hours]] -> 0 | J4: =Table113456[[#This Row],[DG Parboiling Run Hours]] -> 0 | K4: =Table113456[[#This Row],[DG Utility Run Hours]] -> 0.7 | L4: =Table113456[[#This Row],[DG Admin Run Hours]] -> 0 | M4: =Table113[[#This Row],[Comp E75 -1 Rem Hours To Service]] -> 1407 | N4: =Table113[[#This Row],[Comp E75 -2 Rem Hours To Service]] -> 1225 | O4: =Table113[[#This Row],[Comp E75 -3 Rem Hours To Service]] -> 3028 | P4: =Table113[[#This Row],[Comp E55 Rem Hours To Service]] -> 989 | Q4: =$Y$3-Table113456[[#This Row],[DG Milling Run Hr Meter]] -> 136.6 | R4: =Table113456[[#This Row],[DG Parboil REM SERVICE Hr]] -> 105.3 | S4: =Table113456[[#This Row],[DG Utility REM SERVICE Hr]] -> 205.3 | T4: =Table113456[[#This Row],[DG Admin REM SERVICE Hr]] -> 37.2 | AC4: 5184 | AD4: =Diesel!I4 -> 45646.5
A5: ='PowerHouse Data'!$E$1 -> 46267 | B5: =Table113456[[#This Row],[Main Tank Consumption (Liters)]] -> 98.5 | C5: =Table1135[[#This Row],[NEPA Consumption (KWH)]] -> 1140 | D5: =Table1135[[#This Row],[NEPA Availablity]] -> 22.7 | E5: =Table113[[#This Row],[Comp E75 -1 Run Hours]] -> 0 | F5: =Table113[[#This Row],[Comp E75 -2 Run Hours]] -> 0 | G5: =Table113[[#This Row],[Comp E75 -3 Run Hours]] -> 0 | H5: =Table113[[#This Row],[Comp E55 Run Hours]] -> 0 | I5: =Table113456[[#This Row],[DG Milling Run Hours]] -> 1.3 | J5: =Table113456[[#This Row],[DG Parboiling Run Hours]] -> 0 | K5: =Table113456[[#This Row],[DG Utility Run Hours]] -> 0 | L5: =Table113456[[#This Row],[DG Admin Run Hours]] -> 0 | M5: =Table113[[#This Row],[Comp E75 -1 Rem Hours To Service]] -> 1407 | N5: =Table113[[#This Row],[Comp E75 -2 Rem Hours To Service]] -> 1225 | O5: =Table113[[#This Row],[Comp E75 -3 Rem Hours To Service]] -> 3028 | P5: =Table113[[#This Row],[Comp E55 Rem Hours To Service]] -> 989 | Q5: =$Y$3-Table113456[[#This Row],[DG Milling Run Hr Meter]] -> 135.3 | R5: =Table113456[[#This Row],[DG Parboil REM SERVICE Hr]] -> 105.3 | S5: =Table113456[[#This Row],[DG Utility REM SERVICE Hr]] -> 205.3 | T5: =Table113456[[#This Row],[DG Admin REM SERVICE Hr]] -> 37.2 | AD5: =Diesel!I5 -> 45548
A6: ='PowerHouse Data'!$F$1 -> 46268 | B6: =Table113456[[#This Row],[Main Tank Consumption (Liters)]] -> 0 | C6: =Table1135[[#This Row],[NEPA Consumption (KWH)]] -> 1360 | D6: =Table1135[[#This Row],[NEPA Availablity]] -> 24 | E6: =Table113[[#This Row],[Comp E75 -1 Run Hours]] -> 0 | F6: =Table113[[#This Row],[Comp E75 -2 Run Hours]] -> 0 | G6: =Table113[[#This Row],[Comp E75 -3 Run Hours]] -> 0 | H6: =Table113[[#This Row],[Comp E55 Run Hours]] -> 0 | I6: =Table113456[[#This Row],[DG Milling Run Hours]] -> 0 | J6: =Table113456[[#This Row],[DG Parboiling Run Hours]] -> 0 | K6: =Table113456[[#This Row],[DG Utility Run Hours]] -> 0 | L6: =Table113456[[#This Row],[DG Admin Run Hours]] -> 0 | M6: =Table113[[#This Row],[Comp E75 -1 Rem Hours To Service]] -> 1407 | N6: =Table113[[#This Row],[Comp E75 -2 Rem Hours To Service]] -> 1225 | O6: =Table113[[#This Row],[Comp E75 -3 Rem Hours To Service]] -> 3028 | P6: =Table113[[#This Row],[Comp E55 Rem Hours To Service]] -> 989 | Q6: =$Y$3-Table113456[[#This Row],[DG Milling Run Hr Meter]] -> 135.3 | R6: =Table113456[[#This Row],[DG Parboil REM SERVICE Hr]] -> 105.3 | S6: =Table113456[[#This Row],[DG Utility REM SERVICE Hr]] -> 205.3 | T6: =Table113456[[#This Row],[DG Admin REM SERVICE Hr]] -> 37.2 | AD6: =Diesel!I6 -> 45548
A7: ='PowerHouse Data'!$G$1 -> 46269 | B7: =Table113456[[#This Row],[Main Tank Consumption (Liters)]] -> 0 | C7: =Table1135[[#This Row],[NEPA Consumption (KWH)]] -> 1260 | D7: =Table1135[[#This Row],[NEPA Availablity]] -> 24 | E7: =Table113[[#This Row],[Comp E75 -1 Run Hours]] -> 0 | F7: =Table113[[#This Row],[Comp E75 -2 Run Hours]] -> 0 | G7: =Table113[[#This Row],[Comp E75 -3 Run Hours]] -> 0 | H7: =Table113[[#This Row],[Comp E55 Run Hours]] -> 0 | I7: =Table113456[[#This Row],[DG Milling Run Hours]] -> 0 | J7: =Table113456[[#This Row],[DG Parboiling Run Hours]] -> 0 | K7: =Table113456[[#This Row],[DG Utility Run Hours]] -> 0 | L7: =Table113456[[#This Row],[DG Admin Run Hours]] -> 0 | M7: =Table113[[#This Row],[Comp E75 -1 Rem Hours To Service]] -> 1407 | N7: =Table113[[#This Row],[Comp E75 -2 Rem Hours To Service]] -> 1225 | O7: =Table113[[#This Row],[Comp E75 -3 Rem Hours To Service]] -> 3028 | P7: =Table113[[#This Row],[Comp E55 Rem Hours To Service]] -> 989 | Q7: =$Y$3-Table113456[[#This Row],[DG Milling Run Hr Meter]] -> 135.3 | R7: =Table113456[[#This Row],[DG Parboil REM SERVICE Hr]] -> 105.3 | S7: =Table113456[[#This Row],[DG Utility REM SERVICE Hr]] -> 205.3 | T7: =Table113456[[#This Row],[DG Admin REM SERVICE Hr]] -> 37.2 | AD7: =Diesel!I7 -> 45492
A8: ='PowerHouse Data'!$H$1 -> 46270 | B8: =Table113456[[#This Row],[Main Tank Consumption (Liters)]] -> 266 | C8: =Table1135[[#This Row],[NEPA Consumption (KWH)]] -> 890 | D8: =Table1135[[#This Row],[NEPA Availablity]] -> 18.3 | E8: =Table113[[#This Row],[Comp E75 -1 Run Hours]] -> 0 | F8: =Table113[[#This Row],[Comp E75 -2 Run Hours]] -> 0 | G8: =Table113[[#This Row],[Comp E75 -3 Run Hours]] -> 0 | H8: =Table113[[#This Row],[Comp E55 Run Hours]] -> 0 | I8: =Table113456[[#This Row],[DG Milling Run Hours]] -> 4.3 | J8: =Table113456[[#This Row],[DG Parboiling Run Hours]] -> 0 | K8: =Table113456[[#This Row],[DG Utility Run Hours]] -> 0 | L8: =Table113456[[#This Row],[DG Admin Run Hours]] -> 1.4 | M8: =Table113[[#This Row],[Comp E75 -1 Rem Hours To Service]] -> 1407 | N8: =Table113[[#This Row],[Comp E75 -2 Rem Hours To Service]] -> 1225 | O8: =Table113[[#This Row],[Comp E75 -3 Rem Hours To Service]] -> 3028 | P8: =Table113[[#This Row],[Comp E55 Rem Hours To Service]] -> 989 | Q8: =$Y$3-Table113456[[#This Row],[DG Milling Run Hr Meter]] -> 131 | R8: =Table113456[[#This Row],[DG Parboil REM SERVICE Hr]] -> 105.3 | S8: =Table113456[[#This Row],[DG Utility REM SERVICE Hr]] -> 205.3 | T8: =Table113456[[#This Row],[DG Admin REM SERVICE Hr]] -> 35.8 | AD8: =Diesel!I8 -> 45282
A9: ='PowerHouse Data'!$I$1 -> 46271 | B9: =Table113456[[#This Row],[Main Tank Consumption (Liters)]] -> 0 | C9: =Table1135[[#This Row],[NEPA Consumption (KWH)]] -> 990 | D9: =Table1135[[#This Row],[NEPA Availablity]] -> 24 | E9: =Table113[[#This Row],[Comp E75 -1 Run Hours]] -> 0 | F9: =Table113[[#This Row],[Comp E75 -2 Run Hours]] -> 0 | G9: =Table113[[#This Row],[Comp E75 -3 Run Hours]] -> 0 | H9: =Table113[[#This Row],[Comp E55 Run Hours]] -> 0 | I9: =Table113456[[#This Row],[DG Milling Run Hours]] -> 0 | J9: =Table113456[[#This Row],[DG Parboiling Run Hours]] -> 0 | K9: =Table113456[[#This Row],[DG Utility Run Hours]] -> 0 | L9: =Table113456[[#This Row],[DG Admin Run Hours]] -> 0 | M9: =Table113[[#This Row],[Comp E75 -1 Rem Hours To Service]] -> 1407 | N9: =Table113[[#This Row],[Comp E75 -2 Rem Hours To Service]] -> 1225 | O9: =Table113[[#This Row],[Comp E75 -3 Rem Hours To Service]] -> 3028 | P9: =Table113[[#This Row],[Comp E55 Rem Hours To Service]] -> 989 | Q9: =$Y$3-Table113456[[#This Row],[DG Milling Run Hr Meter]] -> 131 | R9: =Table113456[[#This Row],[DG Parboil REM SERVICE Hr]] -> 105.3 | S9: =Table113456[[#This Row],[DG Utility REM SERVICE Hr]] -> 205.3 | T9: =Table113456[[#This Row],[DG Admin REM SERVICE Hr]] -> 35.8 | AD9: =Diesel!I9 -> 45282
A10: ='PowerHouse Data'!$J$1 -> 46272 | B10: =Table113456[[#This Row],[Main Tank Consumption (Liters)]] -> 712 | C10: =Table1135[[#This Row],[NEPA Consumption (KWH)]] -> 1240 | D10: =Table1135[[#This Row],[NEPA Availablity]] -> 24 | E10: =Table113[[#This Row],[Comp E75 -1 Run Hours]] -> 0 | F10: =Table113[[#This Row],[Comp E75 -2 Run Hours]] -> 0 | G10: =Table113[[#This Row],[Comp E75 -3 Run Hours]] -> 0 | H10: =Table113[[#This Row],[Comp E55 Run Hours]] -> 0 | I10: =Table113456[[#This Row],[DG Milling Run Hours]] -> 0 | J10: =Table113456[[#This Row],[DG Parboiling Run Hours]] -> 0 | K10: =Table113456[[#This Row],[DG Utility Run Hours]] -> 0 | L10: =Table113456[[#This Row],[DG Admin Run Hours]] -> 0 | M10: =Table113[[#This Row],[Comp E75 -1 Rem Hours To Service]] -> 1407 | N10: =Table113[[#This Row],[Comp E75 -2 Rem Hours To Service]] -> 1225 | O10: =Table113[[#This Row],[Comp E75 -3 Rem Hours To Service]] -> 3028 | P10: =Table113[[#This Row],[Comp E55 Rem Hours To Service]] -> 989 | Q10: =$Y$3-Table113456[[#This Row],[DG Milling Run Hr Meter]] -> 131 | R10: =Table113456[[#This Row],[DG Parboil REM SERVICE Hr]] -> 105.3 | S10: =Table113456[[#This Row],[DG Utility REM SERVICE Hr]] -> 205.3 | T10: =Table113456[[#This Row],[DG Admin REM SERVICE Hr]] -> 35.8 | AD10: =Diesel!I10 -> 44570
A11: ='PowerHouse Data'!$K$1 -> 46273 | B11: =Table113456[[#This Row],[Main Tank Consumption (Liters)]] -> 312 | C11: =Table1135[[#This Row],[NEPA Consumption (KWH)]] -> 1040 | D11: =Table1135[[#This Row],[NEPA Availablity]] -> 18.3 | E11: =Table113[[#This Row],[Comp E75 -1 Run Hours]] -> 0 | F11: =Table113[[#This Row],[Comp E75 -2 Run Hours]] -> 0 | G11: =Table113[[#This Row],[Comp E75 -3 Run Hours]] -> 0 | H11: =Table113[[#This Row],[Comp E55 Run Hours]] -> 0 | I11: =Table113456[[#This Row],[DG Milling Run Hours]] -> 5.7 | J11: =Table113456[[#This Row],[DG Parboiling Run Hours]] -> 0 | K11: =Table113456[[#This Row],[DG Utility Run Hours]] -> 0 | L11: =Table113456[[#This Row],[DG Admin Run Hours]] -> 0 | M11: =Table113[[#This Row],[Comp E75 -1 Rem Hours To Service]] -> 1407 | N11: =Table113[[#This Row],[Comp E75 -2 Rem Hours To Service]] -> 1225 | O11: =Table113[[#This Row],[Comp E75 -3 Rem Hours To Service]] -> 3028 | P11: =Table113[[#This Row],[Comp E55 Rem Hours To Service]] -> 989 | Q11: =$Y$3-Table113456[[#This Row],[DG Milling Run Hr Meter]] -> 125.3 | R11: =Table113456[[#This Row],[DG Parboil REM SERVICE Hr]] -> 105.3 | S11: =Table113456[[#This Row],[DG Utility REM SERVICE Hr]] -> 205.3 | T11: =Table113456[[#This Row],[DG Admin REM SERVICE Hr]] -> 35.8 | AD11: =Diesel!I11 -> 44258
A12: ='PowerHouse Data'!$L$1 -> 46274 | B12: =Table113456[[#This Row],[Main Tank Consumption (Liters)]] -> 70 | C12: =Table1135[[#This Row],[NEPA Consumption (KWH)]] -> 1220 | D12: =Table1135[[#This Row],[NEPA Availablity]] -> 22.4 | E12: =Table113[[#This Row],[Comp E75 -1 Run Hours]] -> 0 | F12: =Table113[[#This Row],[Comp E75 -2 Run Hours]] -> 0 | G12: =Table113[[#This Row],[Comp E75 -3 Run Hours]] -> 0 | H12: =Table113[[#This Row],[Comp E55 Run Hours]] -> 0 | I12: =Table113456[[#This Row],[DG Milling Run Hours]] -> 0.9 | J12: =Table113456[[#This Row],[DG Parboiling Run Hours]] -> 0 | K12: =Table113456[[#This Row],[DG Utility Run Hours]] -> 0.7 | L12: =Table113456[[#This Row],[DG Admin Run Hours]] -> 0 | M12: =Table113[[#This Row],[Comp E75 -1 Rem Hours To Service]] -> 1407 | N12: =Table113[[#This Row],[Comp E75 -2 Rem Hours To Service]] -> 1225 | O12: =Table113[[#This Row],[Comp E75 -3 Rem Hours To Service]] -> 3028 | P12: =Table113[[#This Row],[Comp E55 Rem Hours To Service]] -> 989 | Q12: =$Y$3-Table113456[[#This Row],[DG Milling Run Hr Meter]] -> 124.4 | R12: =Table113456[[#This Row],[DG Parboil REM SERVICE Hr]] -> 105.3 | S12: =Table113456[[#This Row],[DG Utility REM SERVICE Hr]] -> 204.6 | T12: =Table113456[[#This Row],[DG Admin REM SERVICE Hr]] -> 35.8 | AD12: =Diesel!I12 -> 44188
A13: ='PowerHouse Data'!$M$1 -> 46275 | B13: =Table113456[[#This Row],[Main Tank Consumption (Liters)]] -> 175 | C13: =Table1135[[#This Row],[NEPA Consumption (KWH)]] -> 1020 | D13: =Table1135[[#This Row],[NEPA Availablity]] -> 20.3 | E13: =Table113[[#This Row],[Comp E75 -1 Run Hours]] -> 0 | F13: =Table113[[#This Row],[Comp E75 -2 Run Hours]] -> 0 | G13: =Table113[[#This Row],[Comp E75 -3 Run Hours]] -> 0 | H13: =Table113[[#This Row],[Comp E55 Run Hours]] -> 0 | I13: =Table113456[[#This Row],[DG Milling Run Hours]] -> 2.9 | J13: =Table113456[[#This Row],[DG Parboiling Run Hours]] -> 0 | K13: =Table113456[[#This Row],[DG Utility Run Hours]] -> 0.8 | L13: =Table113456[[#This Row],[DG Admin Run Hours]] -> 0 | M13: =Table113[[#This Row],[Comp E75 -1 Rem Hours To Service]] -> 1407 | N13: =Table113[[#This Row],[Comp E75 -2 Rem Hours To Service]] -> 1225 | O13: =Table113[[#This Row],[Comp E75 -3 Rem Hours To Service]] -> 3028 | P13: =Table113[[#This Row],[Comp E55 Rem Hours To Service]] -> 989 | Q13: =$Y$3-Table113456[[#This Row],[DG Milling Run Hr Meter]] -> 121.5 | R13: =Table113456[[#This Row],[DG Parboil REM SERVICE Hr]] -> 105.3 | S13: =Table113456[[#This Row],[DG Utility REM SERVICE Hr]] -> 203.8 | T13: =Table113456[[#This Row],[DG Admin REM SERVICE Hr]] -> 35.8 | AD13: =Diesel!I13 -> 44013
A14: ='PowerHouse Data'!$N$1 -> 46276 | B14: =Table113456[[#This Row],[Main Tank Consumption (Liters)]] -> 0 | C14: =Table1135[[#This Row],[NEPA Consumption (KWH)]] -> 1150 | D14: =Table1135[[#This Row],[NEPA Availablity]] -> 21.7 | E14: =Table113[[#This Row],[Comp E75 -1 Run Hours]] -> 0 | F14: =Table113[[#This Row],[Comp E75 -2 Run Hours]] -> 0 | G14: =Table113[[#This Row],[Comp E75 -3 Run Hours]] -> 0 | H14: =Table113[[#This Row],[Comp E55 Run Hours]] -> 0 | I14: =Table113456[[#This Row],[DG Milling Run Hours]] -> 0 | J14: =Table113456[[#This Row],[DG Parboiling Run Hours]] -> 0 | K14: =Table113456[[#This Row],[DG Utility Run Hours]] -> 2.3 | L14: =Table113456[[#This Row],[DG Admin Run Hours]] -> 0 | M14: =Table113[[#This Row],[Comp E75 -1 Rem Hours To Service]] -> 1407 | N14: =Table113[[#This Row],[Comp E75 -2 Rem Hours To Service]] -> 1225 | O14: =Table113[[#This Row],[Comp E75 -3 Rem Hours To Service]] -> 3028 | P14: =Table113[[#This Row],[Comp E55 Rem Hours To Service]] -> 989 | Q14: =$Y$3-Table113456[[#This Row],[DG Milling Run Hr Meter]] -> 121.5 | R14: =Table113456[[#This Row],[DG Parboil REM SERVICE Hr]] -> 105.3 | S14: =Table113456[[#This Row],[DG Utility REM SERVICE Hr]] -> 201.5 | T14: =Table113456[[#This Row],[DG Admin REM SERVICE Hr]] -> 35.8 | AD14: =Diesel!I14 -> 44013
A15: ='PowerHouse Data'!$O$1 -> 46277 | B15: =Table113456[[#This Row],[Main Tank Consumption (Liters)]] -> 0 | C15: =Table1135[[#This Row],[NEPA Consumption (KWH)]] -> 1070 | D15: =Table1135[[#This Row],[NEPA Availablity]] -> 22.7 | E15: =Table113[[#This Row],[Comp E75 -1 Run Hours]] -> 0 | F15: =Table113[[#This Row],[Comp E75 -2 Run Hours]] -> 0 | G15: =Table113[[#This Row],[Comp E75 -3 Run Hours]] -> 0 | H15: =Table113[[#This Row],[Comp E55 Run Hours]] -> 0 | I15: =Table113456[[#This Row],[DG Milling Run Hours]] -> 0 | J15: =Table113456[[#This Row],[DG Parboiling Run Hours]] -> 0 | K15: =Table113456[[#This Row],[DG Utility Run Hours]] -> 1.3 | L15: =Table113456[[#This Row],[DG Admin Run Hours]] -> 0 | M15: =Table113[[#This Row],[Comp E75 -1 Rem Hours To Service]] -> 1407 | N15: =Table113[[#This Row],[Comp E75 -2 Rem Hours To Service]] -> 1225 | O15: =Table113[[#This Row],[Comp E75 -3 Rem Hours To Service]] -> 3028 | P15: =Table113[[#This Row],[Comp E55 Rem Hours To Service]] -> 989 | Q15: =$Y$3-Table113456[[#This Row],[DG Milling Run Hr Meter]] -> 121.5 | R15: =Table113456[[#This Row],[DG Parboil REM SERVICE Hr]] -> 105.3 | S15: =Table113456[[#This Row],[DG Utility REM SERVICE Hr]] -> 200.2 | T15: =Table113456[[#This Row],[DG Admin REM SERVICE Hr]] -> 35.8 | AD15: =Diesel!I15 -> 43947
A16: ='PowerHouse Data'!$P$1 -> 46278 | B16: =Table113456[[#This Row],[Main Tank Consumption (Liters)]] -> 0 | C16: =Table1135[[#This Row],[NEPA Consumption (KWH)]] -> 990 | D16: =Table1135[[#This Row],[NEPA Availablity]] -> 24 | E16: =Table113[[#This Row],[Comp E75 -1 Run Hours]] -> 0 | F16: =Table113[[#This Row],[Comp E75 -2 Run Hours]] -> 0 | G16: =Table113[[#This Row],[Comp E75 -3 Run Hours]] -> 0 | H16: =Table113[[#This Row],[Comp E55 Run Hours]] -> 0 | I16: =Table113456[[#This Row],[DG Milling Run Hours]] -> 0 | J16: =Table113456[[#This Row],[DG Parboiling Run Hours]] -> 0 | K16: =Table113456[[#This Row],[DG Utility Run Hours]] -> 0 | L16: =Table113456[[#This Row],[DG Admin Run Hours]] -> 0 | M16: =Table113[[#This Row],[Comp E75 -1 Rem Hours To Service]] -> 1407 | N16: =Table113[[#This Row],[Comp E75 -2 Rem Hours To Service]] -> 1225 | O16: =Table113[[#This Row],[Comp E75 -3 Rem Hours To Service]] -> 3028 | P16: =Table113[[#This Row],[Comp E55 Rem Hours To Service]] -> 989 | Q16: =$Y$3-Table113456[[#This Row],[DG Milling Run Hr Meter]] -> 121.5 | R16: =Table113456[[#This Row],[DG Parboil REM SERVICE Hr]] -> 105.3 | S16: =Table113456[[#This Row],[DG Utility REM SERVICE Hr]] -> 200.2 | T16: =Table113456[[#This Row],[DG Admin REM SERVICE Hr]] -> 35.8 | AD16: =Diesel!I16 -> 43947
A17: ='PowerHouse Data'!$Q$1 -> 46279 | B17: =Table113456[[#This Row],[Main Tank Consumption (Liters)]] -> 0 | C17: =Table1135[[#This Row],[NEPA Consumption (KWH)]] -> 1070 | D17: =Table1135[[#This Row],[NEPA Availablity]] -> 22.7 | E17: =Table113[[#This Row],[Comp E75 -1 Run Hours]] -> 0 | F17: =Table113[[#This Row],[Comp E75 -2 Run Hours]] -> 0 | G17: =Table113[[#This Row],[Comp E75 -3 Run Hours]] -> 0 | H17: =Table113[[#This Row],[Comp E55 Run Hours]] -> 0 | I17: =Table113456[[#This Row],[DG Milling Run Hours]] -> 0 | J17: =Table113456[[#This Row],[DG Parboiling Run Hours]] -> 0 | K17: =Table113456[[#This Row],[DG Utility Run Hours]] -> 1.3 | L17: =Table113456[[#This Row],[DG Admin Run Hours]] -> 0 | M17: =Table113[[#This Row],[Comp E75 -1 Rem Hours To Service]] -> 1407 | N17: =Table113[[#This Row],[Comp E75 -2 Rem Hours To Service]] -> 1225 | O17: =Table113[[#This Row],[Comp E75 -3 Rem Hours To Service]] -> 3028 | P17: =Table113[[#This Row],[Comp E55 Rem Hours To Service]] -> 989 | Q17: =$Y$3-Table113456[[#This Row],[DG Milling Run Hr Meter]] -> 121.5 | R17: =Table113456[[#This Row],[DG Parboil REM SERVICE Hr]] -> 105.3 | S17: =Table113456[[#This Row],[DG Utility REM SERVICE Hr]] -> 198.9 | T17: =Table113456[[#This Row],[DG Admin REM SERVICE Hr]] -> 35.8 | AD17: =Diesel!I17 -> 43937
A18: ='PowerHouse Data'!$R$1 -> 46280 | B18: =Table113456[[#This Row],[Main Tank Consumption (Liters)]] -> 353.5 | C18: =Table1135[[#This Row],[NEPA Consumption (KWH)]] -> 740 | D18: =Table1135[[#This Row],[NEPA Availablity]] -> 18 | E18: =Table113[[#This Row],[Comp E75 -1 Run Hours]] -> 0 | F18: =Table113[[#This Row],[Comp E75 -2 Run Hours]] -> 0 | G18: =Table113[[#This Row],[Comp E75 -3 Run Hours]] -> 0 | H18: =Table113[[#This Row],[Comp E55 Run Hours]] -> 0 | I18: =Table113456[[#This Row],[DG Milling Run Hours]] -> 0 | J18: =Table113456[[#This Row],[DG Parboiling Run Hours]] -> 0 | K18: =Table113456[[#This Row],[DG Utility Run Hours]] -> 5.9 | L18: =Table113456[[#This Row],[DG Admin Run Hours]] -> 0 | M18: =Table113[[#This Row],[Comp E75 -1 Rem Hours To Service]] -> 1407 | N18: =Table113[[#This Row],[Comp E75 -2 Rem Hours To Service]] -> 1225 | O18: =Table113[[#This Row],[Comp E75 -3 Rem Hours To Service]] -> 3028 | P18: =Table113[[#This Row],[Comp E55 Rem Hours To Service]] -> 989 | Q18: =$Y$3-Table113456[[#This Row],[DG Milling Run Hr Meter]] -> 121.5 | R18: =Table113456[[#This Row],[DG Parboil REM SERVICE Hr]] -> 105.3 | S18: =Table113456[[#This Row],[DG Utility REM SERVICE Hr]] -> 193 | T18: =Table113456[[#This Row],[DG Admin REM SERVICE Hr]] -> 35.8 | AD18: =Diesel!I18 -> 43659.5
A19: ='PowerHouse Data'!$S$1 -> 46281 | B19: =Table113456[[#This Row],[Main Tank Consumption (Liters)]] -> 38475.5 | C19: =Table1135[[#This Row],[NEPA Consumption (KWH)]] -> -24340840 | D19: =Table1135[[#This Row],[NEPA Availablity]] -> 0 | E19: =Table113[[#This Row],[Comp E75 -1 Run Hours]] -> -4033 | F19: =Table113[[#This Row],[Comp E75 -2 Run Hours]] -> -6841 | G19: =Table113[[#This Row],[Comp E75 -3 Run Hours]] -> -972 | H19: =Table113[[#This Row],[Comp E55 Run Hours]] -> -25941 | I19: =Table113456[[#This Row],[DG Milling Run Hours]] -> -5702.5 | J19: =Table113456[[#This Row],[DG Parboiling Run Hours]] -> -12538.2 | K19: =Table113456[[#This Row],[DG Utility Run Hours]] -> -30957 | L19: =Table113456[[#This Row],[DG Admin Run Hours]] -> -3504.2 | M19: =Table113[[#This Row],[Comp E75 -1 Rem Hours To Service]] -> 5440 | N19: =Table113[[#This Row],[Comp E75 -2 Rem Hours To Service]] -> 8066 | O19: =Table113[[#This Row],[Comp E75 -3 Rem Hours To Service]] -> 4000 | P19: =Table113[[#This Row],[Comp E55 Rem Hours To Service]] -> 26930 | Q19: =$Y$3-Table113456[[#This Row],[DG Milling Run Hr Meter]] -> 5824 | R19: =Table113456[[#This Row],[DG Parboil REM SERVICE Hr]] -> 12643.5 | S19: =Table113456[[#This Row],[DG Utility REM SERVICE Hr]] -> 31150 | T19: =Table113456[[#This Row],[DG Admin REM SERVICE Hr]] -> 3540 | AD19: =Diesel!I19 -> 0
A20: ='PowerHouse Data'!$T$1 -> 46282 | B20: =Table113456[[#This Row],[Main Tank Consumption (Liters)]] -> 0 | C20: =Table1135[[#This Row],[NEPA Consumption (KWH)]] -> 0 | D20: =Table1135[[#This Row],[NEPA Availablity]] -> 0 | E20: =Table113[[#This Row],[Comp E75 -1 Run Hours]] -> 0 | F20: =Table113[[#This Row],[Comp E75 -2 Run Hours]] -> 0 | G20: =Table113[[#This Row],[Comp E75 -3 Run Hours]] -> 0 | H20: =Table113[[#This Row],[Comp E55 Run Hours]] -> 0 | I20: =Table113456[[#This Row],[DG Milling Run Hours]] -> 0 | J20: =Table113456[[#This Row],[DG Parboiling Run Hours]] -> 0 | K20: =Table113456[[#This Row],[DG Utility Run Hours]] -> 0 | L20: =Table113456[[#This Row],[DG Admin Run Hours]] -> 0 | M20: =Table113[[#This Row],[Comp E75 -1 Rem Hours To Service]] -> 5440 | N20: =Table113[[#This Row],[Comp E75 -2 Rem Hours To Service]] -> 8066 | O20: =Table113[[#This Row],[Comp E75 -3 Rem Hours To Service]] -> 4000 | P20: =Table113[[#This Row],[Comp E55 Rem Hours To Service]] -> 26930 | Q20: =$Y$3-Table113456[[#This Row],[DG Milling Run Hr Meter]] -> 5824 | R20: =Table113456[[#This Row],[DG Parboil REM SERVICE Hr]] -> 12643.5 | S20: =Table113456[[#This Row],[DG Utility REM SERVICE Hr]] -> 31150 | T20: =Table113456[[#This Row],[DG Admin REM SERVICE Hr]] -> 3540 | AD20: =Diesel!I20 -> 0
A21: ='PowerHouse Data'!$U$1 -> 46283 | B21: =Table113456[[#This Row],[Main Tank Consumption (Liters)]] -> 0 | C21: =Table1135[[#This Row],[NEPA Consumption (KWH)]] -> 0 | D21: =Table1135[[#This Row],[NEPA Availablity]] -> 0 | E21: =Table113[[#This Row],[Comp E75 -1 Run Hours]] -> 0 | F21: =Table113[[#This Row],[Comp E75 -2 Run Hours]] -> 0 | G21: =Table113[[#This Row],[Comp E75 -3 Run Hours]] -> 0 | H21: =Table113[[#This Row],[Comp E55 Run Hours]] -> 0 | I21: =Table113456[[#This Row],[DG Milling Run Hours]] -> 0 | J21: =Table113456[[#This Row],[DG Parboiling Run Hours]] -> 0 | K21: =Table113456[[#This Row],[DG Utility Run Hours]] -> 0 | L21: =Table113456[[#This Row],[DG Admin Run Hours]] -> 0 | M21: =Table113[[#This Row],[Comp E75 -1 Rem Hours To Service]] -> 5440 | N21: =Table113[[#This Row],[Comp E75 -2 Rem Hours To Service]] -> 8066 | O21: =Table113[[#This Row],[Comp E75 -3 Rem Hours To Service]] -> 4000 | P21: =Table113[[#This Row],[Comp E55 Rem Hours To Service]] -> 26930 | Q21: =$Y$3-Table113456[[#This Row],[DG Milling Run Hr Meter]] -> 5824 | R21: =Table113456[[#This Row],[DG Parboil REM SERVICE Hr]] -> 12643.5 | S21: =Table113456[[#This Row],[DG Utility REM SERVICE Hr]] -> 31150 | T21: =Table113456[[#This Row],[DG Admin REM SERVICE Hr]] -> 3540 | AD21: =Diesel!I21 -> 0
A22: ='PowerHouse Data'!$V$1 -> 46284 | B22: =Table113456[[#This Row],[Main Tank Consumption (Liters)]] -> 0 | C22: =Table1135[[#This Row],[NEPA Consumption (KWH)]] -> 0 | D22: =Table1135[[#This Row],[NEPA Availablity]] -> 0 | E22: =Table113[[#This Row],[Comp E75 -1 Run Hours]] -> 0 | F22: =Table113[[#This Row],[Comp E75 -2 Run Hours]] -> 0 | G22: =Table113[[#This Row],[Comp E75 -3 Run Hours]] -> 0 | H22: =Table113[[#This Row],[Comp E55 Run Hours]] -> 0 | I22: =Table113456[[#This Row],[DG Milling Run Hours]] -> 0 | J22: =Table113456[[#This Row],[DG Parboiling Run Hours]] -> 0 | K22: =Table113456[[#This Row],[DG Utility Run Hours]] -> 0 | L22: =Table113456[[#This Row],[DG Admin Run Hours]] -> 0 | M22: =Table113[[#This Row],[Comp E75 -1 Rem Hours To Service]] -> 5440 | N22: =Table113[[#This Row],[Comp E75 -2 Rem Hours To Service]] -> 8066 | O22: =Table113[[#This Row],[Comp E75 -3 Rem Hours To Service]] -> 4000 | P22: =Table113[[#This Row],[Comp E55 Rem Hours To Service]] -> 26930 | Q22: =$Y$3-Table113456[[#This Row],[DG Milling Run Hr Meter]] -> 5824 | R22: =Table113456[[#This Row],[DG Parboil REM SERVICE Hr]] -> 12643.5 | S22: =Table113456[[#This Row],[DG Utility REM SERVICE Hr]] -> 31150 | T22: =Table113456[[#This Row],[DG Admin REM SERVICE Hr]] -> 3540 | AD22: =Diesel!I22 -> 0
A23: ='PowerHouse Data'!$W$1 -> 46285 | B23: =Table113456[[#This Row],[Main Tank Consumption (Liters)]] -> 0 | C23: =Table1135[[#This Row],[NEPA Consumption (KWH)]] -> 0 | D23: =Table1135[[#This Row],[NEPA Availablity]] -> 0 | E23: =Table113[[#This Row],[Comp E75 -1 Run Hours]] -> 0 | F23: =Table113[[#This Row],[Comp E75 -2 Run Hours]] -> 0 | G23: =Table113[[#This Row],[Comp E75 -3 Run Hours]] -> 0 | H23: =Table113[[#This Row],[Comp E55 Run Hours]] -> 0 | I23: =Table113456[[#This Row],[DG Milling Run Hours]] -> 0 | J23: =Table113456[[#This Row],[DG Parboiling Run Hours]] -> 0 | K23: =Table113456[[#This Row],[DG Utility Run Hours]] -> 0 | L23: =Table113456[[#This Row],[DG Admin Run Hours]] -> 0 | M23: =Table113[[#This Row],[Comp E75 -1 Rem Hours To Service]] -> 5440 | N23: =Table113[[#This Row],[Comp E75 -2 Rem Hours To Service]] -> 8066 | O23: =Table113[[#This Row],[Comp E75 -3 Rem Hours To Service]] -> 4000 | P23: =Table113[[#This Row],[Comp E55 Rem Hours To Service]] -> 26930 | Q23: =$Y$3-Table113456[[#This Row],[DG Milling Run Hr Meter]] -> 5824 | R23: =Table113456[[#This Row],[DG Parboil REM SERVICE Hr]] -> 12643.5 | S23: =Table113456[[#This Row],[DG Utility REM SERVICE Hr]] -> 31150 | T23: =Table113456[[#This Row],[DG Admin REM SERVICE Hr]] -> 3540 | AD23: =Diesel!I23 -> 0
A24: ='PowerHouse Data'!$X$1 -> 46286 | B24: =Table113456[[#This Row],[Main Tank Consumption (Liters)]] -> 0 | C24: =Table1135[[#This Row],[NEPA Consumption (KWH)]] -> 0 | D24: =Table1135[[#This Row],[NEPA Availablity]] -> 0 | E24: =Table113[[#This Row],[Comp E75 -1 Run Hours]] -> 0 | F24: =Table113[[#This Row],[Comp E75 -2 Run Hours]] -> 0 | G24: =Table113[[#This Row],[Comp E75 -3 Run Hours]] -> 0 | H24: =Table113[[#This Row],[Comp E55 Run Hours]] -> 0 | I24: =Table113456[[#This Row],[DG Milling Run Hours]] -> 0 | J24: =Table113456[[#This Row],[DG Parboiling Run Hours]] -> 0 | K24: =Table113456[[#This Row],[DG Utility Run Hours]] -> 0 | L24: =Table113456[[#This Row],[DG Admin Run Hours]] -> 0 | M24: =Table113[[#This Row],[Comp E75 -1 Rem Hours To Service]] -> 5440 | N24: =Table113[[#This Row],[Comp E75 -2 Rem Hours To Service]] -> 8066 | O24: =Table113[[#This Row],[Comp E75 -3 Rem Hours To Service]] -> 4000 | P24: =Table113[[#This Row],[Comp E55 Rem Hours To Service]] -> 26930 | Q24: =$Y$3-Table113456[[#This Row],[DG Milling Run Hr Meter]] -> 5824 | R24: =Table113456[[#This Row],[DG Parboil REM SERVICE Hr]] -> 12643.5 | S24: =Table113456[[#This Row],[DG Utility REM SERVICE Hr]] -> 31150 | T24: =Table113456[[#This Row],[DG Admin REM SERVICE Hr]] -> 3540 | AD24: =Diesel!I24 -> 0
A25: ='PowerHouse Data'!$Y$1 -> 46287 | B25: =Table113456[[#This Row],[Main Tank Consumption (Liters)]] -> 0 | C25: =Table1135[[#This Row],[NEPA Consumption (KWH)]] -> 0 | D25: =Table1135[[#This Row],[NEPA Availablity]] -> 0 | E25: =Table113[[#This Row],[Comp E75 -1 Run Hours]] -> 0 | F25: =Table113[[#This Row],[Comp E75 -2 Run Hours]] -> 0 | G25: =Table113[[#This Row],[Comp E75 -3 Run Hours]] -> 0 | H25: =Table113[[#This Row],[Comp E55 Run Hours]] -> 0 | I25: =Table113456[[#This Row],[DG Milling Run Hours]] -> 0 | J25: =Table113456[[#This Row],[DG Parboiling Run Hours]] -> 0 | K25: =Table113456[[#This Row],[DG Utility Run Hours]] -> 0 | L25: =Table113456[[#This Row],[DG Admin Run Hours]] -> 0 | M25: =Table113[[#This Row],[Comp E75 -1 Rem Hours To Service]] -> 5440 | N25: =Table113[[#This Row],[Comp E75 -2 Rem Hours To Service]] -> 8066 | O25: =Table113[[#This Row],[Comp E75 -3 Rem Hours To Service]] -> 4000 | P25: =Table113[[#This Row],[Comp E55 Rem Hours To Service]] -> 26930 | Q25: =$Y$3-Table113456[[#This Row],[DG Milling Run Hr Meter]] -> 5824 | R25: =Table113456[[#This Row],[DG Parboil REM SERVICE Hr]] -> 12643.5 | S25: =Table113456[[#This Row],[DG Utility REM SERVICE Hr]] -> 31150 | T25: =Table113456[[#This Row],[DG Admin REM SERVICE Hr]] -> 3540 | AD25: =Diesel!I25 -> 0
A26: ='PowerHouse Data'!$Z$1 -> 46288 | B26: =Table113456[[#This Row],[Main Tank Consumption (Liters)]] -> 0 | C26: =Table1135[[#This Row],[NEPA Consumption (KWH)]] -> 0 | D26: =Table1135[[#This Row],[NEPA Availablity]] -> 0 | E26: =Table113[[#This Row],[Comp E75 -1 Run Hours]] -> 0 | F26: =Table113[[#This Row],[Comp E75 -2 Run Hours]] -> 0 | G26: =Table113[[#This Row],[Comp E75 -3 Run Hours]] -> 0 | H26: =Table113[[#This Row],[Comp E55 Run Hours]] -> 0 | I26: =Table113456[[#This Row],[DG Milling Run Hours]] -> 0 | J26: =Table113456[[#This Row],[DG Parboiling Run Hours]] -> 0 | K26: =Table113456[[#This Row],[DG Utility Run Hours]] -> 0 | L26: =Table113456[[#This Row],[DG Admin Run Hours]] -> 0 | M26: =Table113[[#This Row],[Comp E75 -1 Rem Hours To Service]] -> 5440 | N26: =Table113[[#This Row],[Comp E75 -2 Rem Hours To Service]] -> 8066 | O26: =Table113[[#This Row],[Comp E75 -3 Rem Hours To Service]] -> 4000 | P26: =Table113[[#This Row],[Comp E55 Rem Hours To Service]] -> 26930 | Q26: =$Y$3-Table113456[[#This Row],[DG Milling Run Hr Meter]] -> 5824 | R26: =Table113456[[#This Row],[DG Parboil REM SERVICE Hr]] -> 12643.5 | S26: =Table113456[[#This Row],[DG Utility REM SERVICE Hr]] -> 31150 | T26: =Table113456[[#This Row],[DG Admin REM SERVICE Hr]] -> 3540 | AD26: =Diesel!I26 -> 0
A27: ='PowerHouse Data'!$AA$1 -> 46289 | B27: =Table113456[[#This Row],[Main Tank Consumption (Liters)]] -> 0 | C27: =Table1135[[#This Row],[NEPA Consumption (KWH)]] -> 0 | D27: =Table1135[[#This Row],[NEPA Availablity]] -> 0 | E27: =Table113[[#This Row],[Comp E75 -1 Run Hours]] -> 0 | F27: =Table113[[#This Row],[Comp E75 -2 Run Hours]] -> 0 | G27: =Table113[[#This Row],[Comp E75 -3 Run Hours]] -> 0 | H27: =Table113[[#This Row],[Comp E55 Run Hours]] -> 0 | I27: =Table113456[[#This Row],[DG Milling Run Hours]] -> 0 | J27: =Table113456[[#This Row],[DG Parboiling Run Hours]] -> 0 | K27: =Table113456[[#This Row],[DG Utility Run Hours]] -> 0 | L27: =Table113456[[#This Row],[DG Admin Run Hours]] -> 0 | M27: =Table113[[#This Row],[Comp E75 -1 Rem Hours To Service]] -> 5440 | N27: =Table113[[#This Row],[Comp E75 -2 Rem Hours To Service]] -> 8066 | O27: =Table113[[#This Row],[Comp E75 -3 Rem Hours To Service]] -> 4000 | P27: =Table113[[#This Row],[Comp E55 Rem Hours To Service]] -> 26930 | Q27: =$Y$3-Table113456[[#This Row],[DG Milling Run Hr Meter]] -> 5824 | R27: =Table113456[[#This Row],[DG Parboil REM SERVICE Hr]] -> 12643.5 | S27: =Table113456[[#This Row],[DG Utility REM SERVICE Hr]] -> 31150 | T27: =Table113456[[#This Row],[DG Admin REM SERVICE Hr]] -> 3540 | AD27: =Diesel!I27 -> 0
A28: ='PowerHouse Data'!$AB$1 -> 46290 | B28: =Table113456[[#This Row],[Main Tank Consumption (Liters)]] -> 0 | C28: =Table1135[[#This Row],[NEPA Consumption (KWH)]] -> 0 | D28: =Table1135[[#This Row],[NEPA Availablity]] -> 0 | E28: =Table113[[#This Row],[Comp E75 -1 Run Hours]] -> 0 | F28: =Table113[[#This Row],[Comp E75 -2 Run Hours]] -> 0 | G28: =Table113[[#This Row],[Comp E75 -3 Run Hours]] -> 0 | H28: =Table113[[#This Row],[Comp E55 Run Hours]] -> 0 | I28: =Table113456[[#This Row],[DG Milling Run Hours]] -> 0 | J28: =Table113456[[#This Row],[DG Parboiling Run Hours]] -> 0 | K28: =Table113456[[#This Row],[DG Utility Run Hours]] -> 0 | L28: =Table113456[[#This Row],[DG Admin Run Hours]] -> 0 | M28: =Table113[[#This Row],[Comp E75 -1 Rem Hours To Service]] -> 5440 | N28: =Table113[[#This Row],[Comp E75 -2 Rem Hours To Service]] -> 8066 | O28: =Table113[[#This Row],[Comp E75 -3 Rem Hours To Service]] -> 4000 | P28: =Table113[[#This Row],[Comp E55 Rem Hours To Service]] -> 26930 | Q28: =$Y$3-Table113456[[#This Row],[DG Milling Run Hr Meter]] -> 5824 | R28: =Table113456[[#This Row],[DG Parboil REM SERVICE Hr]] -> 12643.5 | S28: =Table113456[[#This Row],[DG Utility REM SERVICE Hr]] -> 31150 | T28: =Table113456[[#This Row],[DG Admin REM SERVICE Hr]] -> 3540 | AD28: =Diesel!I28 -> 0
A29: ='PowerHouse Data'!$AC$1 -> 46291 | B29: =Table113456[[#This Row],[Main Tank Consumption (Liters)]] -> 0 | C29: =Table1135[[#This Row],[NEPA Consumption (KWH)]] -> 0 | D29: =Table1135[[#This Row],[NEPA Availablity]] -> 0 | E29: =Table113[[#This Row],[Comp E75 -1 Run Hours]] -> 0 | F29: =Table113[[#This Row],[Comp E75 -2 Run Hours]] -> 0 | G29: =Table113[[#This Row],[Comp E75 -3 Run Hours]] -> 0 | H29: =Table113[[#This Row],[Comp E55 Run Hours]] -> 0 | I29: =Table113456[[#This Row],[DG Milling Run Hours]] -> 0 | J29: =Table113456[[#This Row],[DG Parboiling Run Hours]] -> 0 | K29: =Table113456[[#This Row],[DG Utility Run Hours]] -> 0 | L29: =Table113456[[#This Row],[DG Admin Run Hours]] -> 0 | M29: =Table113[[#This Row],[Comp E75 -1 Rem Hours To Service]] -> 5440 | N29: =Table113[[#This Row],[Comp E75 -2 Rem Hours To Service]] -> 8066 | O29: =Table113[[#This Row],[Comp E75 -3 Rem Hours To Service]] -> 4000 | P29: =Table113[[#This Row],[Comp E55 Rem Hours To Service]] -> 26930 | Q29: =$Y$3-Table113456[[#This Row],[DG Milling Run Hr Meter]] -> 5824 | R29: =Table113456[[#This Row],[DG Parboil REM SERVICE Hr]] -> 12643.5 | S29: =Table113456[[#This Row],[DG Utility REM SERVICE Hr]] -> 31150 | T29: =Table113456[[#This Row],[DG Admin REM SERVICE Hr]] -> 3540 | AD29: =Diesel!I29 -> 0
A30: ='PowerHouse Data'!$AD$1 -> 46292 | B30: =Table113456[[#This Row],[Main Tank Consumption (Liters)]] -> 0 | C30: =Table1135[[#This Row],[NEPA Consumption (KWH)]] -> 0 | D30: =Table1135[[#This Row],[NEPA Availablity]] -> 0 | E30: =Table113[[#This Row],[Comp E75 -1 Run Hours]] -> 0 | F30: =Table113[[#This Row],[Comp E75 -2 Run Hours]] -> 0 | G30: =Table113[[#This Row],[Comp E75 -3 Run Hours]] -> 0 | H30: =Table113[[#This Row],[Comp E55 Run Hours]] -> 0 | I30: =Table113456[[#This Row],[DG Milling Run Hours]] -> 0 | J30: =Table113456[[#This Row],[DG Parboiling Run Hours]] -> 0 | K30: =Table113456[[#This Row],[DG Utility Run Hours]] -> 0 | L30: =Table113456[[#This Row],[DG Admin Run Hours]] -> 0 | M30: =Table113[[#This Row],[Comp E75 -1 Rem Hours To Service]] -> 5440 | N30: =Table113[[#This Row],[Comp E75 -2 Rem Hours To Service]] -> 8066 | O30: =Table113[[#This Row],[Comp E75 -3 Rem Hours To Service]] -> 4000 | P30: =Table113[[#This Row],[Comp E55 Rem Hours To Service]] -> 26930 | Q30: =$Y$3-Table113456[[#This Row],[DG Milling Run Hr Meter]] -> 5824 | R30: =Table113456[[#This Row],[DG Parboil REM SERVICE Hr]] -> 12643.5 | S30: =Table113456[[#This Row],[DG Utility REM SERVICE Hr]] -> 31150 | T30: =Table113456[[#This Row],[DG Admin REM SERVICE Hr]] -> 3540 | AD30: =Diesel!I30 -> 0
A31: ='PowerHouse Data'!$AE$1 -> 46293 | B31: =Table113456[[#This Row],[Main Tank Consumption (Liters)]] -> 0 | C31: =Table1135[[#This Row],[NEPA Consumption (KWH)]] -> 0 | D31: =Table1135[[#This Row],[NEPA Availablity]] -> 0 | E31: =Table113[[#This Row],[Comp E75 -1 Run Hours]] -> 0 | F31: =Table113[[#This Row],[Comp E75 -2 Run Hours]] -> 0 | G31: =Table113[[#This Row],[Comp E75 -3 Run Hours]] -> 0 | H31: =Table113[[#This Row],[Comp E55 Run Hours]] -> 0 | I31: =Table113456[[#This Row],[DG Milling Run Hours]] -> 0 | J31: =Table113456[[#This Row],[DG Parboiling Run Hours]] -> 0 | K31: =Table113456[[#This Row],[DG Utility Run Hours]] -> 0 | L31: =Table113456[[#This Row],[DG Admin Run Hours]] -> 0 | M31: =Table113[[#This Row],[Comp E75 -1 Rem Hours To Service]] -> 5440 | N31: =Table113[[#This Row],[Comp E75 -2 Rem Hours To Service]] -> 8066 | O31: =Table113[[#This Row],[Comp E75 -3 Rem Hours To Service]] -> 4000 | P31: =Table113[[#This Row],[Comp E55 Rem Hours To Service]] -> 26930 | Q31: =$Y$3-Table113456[[#This Row],[DG Milling Run Hr Meter]] -> 5824 | R31: =Table113456[[#This Row],[DG Parboil REM SERVICE Hr]] -> 12643.5 | S31: =Table113456[[#This Row],[DG Utility REM SERVICE Hr]] -> 31150 | T31: =Table113456[[#This Row],[DG Admin REM SERVICE Hr]] -> 3540 | AD31: =Diesel!I31 -> 0
A32: ='PowerHouse Data'!$AF$1 -> 46294 | B32: =Table113456[[#This Row],[Main Tank Consumption (Liters)]] -> 0 | C32: =Table1135[[#This Row],[NEPA Consumption (KWH)]] -> 0 | D32: =Table1135[[#This Row],[NEPA Availablity]] -> 0 | E32: =Table113[[#This Row],[Comp E75 -1 Run Hours]] -> 0 | F32: =Table113[[#This Row],[Comp E75 -2 Run Hours]] -> 0 | G32: =Table113[[#This Row],[Comp E75 -3 Run Hours]] -> 0 | H32: =Table113[[#This Row],[Comp E55 Run Hours]] -> 0 | I32: =Table113456[[#This Row],[DG Milling Run Hours]] -> 0 | J32: =Table113456[[#This Row],[DG Parboiling Run Hours]] -> 0 | K32: =Table113456[[#This Row],[DG Utility Run Hours]] -> 0 | L32: =Table113456[[#This Row],[DG Admin Run Hours]] -> 0 | M32: =Table113[[#This Row],[Comp E75 -1 Rem Hours To Service]] -> 5440 | N32: =Table113[[#This Row],[Comp E75 -2 Rem Hours To Service]] -> 8066 | O32: =Table113[[#This Row],[Comp E75 -3 Rem Hours To Service]] -> 4000 | P32: =Table113[[#This Row],[Comp E55 Rem Hours To Service]] -> 26930 | Q32: =$Y$3-Table113456[[#This Row],[DG Milling Run Hr Meter]] -> 5824 | R32: =Table113456[[#This Row],[DG Parboil REM SERVICE Hr]] -> 12643.5 | S32: =Table113456[[#This Row],[DG Utility REM SERVICE Hr]] -> 31150 | T32: =Table113456[[#This Row],[DG Admin REM SERVICE Hr]] -> 3540 | AD32: =Diesel!I32 -> 0
A33: ='PowerHouse Data'!$AG$1 -> 46295 | B33: =Table113456[[#This Row],[Main Tank Consumption (Liters)]] -> 0 | C33: =Table1135[[#This Row],[NEPA Consumption (KWH)]] -> 0 | D33: =Table1135[[#This Row],[NEPA Availablity]] -> 0 | E33: =Table113[[#This Row],[Comp E75 -1 Run Hours]] -> 0 | F33: =Table113[[#This Row],[Comp E75 -2 Run Hours]] -> 0 | G33: =Table113[[#This Row],[Comp E75 -3 Run Hours]] -> 0 | H33: =Table113[[#This Row],[Comp E55 Run Hours]] -> 0 | I33: =Table113456[[#This Row],[DG Milling Run Hours]] -> 0 | J33: =Table113456[[#This Row],[DG Parboiling Run Hours]] -> 0 | K33: =Table113456[[#This Row],[DG Utility Run Hours]] -> 0 | L33: =Table113456[[#This Row],[DG Admin Run Hours]] -> 0 | M33: =Table113[[#This Row],[Comp E75 -1 Rem Hours To Service]] -> 5440 | N33: =Table113[[#This Row],[Comp E75 -2 Rem Hours To Service]] -> 8066 | O33: =Table113[[#This Row],[Comp E75 -3 Rem Hours To Service]] -> 4000 | P33: =Table113[[#This Row],[Comp E55 Rem Hours To Service]] -> 26930 | Q33: =$Y$3-Table113456[[#This Row],[DG Milling Run Hr Meter]] -> 5824 | R33: =Table113456[[#This Row],[DG Parboil REM SERVICE Hr]] -> 12643.5 | S33: =Table113456[[#This Row],[DG Utility REM SERVICE Hr]] -> 31150 | T33: =Table113456[[#This Row],[DG Admin REM SERVICE Hr]] -> 3540 | AD33: =Diesel!I33 -> 0
A34: ='PowerHouse Data'!$AH$1 -> 46296 | B34: =Table113456[[#This Row],[Main Tank Consumption (Liters)]] -> 0 | C34: =Table1135[[#This Row],[NEPA Consumption (KWH)]] -> 0 | D34: =Table1135[[#This Row],[NEPA Availablity]] -> 0 | E34: =Table113[[#This Row],[Comp E75 -1 Run Hours]] -> 0 | F34: =Table113[[#This Row],[Comp E75 -2 Run Hours]] -> 0 | G34: =Table113[[#This Row],[Comp E75 -3 Run Hours]] -> 0 | H34: =Table113[[#This Row],[Comp E55 Run Hours]] -> 0 | I34: =Table113456[[#This Row],[DG Milling Run Hours]] -> 0 | J34: =Table113456[[#This Row],[DG Parboiling Run Hours]] -> 0 | K34: =Table113456[[#This Row],[DG Utility Run Hours]] -> 0 | L34: =Table113456[[#This Row],[DG Admin Run Hours]] -> 0 | M34: =Table113[[#This Row],[Comp E75 -1 Rem Hours To Service]] -> 5440 | N34: =Table113[[#This Row],[Comp E75 -2 Rem Hours To Service]] -> 8066 | O34: =Table113[[#This Row],[Comp E75 -3 Rem Hours To Service]] -> 4000 | P34: =Table113[[#This Row],[Comp E55 Rem Hours To Service]] -> 26930 | Q34: =$Y$3-Table113456[[#This Row],[DG Milling Run Hr Meter]] -> 5824 | R34: =Table113456[[#This Row],[DG Parboil REM SERVICE Hr]] -> 12643.5 | S34: =Table113456[[#This Row],[DG Utility REM SERVICE Hr]] -> 31150 | T34: =Table113456[[#This Row],[DG Admin REM SERVICE Hr]] -> 3540 | AD34: =Diesel!I34 -> 0
A35: ='PowerHouse Data'!$AI$1 -> 0 | B35: =Table113456[[#This Row],[Main Tank Consumption (Liters)]] -> 0 | C35: =Table1135[[#This Row],[NEPA Consumption (KWH)]] -> 0 | D35: =Table1135[[#This Row],[NEPA Availablity]] -> 0 | E35: =Table113[[#This Row],[Comp E75 -1 Run Hours]] -> 0 | F35: =Table113[[#This Row],[Comp E75 -2 Run Hours]] -> 0 | G35: =Table113[[#This Row],[Comp E75 -3 Run Hours]] -> 0 | H35: =Table113[[#This Row],[Comp E55 Run Hours]] -> 0 | I35: =Table113456[[#This Row],[DG Milling Run Hours]] -> 0 | J35: =Table113456[[#This Row],[DG Parboiling Run Hours]] -> 0 | K35: =Table113456[[#This Row],[DG Utility Run Hours]] -> 0 | L35: =Table113456[[#This Row],[DG Admin Run Hours]] -> 0 | M35: =Table113[[#This Row],[Comp E75 -1 Rem Hours To Service]] -> 5440 | N35: =Table113[[#This Row],[Comp E75 -2 Rem Hours To Service]] -> 8066 | O35: =Table113[[#This Row],[Comp E75 -3 Rem Hours To Service]] -> 4000 | P35: =Table113[[#This Row],[Comp E55 Rem Hours To Service]] -> 26930 | Q35: =$Y$3-Table113456[[#This Row],[DG Milling Run Hr Meter]] -> 5824 | R35: =Table113456[[#This Row],[DG Parboil REM SERVICE Hr]] -> 12643.5 | S35: =Table113456[[#This Row],[DG Utility REM SERVICE Hr]] -> 31150 | T35: =Table113456[[#This Row],[DG Admin REM SERVICE Hr]] -> 3540 | AD35: =Diesel!I35 -> 0
B37: =SUM(B4:B34) -> 40462.5 | C37: =SUM(C4:C31) -> -24324380 | E37: =B37-B32 -> 40462.5
B39: NOTE: 06.08.2026 Receive desiel 22 X 230 = 5060 ltrs Befor Receive dip Reading 2098 = 37973 ltrs Calculation wise = 43033 ltrs After Receive dip Reading 2412 = 43035ltrs differance getting extra = 2 ltrs

Sheet Compressor
A1: Date | B1: Comp E75 -1 Run Hours | C1: Comp E75 -1 Run Hr | D1: Comp E75 -1 Rem Hours To Service | E1: Comp E75 -2 Run Hours | F1: Comp E75 -2 Run Hr | G1: Comp E75 -2 Rem Hours To Service | H1: Comp E75 -3 Run Hours | I1: Comp E75 -3 Run Hr | J1: Comp E75 -3 Rem Hours To Service | K1: Comp E55 Run Hours | L1: Comp E55 Run Hr | M1: Comp E55 Rem Hours To Service | N1: Comp E75 -1 Next Ser Hours | O1: Comp E75 -2 Next Ser Hours | P1: Comp E75 -3 Next Ser Hours | Q1: Comp E55 Next Ser Hours
A2: 46233 | B2: 0 | C2: 4033 | D2: 1407 | E2: 0 | F2: 6841 | G2: 1225 | H2: 0 | I2: 972 | J2: 3028 | K2: 0 | L2: 25941 | M2: 989
A3: ='PowerHouse Data'!$C$1 -> 46265 | B3: ='PowerHouse Data'!D9-'PowerHouse Data'!C9 -> 0 | C3: ='PowerHouse Data'!$D$9 -> 4033 | D3: =$N$3-Table113[[#This Row],[Comp E75 -1 Run Hr]] -> 1407 | E3: ='PowerHouse Data'!D10-'PowerHouse Data'!C10 -> 0 | F3: ='PowerHouse Data'!$D$10 -> 6841 | G3: =$O$3-Table113[[#This Row],[Comp E75 -2 Run Hr]] -> 1225 | H3: ='PowerHouse Data'!D11-'PowerHouse Data'!C11 -> 0 | I3: ='PowerHouse Data'!$D$11 -> 972 | J3: =$P$3-Table113[[#This Row],[Comp E75 -3 Run Hr]] -> 3028 | K3: ='PowerHouse Data'!D12-'PowerHouse Data'!C12 -> 0 | L3: ='PowerHouse Data'!$D$12 -> 25941 | M3: =$Q$3-Table113[[#This Row],[Comp E55 Run Hr]] -> 989 | N3: 5440 | O3: 8066 | P3: 4000 | Q3: 26930
A4: ='PowerHouse Data'!$D$1 -> 46266 | B4: =Table113[[#This Row],[Comp E75 -1 Run Hr]]-C3 -> 0 | C4: ='PowerHouse Data'!$E$9 -> 4033 | D4: =$N$3-Table113[[#This Row],[Comp E75 -1 Run Hr]] -> 1407 | E4: =Table113[[#This Row],[Comp E75 -2 Run Hr]]-F3 -> 0 | F4: ='PowerHouse Data'!$E$10 -> 6841 | G4: =$O$3-Table113[[#This Row],[Comp E75 -2 Run Hr]] -> 1225 | H4: =Table113[[#This Row],[Comp E75 -3 Run Hr]]-I3 -> 0 | I4: ='PowerHouse Data'!$E$11 -> 972 | J4: =$P$3-Table113[[#This Row],[Comp E75 -3 Run Hr]] -> 3028 | K4: =Table113[[#This Row],[Comp E55 Run Hr]]-L3 -> 0 | L4: ='PowerHouse Data'!$E$12 -> 25941 | M4: =$Q$3-Table113[[#This Row],[Comp E55 Run Hr]] -> 989
A5: ='PowerHouse Data'!$E$1 -> 46267 | B5: =Table113[[#This Row],[Comp E75 -1 Run Hr]]-C4 -> 0 | C5: ='PowerHouse Data'!$F$9 -> 4033 | D5: =$N$3-Table113[[#This Row],[Comp E75 -1 Run Hr]] -> 1407 | E5: =Table113[[#This Row],[Comp E75 -2 Run Hr]]-F4 -> 0 | F5: ='PowerHouse Data'!$F$10 -> 6841 | G5: =$O$3-Table113[[#This Row],[Comp E75 -2 Run Hr]] -> 1225 | H5: =Table113[[#This Row],[Comp E75 -3 Run Hr]]-I4 -> 0 | I5: ='PowerHouse Data'!$F$11 -> 972 | J5: =$P$3-Table113[[#This Row],[Comp E75 -3 Run Hr]] -> 3028 | K5: =Table113[[#This Row],[Comp E55 Run Hr]]-L4 -> 0 | L5: ='PowerHouse Data'!$F$12 -> 25941 | M5: =$Q$3-Table113[[#This Row],[Comp E55 Run Hr]] -> 989
A6: ='PowerHouse Data'!$F$1 -> 46268 | B6: =Table113[[#This Row],[Comp E75 -1 Run Hr]]-C5 -> 0 | C6: ='PowerHouse Data'!$G$9 -> 4033 | D6: =$N$3-Table113[[#This Row],[Comp E75 -1 Run Hr]] -> 1407 | E6: =Table113[[#This Row],[Comp E75 -2 Run Hr]]-F5 -> 0 | F6: ='PowerHouse Data'!$G$10 -> 6841 | G6: =$O$3-Table113[[#This Row],[Comp E75 -2 Run Hr]] -> 1225 | H6: =Table113[[#This Row],[Comp E75 -3 Run Hr]]-I5 -> 0 | I6: ='PowerHouse Data'!$G$11 -> 972 | J6: =$P$3-Table113[[#This Row],[Comp E75 -3 Run Hr]] -> 3028 | K6: =Table113[[#This Row],[Comp E55 Run Hr]]-L5 -> 0 | L6: ='PowerHouse Data'!$G$12 -> 25941 | M6: =$Q$3-Table113[[#This Row],[Comp E55 Run Hr]] -> 989
A7: ='PowerHouse Data'!$G$1 -> 46269 | B7: =Table113[[#This Row],[Comp E75 -1 Run Hr]]-C6 -> 0 | C7: ='PowerHouse Data'!$H$9 -> 4033 | D7: =$N$3-Table113[[#This Row],[Comp E75 -1 Run Hr]] -> 1407 | E7: =Table113[[#This Row],[Comp E75 -2 Run Hr]]-F6 -> 0 | F7: ='PowerHouse Data'!$H$10 -> 6841 | G7: =$O$3-Table113[[#This Row],[Comp E75 -2 Run Hr]] -> 1225 | H7: =Table113[[#This Row],[Comp E75 -3 Run Hr]]-I6 -> 0 | I7: ='PowerHouse Data'!$H$11 -> 972 | J7: =$P$3-Table113[[#This Row],[Comp E75 -3 Run Hr]] -> 3028 | K7: =Table113[[#This Row],[Comp E55 Run Hr]]-L6 -> 0 | L7: ='PowerHouse Data'!$H$12 -> 25941 | M7: =$Q$3-Table113[[#This Row],[Comp E55 Run Hr]] -> 989
A8: ='PowerHouse Data'!$H$1 -> 46270 | B8: =Table113[[#This Row],[Comp E75 -1 Run Hr]]-C7 -> 0 | C8: ='PowerHouse Data'!$I$9 -> 4033 | D8: =$N$3-Table113[[#This Row],[Comp E75 -1 Run Hr]] -> 1407 | E8: =Table113[[#This Row],[Comp E75 -2 Run Hr]]-F7 -> 0 | F8: ='PowerHouse Data'!$I$10 -> 6841 | G8: =$O$3-Table113[[#This Row],[Comp E75 -2 Run Hr]] -> 1225 | H8: =Table113[[#This Row],[Comp E75 -3 Run Hr]]-I7 -> 0 | I8: ='PowerHouse Data'!$I$11 -> 972 | J8: =$P$3-Table113[[#This Row],[Comp E75 -3 Run Hr]] -> 3028 | K8: =Table113[[#This Row],[Comp E55 Run Hr]]-L7 -> 0 | L8: ='PowerHouse Data'!$I$12 -> 25941 | M8: =$Q$3-Table113[[#This Row],[Comp E55 Run Hr]] -> 989
A9: ='PowerHouse Data'!$I$1 -> 46271 | B9: =Table113[[#This Row],[Comp E75 -1 Run Hr]]-C8 -> 0 | C9: ='PowerHouse Data'!$J$9 -> 4033 | D9: =$N$3-Table113[[#This Row],[Comp E75 -1 Run Hr]] -> 1407 | E9: =Table113[[#This Row],[Comp E75 -2 Run Hr]]-F8 -> 0 | F9: ='PowerHouse Data'!$J$10 -> 6841 | G9: =$O$3-Table113[[#This Row],[Comp E75 -2 Run Hr]] -> 1225 | H9: =Table113[[#This Row],[Comp E75 -3 Run Hr]]-I8 -> 0 | I9: ='PowerHouse Data'!$J$11 -> 972 | J9: =$P$3-Table113[[#This Row],[Comp E75 -3 Run Hr]] -> 3028 | K9: =Table113[[#This Row],[Comp E55 Run Hr]]-L8 -> 0 | L9: ='PowerHouse Data'!$J$12 -> 25941 | M9: =$Q$3-Table113[[#This Row],[Comp E55 Run Hr]] -> 989
A10: ='PowerHouse Data'!$J$1 -> 46272 | B10: =Table113[[#This Row],[Comp E75 -1 Run Hr]]-C9 -> 0 | C10: ='PowerHouse Data'!$K$9 -> 4033 | D10: =$N$3-Table113[[#This Row],[Comp E75 -1 Run Hr]] -> 1407 | E10: =Table113[[#This Row],[Comp E75 -2 Run Hr]]-F9 -> 0 | F10: ='PowerHouse Data'!$K$10 -> 6841 | G10: =$O$3-Table113[[#This Row],[Comp E75 -2 Run Hr]] -> 1225 | H10: =Table113[[#This Row],[Comp E75 -3 Run Hr]]-I9 -> 0 | I10: ='PowerHouse Data'!$K$11 -> 972 | J10: =$P$3-Table113[[#This Row],[Comp E75 -3 Run Hr]] -> 3028 | K10: =Table113[[#This Row],[Comp E55 Run Hr]]-L9 -> 0 | L10: ='PowerHouse Data'!$K$12 -> 25941 | M10: =$Q$3-Table113[[#This Row],[Comp E55 Run Hr]] -> 989
A11: ='PowerHouse Data'!$K$1 -> 46273 | B11: =Table113[[#This Row],[Comp E75 -1 Run Hr]]-C10 -> 0 | C11: ='PowerHouse Data'!$L$9 -> 4033 | D11: =$N$3-Table113[[#This Row],[Comp E75 -1 Run Hr]] -> 1407 | E11: =Table113[[#This Row],[Comp E75 -2 Run Hr]]-F10 -> 0 | F11: ='PowerHouse Data'!$L$10 -> 6841 | G11: =$O$3-Table113[[#This Row],[Comp E75 -2 Run Hr]] -> 1225 | H11: =Table113[[#This Row],[Comp E75 -3 Run Hr]]-I10 -> 0 | I11: ='PowerHouse Data'!$L$11 -> 972 | J11: =$P$3-Table113[[#This Row],[Comp E75 -3 Run Hr]] -> 3028 | K11: =Table113[[#This Row],[Comp E55 Run Hr]]-L10 -> 0 | L11: ='PowerHouse Data'!$L$12 -> 25941 | M11: =$Q$3-Table113[[#This Row],[Comp E55 Run Hr]] -> 989
A12: ='PowerHouse Data'!$L$1 -> 46274 | B12: =Table113[[#This Row],[Comp E75 -1 Run Hr]]-C11 -> 0 | C12: ='PowerHouse Data'!$M$9 -> 4033 | D12: =$N$3-Table113[[#This Row],[Comp E75 -1 Run Hr]] -> 1407 | E12: =Table113[[#This Row],[Comp E75 -2 Run Hr]]-F11 -> 0 | F12: ='PowerHouse Data'!$M$10 -> 6841 | G12: =$O$3-Table113[[#This Row],[Comp E75 -2 Run Hr]] -> 1225 | H12: =Table113[[#This Row],[Comp E75 -3 Run Hr]]-I11 -> 0 | I12: ='PowerHouse Data'!$M$11 -> 972 | J12: =$P$3-Table113[[#This Row],[Comp E75 -3 Run Hr]] -> 3028 | K12: =Table113[[#This Row],[Comp E55 Run Hr]]-L11 -> 0 | L12: ='PowerHouse Data'!$M$12 -> 25941 | M12: =$Q$3-Table113[[#This Row],[Comp E55 Run Hr]] -> 989
A13: ='PowerHouse Data'!$M$1 -> 46275 | B13: =Table113[[#This Row],[Comp E75 -1 Run Hr]]-C12 -> 0 | C13: ='PowerHouse Data'!$N$9 -> 4033 | D13: =$N$3-Table113[[#This Row],[Comp E75 -1 Run Hr]] -> 1407 | E13: =Table113[[#This Row],[Comp E75 -2 Run Hr]]-F12 -> 0 | F13: ='PowerHouse Data'!$N$10 -> 6841 | G13: =$O$3-Table113[[#This Row],[Comp E75 -2 Run Hr]] -> 1225 | H13: =Table113[[#This Row],[Comp E75 -3 Run Hr]]-I12 -> 0 | I13: ='PowerHouse Data'!$N$11 -> 972 | J13: =$P$3-Table113[[#This Row],[Comp E75 -3 Run Hr]] -> 3028 | K13: =Table113[[#This Row],[Comp E55 Run Hr]]-L12 -> 0 | L13: ='PowerHouse Data'!$N$12 -> 25941 | M13: =$Q$3-Table113[[#This Row],[Comp E55 Run Hr]] -> 989
A14: ='PowerHouse Data'!$N$1 -> 46276 | B14: =Table113[[#This Row],[Comp E75 -1 Run Hr]]-C13 -> 0 | C14: ='PowerHouse Data'!$O$9 -> 4033 | D14: =$N$3-Table113[[#This Row],[Comp E75 -1 Run Hr]] -> 1407 | E14: =Table113[[#This Row],[Comp E75 -2 Run Hr]]-F13 -> 0 | F14: ='PowerHouse Data'!$O$10 -> 6841 | G14: =$O$3-Table113[[#This Row],[Comp E75 -2 Run Hr]] -> 1225 | H14: =Table113[[#This Row],[Comp E75 -3 Run Hr]]-I13 -> 0 | I14: ='PowerHouse Data'!$O$11 -> 972 | J14: =$P$3-Table113[[#This Row],[Comp E75 -3 Run Hr]] -> 3028 | K14: =Table113[[#This Row],[Comp E55 Run Hr]]-L13 -> 0 | L14: ='PowerHouse Data'!$O$12 -> 25941 | M14: =$Q$3-Table113[[#This Row],[Comp E55 Run Hr]] -> 989
A15: ='PowerHouse Data'!$O$1 -> 46277 | B15: =Table113[[#This Row],[Comp E75 -1 Run Hr]]-C14 -> 0 | C15: ='PowerHouse Data'!$P$9 -> 4033 | D15: =$N$3-Table113[[#This Row],[Comp E75 -1 Run Hr]] -> 1407 | E15: =Table113[[#This Row],[Comp E75 -2 Run Hr]]-F14 -> 0 | F15: ='PowerHouse Data'!$P$10 -> 6841 | G15: =$O$3-Table113[[#This Row],[Comp E75 -2 Run Hr]] -> 1225 | H15: =Table113[[#This Row],[Comp E75 -3 Run Hr]]-I14 -> 0 | I15: ='PowerHouse Data'!$P$11 -> 972 | J15: =$P$3-Table113[[#This Row],[Comp E75 -3 Run Hr]] -> 3028 | K15: =Table113[[#This Row],[Comp E55 Run Hr]]-L14 -> 0 | L15: ='PowerHouse Data'!$P$12 -> 25941 | M15: =$Q$3-Table113[[#This Row],[Comp E55 Run Hr]] -> 989
A16: ='PowerHouse Data'!$P$1 -> 46278 | B16: =Table113[[#This Row],[Comp E75 -1 Run Hr]]-C15 -> 0 | C16: ='PowerHouse Data'!$Q$9 -> 4033 | D16: =$N$3-Table113[[#This Row],[Comp E75 -1 Run Hr]] -> 1407 | E16: =Table113[[#This Row],[Comp E75 -2 Run Hr]]-F15 -> 0 | F16: ='PowerHouse Data'!$Q$10 -> 6841 | G16: =$O$3-Table113[[#This Row],[Comp E75 -2 Run Hr]] -> 1225 | H16: =Table113[[#This Row],[Comp E75 -3 Run Hr]]-I15 -> 0 | I16: ='PowerHouse Data'!$Q$11 -> 972 | J16: =$P$3-Table113[[#This Row],[Comp E75 -3 Run Hr]] -> 3028 | K16: =Table113[[#This Row],[Comp E55 Run Hr]]-L15 -> 0 | L16: ='PowerHouse Data'!$Q$12 -> 25941 | M16: =$Q$3-Table113[[#This Row],[Comp E55 Run Hr]] -> 989
A17: ='PowerHouse Data'!$Q$1 -> 46279 | B17: =Table113[[#This Row],[Comp E75 -1 Run Hr]]-C16 -> 0 | C17: ='PowerHouse Data'!$R$9 -> 4033 | D17: =$N$3-Table113[[#This Row],[Comp E75 -1 Run Hr]] -> 1407 | E17: =Table113[[#This Row],[Comp E75 -2 Run Hr]]-F16 -> 0 | F17: ='PowerHouse Data'!$R$10 -> 6841 | G17: =$O$3-Table113[[#This Row],[Comp E75 -2 Run Hr]] -> 1225 | H17: =Table113[[#This Row],[Comp E75 -3 Run Hr]]-I16 -> 0 | I17: ='PowerHouse Data'!$R$11 -> 972 | J17: =$P$3-Table113[[#This Row],[Comp E75 -3 Run Hr]] -> 3028 | K17: =Table113[[#This Row],[Comp E55 Run Hr]]-L16 -> 0 | L17: ='PowerHouse Data'!$R$12 -> 25941 | M17: =$Q$3-Table113[[#This Row],[Comp E55 Run Hr]] -> 989
